Workbook

Sheet Pay Sheet
Z1: =C2 -> 26.6951
A2: rate | C2: 26.6951 | J2: USD/ZWL | P2: Basic | R2: OT & Allowances | S2: CILL | T2: CILL | U2: Bonus | V2: Gross | Y2: Allowable Deductions | AE2: Taxable Income | AG2: Total Taxable in | AH2: PAYE in | AI2: Tax Credits | AJ2: Net PAYE | AK2: PAYE USD | AM2: PAYE ZWL | AO2: Salary After Tax | AQ2: Other Deductions | AV2: Net Salary | AY2: Tax Table USD | BE2: Bank | BG2: Branch | BI2: Account Number | BK2: Leave Days
B3: Netsai | C3: Nhemachena | D3: 78-171262Y32 | E3: Occupation | F3: Leave Days | G3: NSSA Number | H3: Station | I3: Pay Date | J3: RATIO | K3: Period | L3: Hours Worked | M3: Total Basic USD | O3: Total Basic ZWL | P3: USD | Q3: ZWL | R3: USD | S3: USD | T3: ZWL | U3: USD | V3: Total | W3: usd | X3: ZWL | Y3: NSSA | Z3: NSSA USD | AA3: NSSA ZWG | AB3: MIPF | AC3: NEC | AD3: Non Taxable Bonus | AE3: USD | AF3: ZWL | AG3: USD | AH3: USD | AI3: USD | AJ3: USD | AK3: PAYE | AL3: AIDS LEVY | AM3: PAYE | AN3: AIDS LEVY | AO3: USD | AP3: ZWL | AQ3: Nyaradzo | AR3: May Day | AS3: Maintenance | AT3: Funeral Assistance | AU3: Loan Repayment | AV3: USD | AW3: ZWL | AX3: 0-100 | AY3: 101-300 | AZ3: 300.01-1000 | BA3: 1000.01-2000 | BB3: 2000.01-3000 | BC3: 3000 and Above | BD3: Total | BE3: USD | BF3: ZWL | BG3: USD | BH3: ZWL | BI3: USD | BJ3: ZWL | BK3: Opening | BL3: Acrued | BM3: Taken | BN3: Closing
A4: AES-E007 | B4: Talent | C4: Hungwe | D4: 04-885408T08 | E4: I.T Assistant | F4: =BN4 -> 7.5 | G4: 4185957K | H4: Gweru | I4: 45747 | K4: 3/25 | L4: 208 | M4: 400 | O4: =(P4*$C$2)+Q4 -> 10678.04 | P4: =M4*0.5 -> 200 | Q4: =M4*0.5*C2 -> 5339.02 | V4: =P4+R4+S4+U4 -> 200 | W4: =V4 -> 200 | X4: =Q4 -> 5339.02 | Y4: =IF(O4>18519.27,0.045*18519.27,O4*0.045) -> 480.5118 | Z4: =(Y4*0.5)/$Z$1 -> 9 | AA4: =Y4*0.5 -> 240.2559 | AE4: =W4-Z4-AD4 -> 191 | AF4: =X4-AA4-AB4-AC4 -> 5098.7641 | AG4: =AE4+(AF4/$C$2) -> 382 | AH4: =BD4 -> 60.5 | AI4: 0 | AJ4: =AH4-AI4 -> 60.5 | AK4: =(AE4/AG4)*AH4 -> 30.25 | AL4: =AK4*0.03 -> 0.9075 | AM4: =(AJ4-AK4)*$C$2 -> 807.52678 | AN4: =AM4*0.03 -> 24.225803 | AO4: =AE4-AK4-AL4 -> 159.8425 | AP4: =AF4-AM4-AN4 -> 4267.0115 | AR4: 12.5 | AV4: =AO4-AU4-AR4 -> 147.3425 | AW4: =AP4-AQ4-AS4-AT4 -> 4267.0115 | AX4: =IF(AG4<100,0,0) -> 0 | AY4: =IF(AG4<100,0,IF(AG4<=300,AG4*0.2-20,)) -> 0 | AZ4: =IF(AG4<300.01,0,IF(AG4<=1000,AG4*0.25-35,)) -> 60.5 | BA4: =IF(AG4<1000.01,0,IF(AG4<=2000,AG4*0.3-85,)) -> 0 | BB4: =IF(AG4<2000.01,"",IF(AG4<=3000,AG4*0.35-185,)) | BC4: =IF(AG4<3000.01,"",IF(AG4>3000,AG4*0.4-335,)) | BD4: =SUM(AX4:BC4) -> 60.5 | BE4: FBC | BF4: FBC | BG4: Gweru | BH4: Gweru | BI4: 4944283045955 | BJ4: 3037694702002 | BK4: 5 | BL4: 2.5 | BN4: =BK4+BL4-BM4 -> 7.5
A5: AES-E008 | B5: Knowledge | C5: Zvobgo | D5: 10-919182X07 | E5: Production Engineer | F5: =BN5 -> 7.5 | G5: 4965789F | H5: Gweru | I5: =I4 -> 45747 | J5: 0 | K5: =K4 -> 3/25 | L5: 208 | M5: 990.08 | O5: =(P5*$C$2)+Q5 -> 26430.285 | P5: =M5*0.5 -> 495.04 | Q5: =M5*0.5*C2 -> 13215.142 | S5: 0 | V5: =P5+R5+S5+U5 -> 495.04 | W5: =V5 -> 495.04 | X5: =Q5 -> 13215.142 | Y5: =IF(O5>18519.27,0.045*18519.27,O5*0.045) -> 833.36715 | Z5: =(Y5*0.5)/$Z$1 -> 15.608991 | AA5: =Y5*0.5 -> 416.68358 | AD5: =IF(U5>320,320,U5) -> 0 | AE5: =W5-Z5-AD5 -> 479.43101 | AF5: =X5-AA5-AB5-AC5 -> 12798.459 | AG5: =AE5+(AF5/$C$2) -> 958.86202 | AH5: =BD5 -> 204.7155 | AI5: 0 | AJ5: =AH5-AI5 -> 204.7155 | AK5: =(AE5/AG5)*AH5 -> 102.35775 | AL5: =AK5*0.03 -> 3.0707326 | AM5: =(AJ5-AK5)*$C$2 -> 2732.4504 | AN5: =AM5*0.03 -> 81.973513 | AO5: =AE5-AK5-AL5 -> 374.00252 | AP5: =AF5-AM5-AN5 -> 9984.0348 | AR5: 12.5 | AV5: =AO5-AU5-AR5 -> 361.50252 | AW5: =AP5-AQ5-AS5-AT5 -> 9984.0348 | AX5: =IF(AG5<100,0,0) -> 0 | AY5: =IF(AG5<100,0,IF(AG5<=300,AG5*0.2-20,)) -> 0 | AZ5: =IF(AG5<300.01,0,IF(AG5<=1000,AG5*0.25-35,)) -> 204.7155 | BA5: =IF(AG5<1000.01,0,IF(AG5<=2000,AG5*0.3-85,)) -> 0 | BB5: =IF(AG5<2000.01,"",IF(AG5<=3000,AG5*0.35-185,)) | BC5: =IF(AG5<3000.01,"",IF(AG5>3000,AG5*0.4-335,)) | BD5: =SUM(AX5:BC5) -> 204.7155 | BE5: FBC | BF5: FBC | BG5: Head Office | BH5: Gweru BS | BI5: 1548700253549 | BJ5: 5690134581994 | BK5: 5 | BL5: 2.5 | BN5: =BK5+BL5-BM5 -> 7.5
A6: AES-E009 | B6: Chipo | C6: Mhlanga | D6: 33-309044A21 | E6: Accounts Clerk | F6: =BN6 -> 7.5 | G6: 4652414B | H6: Gweru | I6: =I5 -> 45747 | J6: 0 | K6: =K5 -> 3/25 | L6: 208 | M6: 748.8 | O6: =(P6*$C$2)+Q6 -> 19989.291 | P6: =748.8*0.5 -> 374.4 | Q6: =M6*0.5*C2 -> 9994.6454 | V6: =P6+R6+S6+U6 -> 374.4 | W6: =V6 -> 374.4 | X6: =Q6+T6 -> 9994.6454 | Y6: =IF(O6>18519.27,0.045*18519.27,O6*0.045) -> 833.36715 | Z6: =(Y6*0.5)/$Z$1 -> 15.608991 | AA6: =Y6*0.5 -> 416.68358 | AD6: =IF(U6>320,320,U6) -> 0 | AE6: =W6-Z6-AD6 -> 358.79101 | AF6: =X6-AA6-AB6-AC6 -> 9577.9619 | AG6: =AE6+(AF6/$C$2) -> 717.58202 | AH6: =BD6 -> 144.3955 | AI6: 0 | AJ6: =AH6-AI6 -> 144.3955 | AK6: =(AE6/AG6)*AH6 -> 72.197752 | AL6: =AK6*0.03 -> 2.1659326 | AM6: =(AJ6-AK6)*$C$2 -> 1927.3262 | AN6: =AM6*0.03 -> 57.819786 | AO6: =AE6-AK6-AL6 -> 284.42732 | AP6: =AF6-AM6-AN6 -> 7592.8159 | AR6: 12.5 | AV6: =AO6-AU6-AR6 -> 271.92732 | AW6: =AP6-AQ6-AS6-AT6 -> 7592.8159 | AX6: =IF(AG6<100,0,0) -> 0 | AY6: =IF(AG6<100,0,IF(AG6<=300,AG6*0.2-20,)) -> 0 | AZ6: =IF(AG6<300.01,0,IF(AG6<=1000,AG6*0.25-35,)) -> 144.3955 | BA6: =IF(AG6<1000.01,0,IF(AG6<=2000,AG6*0.3-85,)) -> 0 | BB6: =IF(AG6<2000.01,"",IF(AG6<=3000,AG6*0.35-185,)) | BC6: =IF(AG6<3000.01,"",IF(AG6>3000,AG6*0.4-335,)) | BD6: =SUM(AX6:BC6) -> 144.3955 | BE6: FBC | BF6: FBC | BG6: Gweru | BH6: Gweru | BI6: 3221522634754 | BJ6: 3002178920001 | BK6: 5 | BL6: 2.5 | BN6: =BK6+BL6-BM6 -> 7.5
A7: AES-E002 | B7: Tonderayi | C7: Zendera | D7: 62-801978D74 | E7: Refreg Technician | F7: =BN7 -> 7.5 | G7: 9075854G | H7: Gweru | I7: =I6 -> 45747 | K7: =K6 -> 3/25 | L7: 208 | M7: =800*0.9 -> 720 | O7: =(P7*$C$2)+Q7 -> 19220.472 | P7: =M7*0.5 -> 360 | Q7: =M7*0.5*C2 -> 9610.236 | V7: =P7+R7+S7+U7 -> 360 | W7: =V7 -> 360 | X7: =Q7 -> 9610.236 | Y7: =IF(O7>18519.27,0.045*18519.27,O7*0.045) -> 833.36715 | Z7: =(Y7*0.5)/$Z$1 -> 15.608991 | AA7: =Y7*0.5 -> 416.68358 | AE7: =W7-Z7-AD7 -> 344.39101 | AF7: =X7-AA7-AB7-AC7 -> 9193.5524 | AG7: =AE7+(AF7/$C$2) -> 688.78202 | AH7: =BD7 -> 137.1955 | AJ7: =AH7-AI7 -> 137.1955 | AK7: =(AE7/AG7)*AH7 -> 68.597752 | AL7: =AK7*0.03 -> 2.0579326 | AM7: =(AJ7-AK7)*$C$2 -> 1831.2239 | AN7: =AM7*0.03 -> 54.936716 | AO7: =AE7-AK7-AL7 -> 273.73532 | AP7: =AF7-AM7-AN7 -> 7307.3919 | AR7: 12.5 | AV7: =AO7-AU7-AR7 -> 261.23532 | AW7: =AP7-AQ7-AS7-AT7 -> 7307.3919 | AX7: =IF(AG7<100,0,0) -> 0 | AY7: =IF(AG7<100,0,IF(AG7<=300,AG7*0.2-20,)) -> 0 | AZ7: =IF(AG7<300.01,0,IF(AG7<=1000,AG7*0.25-35,)) -> 137.1955 | BA7: =IF(AG7<1000.01,0,IF(AG7<=2000,AG7*0.3-85,)) -> 0 | BB7: =IF(AG7<2000.01,"",IF(AG7<=3000,AG7*0.35-185,)) | BC7: =IF(AG7<3000.01,"",IF(AG7>3000,AG7*0.4-335,)) | BD7: =SUM(AX7:BC7) -> 137.1955 | BE7: FBC | BF7: FBC | BG7: Gweru | BH7: Gweru | BI7: 4835181413465 | BJ7: 3037698131452 | BK7: 5 | BL7: 2.5 | BN7: =BK7+BL7-BM7 -> 7.5
A8: AES-E003 | B8: Tadiwanashe | C8: Hungwe | D8: 61-833442J49 | E8: Accounts Clerk | F8: =BN8 -> 7.5 | G8: 2022698L | H8: Gweru | I8: =I7 -> 45747 | K8: =K7 -> 3/25 | L8: 208 | M8: 748.8 | O8: =(P8*$C$2)+Q8 -> 19989.291 | P8: =748.8*0.5 -> 374.4 | Q8: =M8*0.5*C2 -> 9994.6454 | V8: =P8+R8+S8+U8 -> 374.4 | W8: =V8 -> 374.4 | X8: =Q8+T8 -> 9994.6454 | Y8: =IF(O8>18519.27,0.045*18519.27,O8*0.045) -> 833.36715 | Z8: =(Y8*0.5)/$Z$1 -> 15.608991 | AA8: =Y8*0.5 -> 416.68358 | AE8: =W8-Z8-AD8 -> 358.79101 | AF8: =X8-AA8-AB8-AC8 -> 9577.9619 | AG8: =AE8+(AF8/$C$2) -> 717.58202 | AH8: =BD8 -> 144.3955 | AJ8: =AH8-AI8 -> 144.3955 | AK8: =(AE8/AG8)*AH8 -> 72.197752 | AL8: =AK8*0.03 -> 2.1659326 | AM8: =(AJ8-AK8)*$C$2 -> 1927.3262 | AN8: =AM8*0.03 -> 57.819786 | AO8: =AE8-AK8-AL8 -> 284.42732 | AP8: =AF8-AM8-AN8 -> 7592.8159 | AR8: 12.5 | AV8: =AO8-AU8-AR8 -> 271.92732 | AW8: =AP8-AQ8-AS8-AT8 -> 7592.8159 | AX8: =IF(AG8<100,0,0) -> 0 | AY8: =IF(AG8<100,0,IF(AG8<=300,AG8*0.2-20,)) -> 0 | AZ8: =IF(AG8<300.01,0,IF(AG8<=1000,AG8*0.25-35,)) -> 144.3955 | BA8: =IF(AG8<1000.01,0,IF(AG8<=2000,AG8*0.3-85,)) -> 0 | BB8: =IF(AG8<2000.01,"",IF(AG8<=3000,AG8*0.35-185,)) | BC8: =IF(AG8<3000.01,"",IF(AG8>3000,AG8*0.4-335,)) | BD8: =SUM(AX8:BC8) -> 144.3955 | BE8: FBC | BF8: FBC | BG8: Gweru | BH8: GWERU/BS | BI8: 3881146960064 | BJ8: '5690128271998 | BK8: 5 | BL8: 2.5 | BN8: =BK8+BL8-BM8 -> 7.5
A9: AES-E004 | B9: Nokutenda | C9: Marimo | E9: Driver/Messenger | F9: =BN9 -> 7.5 | G9: 9997381Q | H9: Gweru | I9: =I8 -> 45747 | K9: =K8 -> 3/25 | L9: 208 | M9: 336.96 | O9: =(P9*$C$2)+Q9 -> 8995.1809 | P9: =M9*0.5 -> 168.48 | Q9: =M9*0.5*C2 -> 4497.5904 | V9: =P9+(R9*0.5)+S9+U9 -> 168.48 | W9: =V9 -> 168.48 | X9: =Q9+(R9*0.5*C2) -> 4497.5904 | Y9: =IF(O9>18519.27,0.045*18519.27,O9*0.045) -> 404.78314 | Z9: =(Y9*0.5)/$Z$1 -> 7.5816 | AA9: =Y9*0.5 -> 202.39157 | AE9: =W9-Z9-AD9 -> 160.8984 | AF9: =X9-AA9-AB9-AC9 -> 4295.1989 | AG9: =AE9+(AF9/$C$2) -> 321.7968 | AH9: =BD9 -> 45.4492 | AJ9: =AH9-AI9 -> 45.4492 | AK9: =(AE9/AG9)*AH9 -> 22.7246 | AL9: =AK9*0.03 -> 0.681738 | AM9: =(AJ9-AK9)*$C$2 -> 606.63547 | AN9: =AM9*0.03 -> 18.199064 | AO9: =AE9-AK9-AL9 -> 137.49206 | AP9: =AF9-AM9-AN9 -> 3670.3643 | AR9: 12.5 | AV9: =AO9-AU9-AR9 -> 124.99206 | AW9: =AP9-AQ9-AS9-AT9 -> 3670.3643 | AX9: =IF(AG9<100,0,0) -> 0 | AY9: =IF(AG9<100,0,IF(AG9<=300,AG9*0.2-20,)) -> 0 | AZ9: =IF(AG9<300.01,0,IF(AG9<=1000,AG9*0.25-35,)) -> 45.4492 | BA9: =IF(AG9<1000.01,0,IF(AG9<=2000,AG9*0.3-85,)) -> 0 | BB9: =IF(AG9<2000.01,"",IF(AG9<=3000,AG9*0.35-185,)) | BC9: =IF(AG9<3000.01,"",IF(AG9>3000,AG9*0.4-335,)) | BD9: =SUM(AX9:BC9) -> 45.4492 | BE9: FBC | BF9: FBC | BG9: Gweru | BH9: GWERU | BI9: 6475931779276 | BJ9: 3037699612501 | BK9: 5 | BL9: 2.5 | BN9: =BK9+BL9-BM9 -> 7.5
A10: AES-E006 | B10: Lovemore | C10: Makoni | D10: 15-706794A41 | E10: Operations Director | G10: 4214348G | H10: Gweru | I10: =I9 -> 45747 | K10: =K9 -> 3/25 | L10: 208 | M10: 900 | O10: =(P10*$C$2)+Q10 -> 44344.597 | P10: 1291.58 | Q10: 9865.74 | V10: =P10+R10+S10+U10 -> 1291.58 | W10: =V10 -> 1291.58 | X10: =Q10+T10 -> 9865.74 | Y10: =IF(O10>18519.27,0.045*18519.27,O10*0.045) -> 833.36715 | Z10: =(Y10*0.5)/$Z$1 -> 15.608991 | AA10: =Y10*0.5 -> 416.68358 | AE10: =W10-Z10-AD10 -> 1275.971 | AF10: =X10-AA10-AB10-AC10 -> 9449.0564 | AG10: =AE10+(AF10/$C$2) -> 1629.9332 | AH10: =BD10 -> 403.97996 | AJ10: =AH10-AI10 -> 403.97996 | AK10: =(AE10/AG10)*AH10 -> 316.25021 | AL10: =AK10*0.03 -> 9.4875063 | AM10: =(AJ10-AK10)*$C$2 -> 2341.9545 | AN10: =AM10*0.03 -> 70.258636 | AO10: =AE10-AK10-AL10 -> 950.23329 | AP10: =AF10-AM10-AN10 -> 7036.8433 | AV10: =AO10-AU10-AR10 -> 950.23329 | AW10: =AP10-AQ10-AS10-AT10 -> 7036.8433 | AX10: =IF(AG10<100,0,0) -> 0 | AY10: =IF(AG10<100,0,IF(AG10<=300,AG10*0.2-20,)) -> 0 | AZ10: =IF(AG10<300.01,0,IF(AG10<=1000,AG10*0.25-35,)) -> 0 | BA10: =IF(AG10<1000.01,0,IF(AG10<=2000,AG10*0.3-85,)) -> 403.97996 | BB10: =IF(AG10<2000.01,"",IF(AG10<=3000,AG10*0.35-185,)) | BD10: =SUM(AX10:BC10) -> 403.97996 | BE10: FBC | BF10: FBC | BG10: Gweru | BH10: GWERU | BI10: 7976638819817 | BJ10: 3037699612501 | BK10: 5 | BL10: 2.5 | BN10: =BK10+BL10-BM10 -> 7.5
AX11: =IF(AG11<100,0,0) -> 0 | AY11: =IF(AG11<100,0,IF(AG11<=300,AG11*0.2-20,)) -> 0 | AZ11: =IF(AG11<300.01,0,IF(AG11<=1000,AG11*0.25-35,)) -> 0 | BA11: =IF(AG11<1000.01,0,IF(AG11<=2000,AG11*0.3-85,)) -> 0 | BB11: =IF(AG11<2000.01,"",IF(AG11<=3000,AG11*0.35-185,)) | BD11: =SUM(AX11:BC11) -> 0
AX12: =IF(AG12<100,0,0) -> 0 | AY12: =IF(AG12<100,0,IF(AG12<=300,AG12*0.2-20,)) -> 0 | AZ12: =IF(AG12<300.01,0,IF(AG12<=1000,AG12*0.25-35,)) -> 0 | BA12: =IF(AG12<1000.01,0,IF(AG12<=2000,AG12*0.3-85,)) -> 0 | BB12: =IF(AG12<2000.01,"",IF(AG12<=3000,AG12*0.35-185,)) | BD12: =SUM(BD4:BD11) -> 1140.6312
C13: Totals | P13: =SUM(P4:P8) -> 1803.84 | Q13: =SUM(Q4:Q8) -> 48153.689 | R13: =SUM(R4:R9) -> 0 | S13: =SUM(S4:S8) -> 0 | T13: =SUM(T4:T8) -> 0 | U13: =SUM(U4:U8) -> 0 | V13: =SUM(V4:V9) -> 1972.32 | W13: =SUM(W4:W9) -> 1972.32 | X13: =SUM(X4:X9) -> 52651.28 | Y13: =SUM(Y4:Y9) -> 4218.7635 | Z13: =SUM(Z4:Z9) -> 79.017564 | AA13: =SUM(AA4:AA9) -> 2109.3818 | AB13: =SUM(AB4:AB9) -> 0 | AC13: =SUM(AC4:AC9) -> 0 | ... AU13: =SUM(AU4:AU9) -> 0 | AV13: =SUM(AV4:AV12) -> 2389.1604 | AW13: =SUM(AW4:AW12) -> 47451.277
A17: rate | C17: =C2 -> 26.6951 | J17: USD/ZWL | P17: Basic | R17: Withholding Tax | T17: Net Payable
B18: Netsai | C18: Nhemachena | D18: 78-171262Y32 | E18: Occupation | F18: Leave Days | G18: NSSA Number | H18: Station | I18: Pay Date | J18: RATIO | K18: Period | L18: Hours Worked | M18: Total Basic USD | O18: Total Basic ZWL | P18: USD | Q18: ZWL | R18: USD | S18: ZWL | T18: USD | U18: ZWL
A19: AES-E001 | B19: Learnmore | C19: Makoni | E19: Director | H19: Gweru | I19: =I9 -> 45747 | J19: 0.57 | K19: =K4 -> 3/25 | L19: 208 | M19: 1000 | N19: 745.81 | O19: =(P19*$C$2)+Q19 -> 49570.665 | P19: 1111.11 | Q19: =N19*$C$17 -> 19909.473 | R19: =P19*0.1 -> 111.111 | S19: =Q19*0.1 -> 1990.9473 | T19: =P19-R19 -> 999.999 | U19: =Q19-S19 -> 17918.525
A20: AES-E005 | B20: Ruvarashe | C20: Makoni | E20: Director | H20: Gweru | I20: =I19 -> 45747 | J20: 0.69 | K20: =K19 -> 3/25 | L20: 208 | M20: =1000+447.49 -> 1447.49 | N20: 447.49 | O20: =(P20*$C$2)+Q20 -> 41606.983 | P20: 1111.11 | Q20: =N20*$C$17 -> 11945.79 | R20: =P20*0.1 -> 111.111 | S20: =Q20*0.1 -> 1194.579 | T20: =P20-R20 -> 999.999 | U20: =Q20-S20 -> 10751.211
C21: Totals | P21: =SUM(P19:P20) -> 2222.22 | Q21: =SUM(Q19:Q20) -> 31855.263 | R21: =SUM(R19:R20) -> 222.222 | S21: =SUM(S19:S20) -> 3185.5263 | T21: =SUM(T19:T20) -> 1999.998 | U21: =SUM(U19:U20) -> 28669.737
M23: Lovemore Nssa | N23: =IF(#REF!>18382.98,0.045*18382.98,#REF!*0.045) -> #REF!

Sheet Payslip
A1: AIRFLOW ENVIRONMENTAL SOLUTIONS PRIVATE LIMITED PAYSLIP | M1: Rate | N1: ='Pay Sheet'!C2 -> 26.6951
A2: Employee Details | D2: Earnings Details | E2: Units | F2: Earning Amounts | I2: Deduction Details | J2: Deduction Amounts | M2: AES | N2: 12 | O2: =CONCATENATE(M2,N2) -> AES12
A3: =VLOOKUP(B4,'Pay Sheet'!$A$2:$BJ$9, COLUMN('Pay Sheet'!B4), FALSE()) -> #N/A | B3: =VLOOKUP($B$4,'Pay Sheet'!$A$2:$BJ$9, COLUMN('Pay Sheet'!C4), FALSE()) -> #N/A | F3: USD | G3: ZIG | J3: USD | K3: ZIG | M3: AES | N3: 10 | O3: =CONCATENATE(M3,N3) -> AES10
A4: Employee NO | B4: =O2 -> AES12 | D4: Basic Pay | E4: =VLOOKUP($B$4,'Pay Sheet'!$A$2:$BJ$9, COLUMN('pay sheet'!#ref!), FALSE()) -> #VALUE! | F4: =VLOOKUP($B$4,'Pay Sheet'!$A$2:$BJ$9, COLUMN('pay sheet'!#ref!), FALSE()) -> #VALUE! | G4: =VLOOKUP($B$4,'Pay Sheet'!$A$2:$BJ$9, COLUMN('pay sheet'!#ref!), FALSE()) -> #VALUE! | I4: PAYE | J4: =VLOOKUP($B$4,'Pay Sheet'!$A$2:$BJ$9, COLUMN('pay sheet'!#ref!), FALSE()) -> #VALUE! | K4: =VLOOKUP($B$4,'Pay Sheet'!$A$2:$BJ$9, COLUMN('pay sheet'!#ref!), FALSE()) -> #VALUE! | M4: AES | N4: 11 | O4: =CONCATENATE(M4,N4) -> AES11
A5: Period | B5: =VLOOKUP($B$4,'Pay Sheet'!$A$2:$BJ$9, COLUMN('Pay Sheet'!K4), FALSE()) -> #N/A | D5: Housing Allowance | F5: 0 | G5: 0 | I5: AIDS LEVY | J5: =VLOOKUP($B$4,'Pay Sheet'!$A$2:$BJ$9, COLUMN('Pay Sheet'!AL5), FALSE()) -> #N/A | K5: =VLOOKUP($B$4,'Pay Sheet'!$A$2:$BJ$9, COLUMN('Pay Sheet'!AN5), FALSE()) -> #N/A
A6: Nat ID | B6: =VLOOKUP($B$4,'Pay Sheet'!$A$2:$BJ$9, COLUMN('Pay Sheet'!D6), FALSE()) -> #N/A | D6: Overtime 1.5 | F6: 0 | I6: NSSA | J6: 0 | K6: =VLOOKUP($B$4,'Pay Sheet'!$A$2:$BJ$9, COLUMN('Pay Sheet'!Y6), FALSE()) -> #N/A
A7: Pay Method | B7: Transfer | D7: Overtime 2.0 | F7: 0 | I7: NEC | K7: 0
A8: Grade | B8: TBA | D8: Loan/Advance | I8: Repayment | J8: =VLOOKUP($B$4,'Pay Sheet'!$A$2:$BJ$9, COLUMN('Pay Sheet'!AU7), FALSE()) -> #N/A
A9: Occupation | B9: =VLOOKUP($B$4,'Pay Sheet'!$A$2:$BJ$9, COLUMN('Pay Sheet'!E8), FALSE()) -> #N/A | D9: C.I.L.O.L | F9: =VLOOKUP($B$4,'Pay Sheet'!$A$2:$BJ$9, COLUMN('Pay Sheet'!S8), FALSE()) -> #N/A | G9: =VLOOKUP($B$4,'Pay Sheet'!$A$2:$BJ$9, COLUMN('Pay Sheet'!T8), FALSE()) -> #N/A | I9: Maintenance | J9: 0 | K9: 0
A10: Leave Days | B10: TBA | D10: Food Allowance | G10: 0 | I10: Nyaradzo | K10: 0
A11: NSSA No | B11: =VLOOKUP($B$4,'Pay Sheet'!$A$2:$BJ$9, COLUMN('Pay Sheet'!G13), FALSE()) -> #N/A | D11: Airtime Allowance | G11: 0 | I11: MIPF | K11: 0 | M11: Checking
A12: Station | B12: =VLOOKUP($B$4,'Pay Sheet'!$A$2:$BJ$9, COLUMN('Pay Sheet'!H14), FALSE()) -> #N/A | D12: Underground Allowance | F12: 0 | G12: 0 | I12: CBZ Fund | K12: 0 | M12: usd | N12: =F15-J15 -> #N/A
A13: Pay Date | B13: =VLOOKUP($B$4,'Pay Sheet'!$A$2:$BJ$9, COLUMN('Pay Sheet'!I15), FALSE()) -> #N/A | D13: Night Shift Allowance | F13: 0 | G13: 0 | I13: May Day | J13: =VLOOKUP($B$4,'Pay Sheet'!$A$2:$BJ$9, COLUMN('Pay Sheet'!AR14), FALSE()) -> #N/A | M13: zwl | N13: =G15-K15 -> #VALUE!
D15: Gross | F15: =SUM(F4:F14) -> #N/A | G15: =SUM(G4:G14) -> #N/A | I15: Total Deductions | J15: =SUM(J4:J14) -> #N/A | K15: =SUM(K4:K14) -> #VALUE!
A17: ZIG Banked | B17: =VLOOKUP($B$4,'Pay Sheet'!$A$2:$BJ$9, COLUMN('Pay Sheet'!BF19), FALSE()) -> #N/A | D17: =VLOOKUP($B$4,'Pay Sheet'!$A$2:$BJ$9, COLUMN('Pay Sheet'!BJ19), FALSE()) -> #N/A | F17: Tax Credit | I17: NET PAY | J17: ZIG | K17: =VLOOKUP($B$4,'Pay Sheet'!$A$2:$BJ$9, COLUMN('Pay Sheet'!AW19), FALSE()) -> #N/A | N17: =K17-N13 -> #VALUE!
A18: USD Banked | B18: =VLOOKUP($B$4,'Pay Sheet'!$A$2:$BJ$9, COLUMN('Pay Sheet'!BE20), FALSE()) -> #N/A | D18: =VLOOKUP($B$4,'Pay Sheet'!$A$2:$BJ$9, COLUMN('Pay Sheet'!BI20), FALSE()) -> #N/A | F18: 0 | J18: USD | K18: =VLOOKUP($B$4,'Pay Sheet'!$A$2:$BJ$9, COLUMN('Pay Sheet'!AV20), FALSE()) -> #N/A
A21: AIRFLOW ENVIRONMENTAL SOLUTIONS PRIVATE LIMITED PAYSLIP
A22: Employee Details | D22: Earnings Details | E22: Units | F22: Earning Amounts | I22: Deduction Details | J22: Deduction Amounts
A23: =VLOOKUP(B24,'Pay Sheet'!$A$2:$BJ$9, COLUMN('Pay Sheet'!B24), FALSE()) -> #N/A | B23: =VLOOKUP(B24,'Pay Sheet'!$A$2:$BJ$9, COLUMN('Pay Sheet'!C24), FALSE()) -> #N/A | F23: USD | G23: ZIG | J23: USD | K23: ZIG
A24: Employee NO | B24: =O3 -> AES10 | D24: Basic Pay | E24: =VLOOKUP($B$4,'Pay Sheet'!$A$2:$BJ$9, COLUMN('Pay Sheet'!L25), FALSE()) -> #N/A | F24: =VLOOKUP(B24,'Pay Sheet'!$A$2:$BJ$9, COLUMN('Pay Sheet'!P25), FALSE()) -> #N/A | G24: =VLOOKUP(B24,'Pay Sheet'!$A$2:$BJ$9, COLUMN('Pay Sheet'!Q25), FALSE()) -> #N/A | I24: PAYE | J24: =VLOOKUP(B24,'Pay Sheet'!$A$2:$BJ$9, COLUMN('Pay Sheet'!AK25), FALSE()) -> #N/A | K24: =VLOOKUP(B24,'Pay Sheet'!$A$2:$BJ$9, COLUMN('Pay Sheet'!AM25), FALSE()) -> #N/A
A25: Period | B25: =VLOOKUP(B24,'Pay Sheet'!$A$2:$BJ$9, COLUMN('Pay Sheet'!K26), FALSE()) -> #N/A | D25: Housing Allowance | F25: 0 | G25: 0 | I25: AIDS LEVY | J25: =VLOOKUP(B24,'Pay Sheet'!$A$2:$BJ$9, COLUMN('Pay Sheet'!AL26), FALSE()) -> #N/A | K25: =VLOOKUP(B24,'Pay Sheet'!$A$2:$BJ$9, COLUMN('Pay Sheet'!AN26), FALSE()) -> #N/A
A26: Nat ID | B26: =VLOOKUP(B24,'Pay Sheet'!$A$2:$BJ$9, COLUMN('Pay Sheet'!D27), FALSE()) -> #N/A | D26: Overtime 1.5 | F26: 0 | I26: NSSA | J26: 0 | K26: =VLOOKUP(B24,'Pay Sheet'!$A$2:$BJ$9, COLUMN('Pay Sheet'!Y27), FALSE()) -> #N/A
A27: Pay Method | B27: Transfer | D27: Overtime 2.0 | F27: 0 | I27: NEC | K27: 0
A28: Grade | B28: TBA | D28: Loan/Advance | I28: Repayment | J28: 0
A29: Occupation | B29: =VLOOKUP(B24,'Pay Sheet'!$A$2:$BJ$9, COLUMN('Pay Sheet'!E8), FALSE()) -> #N/A | D29: C.I.L.O.L | F29: =VLOOKUP($B$4,'Pay Sheet'!$A$2:$BJ$9, COLUMN('Pay Sheet'!S30), FALSE()) -> #N/A | G29: =VLOOKUP(B24,'Pay Sheet'!$A$2:$BJ$9, COLUMN('Pay Sheet'!T30), FALSE()) -> #N/A | I29: Maintenance | J29: 0 | K29: 0
A30: Leave Days | B30: TBA | D30: Food Allowance | G30: 0 | I30: Nyaradzo | K30: 0
A31: NSSA No | B31: =VLOOKUP(B24,'Pay Sheet'!$A$2:$BJ$9, COLUMN('Pay Sheet'!G32), FALSE()) -> #N/A | D31: Airtime Allowance | G31: 0 | I31: MIPF | K31: 0 | M31: Checking
A32: Station | B32: =VLOOKUP(B24,'Pay Sheet'!$A$2:$BJ$9, COLUMN('Pay Sheet'!H33), FALSE()) -> #N/A | D32: Underground Allowance | F32: 0 | G32: 0 | I32: CBZ Fund | K32: 0 | M32: usd | N32: =F35-J35 -> #N/A
A33: Pay Date | B33: =VLOOKUP(B24,'Pay Sheet'!$A$2:$BJ$9, COLUMN('Pay Sheet'!I34), FALSE()) -> #N/A | D33: Night Shift Allowance | F33: 0 | G33: 0 | I33: May Day | J33: =VLOOKUP(B24,'Pay Sheet'!$A$2:$BJ$9, COLUMN('Pay Sheet'!AR34), FALSE()) -> #N/A | M33: zwl | N33: =G35-K35 -> #N/A
D35: Gross | F35: =SUM(F24:F34) -> #N/A | G35: =SUM(G24:G34) -> #N/A | I35: Total Deductions | J35: =SUM(J24:J34) -> #N/A | K35: =SUM(K24:K34) -> #N/A
A37: ZWL Banked | B37: =VLOOKUP(B24,'Pay Sheet'!$A$2:$BJ$9, COLUMN('Pay Sheet'!BF38), FALSE()) -> #N/A | D37: =VLOOKUP(B24,'Pay Sheet'!$A$2:$BJ$9, COLUMN('Pay Sheet'!BJ38), FALSE()) -> #N/A | F37: Tax Credit | I37: NET PAY | J37: ZIG | K37: =VLOOKUP(B24,'Pay Sheet'!$A$2:$BJ$9, COLUMN('Pay Sheet'!AW38), FALSE()) -> #N/A | N37: =N32-K38 -> #N/A
A38: USD Banked | B38: =VLOOKUP(B24,'Pay Sheet'!$A$2:$BJ$9, COLUMN('Pay Sheet'!BE39), FALSE()) -> #N/A | D38: =VLOOKUP(B24,'Pay Sheet'!$A$2:$BJ$9, COLUMN('Pay Sheet'!BI39), FALSE()) -> #N/A | F38: 0 | J38: USD | K38: =VLOOKUP(B24,'Pay Sheet'!$A$2:$BJ$9, COLUMN('Pay Sheet'!AV39), FALSE()) -> #N/A | N38: =K37-N33 -> #N/A
A41: AIRFLOW ENVIRONMENTAL SOLUTIONS PRIVATE LIMITED PAYSLIP
A42: Employee Details | D42: Earnings Details | E42: Units | F42: Earning Amounts | I42: Deduction Details | J42: Deduction Amounts
A43: =VLOOKUP(B44,'Pay Sheet'!$A$2:$BJ$9, COLUMN('Pay Sheet'!B4), FALSE()) -> #N/A | B43: =VLOOKUP(B44,'Pay Sheet'!$A$2:$BJ$9, COLUMN('Pay Sheet'!C4), FALSE()) -> #N/A | F43: USD | G43: ZIG | J43: USD | K43: ZIG
A44: Employee NO | B44: =O4 -> AES11 | D44: Basic Pay | E44: =VLOOKUP($B$4,'Pay Sheet'!$A$2:$BJ$9, COLUMN('Pay Sheet'!L45), FALSE()) -> #N/A | F44: =VLOOKUP(B44,'Pay Sheet'!$A$2:$BJ$9, COLUMN('Pay Sheet'!P45), FALSE()) -> #N/A | G44: =VLOOKUP(B44,'Pay Sheet'!$A$2:$BJ$9, COLUMN('Pay Sheet'!Q45), FALSE()) -> #N/A | I44: PAYE | J44: =VLOOKUP(B44,'Pay Sheet'!$A$2:$BJ$9, COLUMN('Pay Sheet'!AK45), FALSE()) -> #N/A | K44: =VLOOKUP(B44,'Pay Sheet'!$A$2:$BJ$9, COLUMN('Pay Sheet'!AM45), FALSE()) -> #N/A
A45: Period | B45: =VLOOKUP(B44,'Pay Sheet'!$A$2:$BJ$9, COLUMN('Pay Sheet'!K46), FALSE()) -> #N/A | D45: Housing Allowance | F45: 0 | G45: 0 | I45: AIDS LEVY | J45: =VLOOKUP(B44,'Pay Sheet'!$A$2:$BJ$9, COLUMN('Pay Sheet'!AL46), FALSE()) -> #N/A | K45: =VLOOKUP(B44,'Pay Sheet'!$A$2:$BJ$9, COLUMN('Pay Sheet'!AN46), FALSE()) -> #N/A
A46: Nat ID | B46: =VLOOKUP(B44,'Pay Sheet'!$A$2:$BJ$9, COLUMN('Pay Sheet'!D47), FALSE()) -> #N/A | D46: Overtime 1.5 | F46: 0 | G46: 0 | I46: NSSA | J46: 0 | K46: =VLOOKUP(B44,'Pay Sheet'!$A$2:$BJ$9, COLUMN('Pay Sheet'!Y47), FALSE()) -> #N/A
A47: Pay Method | B47: Transfer | D47: Overtime 2.0 | F47: 0 | G47: 0 | I47: NEC | K47: 0
A48: Grade | B48: TBA | D48: Loan/Advance | I48: Repayment | J48: 0
...

Sheet Bank Schedule
B1: Netsai | C1: Nhemachena | D1: Bank | E1: Branch | F1: Account Number | G1: Amount | H1: Bank | I1: Branch | J1: Account Number | K1: Amount
A2: ='Pay Sheet'!A4 -> AES-E007 | B2: ='Pay Sheet'!B4 -> Talent | C2: ='Pay Sheet'!C4 -> Hungwe | D2: ='Pay Sheet'!BE4 -> FBC | E2: ='Pay Sheet'!BG4 -> Gweru | F2: ='Pay Sheet'!BI4 -> 4944283045955 | G2: ='Pay Sheet'!AV4 -> 147.3425 | H2: ='Pay Sheet'!BF4 -> FBC | I2: ='Pay Sheet'!BH4 -> Gweru | J2: ='Pay Sheet'!BJ4 -> 3037694702002 | K2: ='Pay Sheet'!AP4 -> 4267.0115
A3: ='Pay Sheet'!A5 -> AES-E008 | B3: ='Pay Sheet'!B5 -> Knowledge | C3: ='Pay Sheet'!C5 -> Zvobgo | D3: ='Pay Sheet'!BE5 -> FBC | E3: ='Pay Sheet'!BG5 -> Head Office | F3: ='Pay Sheet'!BI5 -> 1548700253549 | G3: ='Pay Sheet'!AV5 -> 361.50252 | H3: ='Pay Sheet'!BF5 -> FBC | I3: ='Pay Sheet'!BH5 -> Gweru BS | J3: ='Pay Sheet'!BJ5 -> 5690134581994 | K3: ='Pay Sheet'!AP5 -> 9984.0348
A4: ='Pay Sheet'!A6 -> AES-E009 | B4: ='Pay Sheet'!B6 -> Chipo | C4: ='Pay Sheet'!C6 -> Mhlanga | D4: ='Pay Sheet'!BE6 -> FBC | E4: Virtual | F4: ='Pay Sheet'!BI6 -> 3221522634754 | G4: ='Pay Sheet'!AV6 -> 271.92732 | H4: ='Pay Sheet'!BF6 -> FBC | I4: Virtual | J4: ='Pay Sheet'!BJ6 -> 3002178920001 | K4: ='Pay Sheet'!AP6 -> 7592.8159
A5: ='Pay Sheet'!A7 -> AES-E002 | B5: ='Pay Sheet'!B7 -> Tonderayi | C5: ='Pay Sheet'!C7 -> Zendera | D5: ='Pay Sheet'!BE7 -> FBC | E5: ='Pay Sheet'!BG7 -> Gweru | F5: ='Pay Sheet'!BI7 -> 4835181413465 | G5: ='Pay Sheet'!AV7 -> 261.23532 | H5: ='Pay Sheet'!BF7 -> FBC | I5: ='Pay Sheet'!BH7 -> Gweru | J5: ='Pay Sheet'!BJ7 -> 3037698131452 | K5: ='Pay Sheet'!AP7 -> 7307.3919
A6: ='Pay Sheet'!A8 -> AES-E003 | B6: ='Pay Sheet'!B8 -> Tadiwanashe | C6: ='Pay Sheet'!C8 -> Hungwe | D6: ='Pay Sheet'!BE8 -> FBC | E6: ='Pay Sheet'!BG8 -> Gweru | F6: ='Pay Sheet'!BI8 -> 3881146960064 | G6: ='Pay Sheet'!AV8 -> 271.92732 | H6: ='Pay Sheet'!BF8 -> FBC | I6: ='Pay Sheet'!BH8 -> GWERU/BS | J6: ='Pay Sheet'!BJ8 -> '5690128271998 | K6: ='Pay Sheet'!AP8 -> 7592.8159
B7: ='Pay Sheet'!B9 -> Nokutenda | C7: ='Pay Sheet'!C9 -> Marimo | D7: ='Pay Sheet'!BE9 -> FBC | E7: ='Pay Sheet'!BG9 -> Gweru | F7: ='Pay Sheet'!BI9 -> 6475931779276 | G7: ='Pay Sheet'!AV9 -> 124.99206 | H7: ='Pay Sheet'!BF9 -> FBC | I7: ='Pay Sheet'!BH9 -> GWERU | J7: ='Pay Sheet'!BJ9 -> 3037699612501 | K7: ='Pay Sheet'!AP9 -> 3670.3643
B8: ='Pay Sheet'!B19 -> Learnmore | C8: ='Pay Sheet'!C19 -> Makoni | D8: FBC | E8: Gweru | G8: ='Pay Sheet'!T19 -> 999.999 | H8: FBC | I8: GWERU | K8: ='Pay Sheet'!U19 -> 17918.525
B9: ='Pay Sheet'!B20 -> Ruvarashe | C9: ='Pay Sheet'!C20 -> Makoni | D9: FBC | E9: Gweru | G9: ='Pay Sheet'!T20 -> 999.999 | H9: FBC | I9: GWERU | K9: ='Pay Sheet'!U20 -> 10751.211
B10: ='Pay Sheet'!B10 -> Lovemore | C10: ='Pay Sheet'!C10 -> Makoni | D10: FBC | E10: Gweru | G10: ='Pay Sheet'!AO10 -> 950.23329 | H10: FBC | I10: GWERU | K10: ='Pay Sheet'!AW10 -> 7036.8433
G16: =SUM(G2:G10) -> 4389.1584 | K16: =SUM(K2:K10) -> 76121.014
B18: Consultancy Services | I18: Rate | J18: ='Pay Sheet'!C2 -> 26.6951
B19: Beaven | C19: Muchingami | D19: FBC | E19: Head Office | G19: =500*0.5 -> 250 | H19: ZB | I19: Gweru | K19: =250*J18 -> 6673.775
B20: Bessie | C20: Bonga | D20: FBC | E20: Gweru | G20: =375*0.5 -> 187.5 | H20: FBC | I20: Gweru | K20: =375*0.5*J18 -> 5005.3313
G21: =SUM(G19:G20) -> 437.5 | K21: =SUM(K19:K20) -> 11679.106

Sheet NSSA
B1: Netsai | C1: Nhemachena | D1: Employee Contribution (USD) | E1: Employee Contribution(ZWG) | F1: Employer Contribution(USD) | G1: Employer Contribution(ZWG) | H1: Total(USD) | I1: Total(ZWG)
A2: ='Pay Sheet'!A4 -> AES-E007 | B2: ='Pay Sheet'!B4 -> Talent | C2: ='Pay Sheet'!C4 -> Hungwe | D2: ='Pay Sheet'!Z4 -> 9 | E2: ='Pay Sheet'!AA4 -> 240.2559 | G2: =E2 -> 240.2559 | I2: =SUM(E2:G2) -> 480.5118
A3: ='Pay Sheet'!A5 -> AES-E008 | B3: ='Pay Sheet'!B5 -> Knowledge | C3: ='Pay Sheet'!C5 -> Zvobgo | D3: ='Pay Sheet'!Z5 -> 15.608991 | E3: ='Pay Sheet'!AA5 -> 416.68358 | G3: =E3 -> 416.68358 | I3: =SUM(E3:G3) -> 833.36715
A4: ='Pay Sheet'!A6 -> AES-E009 | B4: ='Pay Sheet'!B6 -> Chipo | C4: ='Pay Sheet'!C6 -> Mhlanga | D4: ='Pay Sheet'!Z6 -> 15.608991 | E4: ='Pay Sheet'!AA6 -> 416.68358 | G4: =E4 -> 416.68358 | I4: =SUM(E4:G4) -> 833.36715
A5: ='Pay Sheet'!A7 -> AES-E002 | B5: ='Pay Sheet'!B7 -> Tonderayi | C5: ='Pay Sheet'!C7 -> Zendera | D5: ='Pay Sheet'!Z7 -> 15.608991 | E5: ='Pay Sheet'!AA7 -> 416.68358 | G5: =E5 -> 416.68358 | I5: =SUM(E5:G5) -> 833.36715
A6: ='Pay Sheet'!A8 -> AES-E003 | B6: ='Pay Sheet'!B8 -> Tadiwanashe | C6: ='Pay Sheet'!C8 -> Hungwe | D6: ='Pay Sheet'!Z8 -> 15.608991 | E6: ='Pay Sheet'!AA8 -> 416.68358 | G6: =E6 -> 416.68358 | I6: =SUM(E6:G6) -> 833.36715
B7: Lovemore | C7: Makoni | E7: ='Pay Sheet'!AA9 -> 202.39157 | G7: =E7 -> 202.39157 | I7: =SUM(E7:G7) -> 404.78314
E8: =SUM(E2:E7) -> 2109.3818 | G8: =SUM(G2:G7) -> 2109.3818 | I8: =SUM(E8:G8) -> 4218.7635
G9: Total | I9: =SUM(I2:I8) -> 8437.5271
G10: WCIF | I10: =I9*0.0177 -> 149.34423
G11: Payable | I11: =I9+I10 -> 8586.8713
I13: =G8+I10 -> 2258.726

Sheet PAYE
A1: Details | D1: USD | G1: ZWL
B2: Netsai | C2: Nhemachena | D2: PAYE | E2: AIDS LEVY | F2: Total | G2: PAYE | H2: AIDS LEVY | I2: Total
A3: ='Pay Sheet'!A4 -> AES-E007 | B3: ='Pay Sheet'!B4 -> Talent | C3: ='Pay Sheet'!C4 -> Hungwe | D3: ='Pay Sheet'!AK4 -> 30.25 | E3: ='Pay Sheet'!AL4 -> 0.9075 | F3: =D3+E3 -> 31.1575 | G3: ='Pay Sheet'!AM4 -> 807.52678 | H3: ='Pay Sheet'!AN4 -> 24.225803 | I3: =G3+H3 -> 831.75258
A4: ='Pay Sheet'!A5 -> AES-E008 | B4: ='Pay Sheet'!B5 -> Knowledge | C4: ='Pay Sheet'!C5 -> Zvobgo | D4: ='Pay Sheet'!AK5 -> 102.35775 | E4: ='Pay Sheet'!AL5 -> 3.0707326 | F4: =D4+E4 -> 105.42848 | G4: ='Pay Sheet'!AM5 -> 2732.4504 | H4: ='Pay Sheet'!AN5 -> 81.973513 | I4: =G4+H4 -> 2814.4239
A5: ='Pay Sheet'!A6 -> AES-E009 | B5: ='Pay Sheet'!B6 -> Chipo | C5: ='Pay Sheet'!C6 -> Mhlanga | D5: ='Pay Sheet'!AK6 -> 72.197752 | E5: ='Pay Sheet'!AL6 -> 2.1659326 | F5: =D5+E5 -> 74.363685 | G5: ='Pay Sheet'!AM6 -> 1927.3262 | H5: ='Pay Sheet'!AN6 -> 57.819786 | I5: =G5+H5 -> 1985.146
A6: ='Pay Sheet'!A7 -> AES-E002 | B6: ='Pay Sheet'!B7 -> Tonderayi | C6: ='Pay Sheet'!C7 -> Zendera | D6: ='Pay Sheet'!AK7 -> 68.597752 | E6: ='Pay Sheet'!AL7 -> 2.0579326 | F6: =D6+E6 -> 70.655685 | G6: ='Pay Sheet'!AM7 -> 1831.2239 | H6: ='Pay Sheet'!AN7 -> 54.936716 | I6: =G6+H6 -> 1886.1606
A7: ='Pay Sheet'!A8 -> AES-E003 | B7: ='Pay Sheet'!B8 -> Tadiwanashe | C7: ='Pay Sheet'!C8 -> Hungwe | D7: ='Pay Sheet'!AK8 -> 72.197752 | E7: ='Pay Sheet'!AL8 -> 2.1659326 | F7: =D7+E7 -> 74.363685 | G7: ='Pay Sheet'!AM8 -> 1927.3262 | H7: ='Pay Sheet'!AN8 -> 57.819786 | I7: =G7+H7 -> 1985.146
A8: ='Pay Sheet'!A9 -> AES-E004 | B8: ='Pay Sheet'!B9 -> Nokutenda | C8: ='Pay Sheet'!C9 -> Marimo | D8: ='Pay Sheet'!AK9 -> 22.7246
A9: ='Pay Sheet'!A10 -> AES-E006 | B9: ='Pay Sheet'!B10 -> Lovemore | C9: ='Pay Sheet'!C10 -> Makoni | D9: ='Pay Sheet'!AK10 -> 316.25021
C11: Total | D11: =SUM(D3:D5) -> 204.8055 | E11: =SUM(E3:E5) -> 6.1441651 | F11: =SUM(F3:F5) -> 210.94967 | G11: =SUM(G3:G5) -> 5467.3034 | H11: =SUM(H3:H5) -> 164.0191 | I11: =SUM(I3:I5) -> 5631.3225

Sheet ZIMDEF
C1: Zimdef Schedule September 2025
D2: Gross | F2: Rate | G2: ='Pay Sheet'!C2 -> 26.6951
A3: Works # | B3: Netsai | C3: Nhemachena | D3: USD | E3: ZWL | F3: NSSA | G3: USD CONVERTED | H3: TOTAL | I3: ZIMDEF
A4: ='Pay Sheet'!A4 -> AES-E007 | B4: ='Pay Sheet'!B4 -> Talent | C4: ='Pay Sheet'!C4 -> Hungwe | D4: ='Pay Sheet'!W4 -> 200 | E4: ='Pay Sheet'!X4 -> 5339.02 | F4: ='Pay Sheet'!Y4 -> 480.5118 | G4: =D4*$G$2 -> 5339.02 | H4: =E4+F4+G4 -> 11158.552 | I4: =H4*0.01 -> 111.58552
A5: ='Pay Sheet'!A5 -> AES-E008 | B5: ='Pay Sheet'!B5 -> Knowledge | C5: ='Pay Sheet'!C5 -> Zvobgo | D5: ='Pay Sheet'!W5 -> 495.04 | E5: ='Pay Sheet'!X5 -> 13215.142 | F5: ='Pay Sheet'!Y5 -> 833.36715 | G5: =D5*$G$2 -> 13215.142 | H5: =E5+F5+G5 -> 27263.652 | I5: =H5*0.01 -> 272.63652
A6: ='Pay Sheet'!A6 -> AES-E009 | B6: ='Pay Sheet'!B6 -> Chipo | C6: ='Pay Sheet'!C6 -> Mhlanga | D6: ='Pay Sheet'!W6 -> 374.4 | E6: ='Pay Sheet'!X6 -> 9994.6454 | F6: ='Pay Sheet'!Y6 -> 833.36715 | G6: =D6*$G$2 -> 9994.6454 | H6: =E6+F6+G6 -> 20822.658 | I6: =H6*0.01 -> 208.22658
A7: ='Pay Sheet'!A7 -> AES-E002 | B7: ='Pay Sheet'!B7 -> Tonderayi | C7: ='Pay Sheet'!C7 -> Zendera | D7: ='Pay Sheet'!W7 -> 360 | E7: ='Pay Sheet'!X7 -> 9610.236 | F7: ='Pay Sheet'!Y7 -> 833.36715 | G7: =D7*$G$2 -> 9610.236 | H7: =E7+F7+G7 -> 20053.839 | I7: =H7*0.01 -> 200.53839
A8: ='Pay Sheet'!A8 -> AES-E003 | B8: ='Pay Sheet'!B8 -> Tadiwanashe | C8: ='Pay Sheet'!C8 -> Hungwe | D8: ='Pay Sheet'!W8 -> 374.4 | E8: ='Pay Sheet'!X8 -> 9994.6454 | F8: ='Pay Sheet'!Y8 -> 833.36715 | G8: =D8*$G$2 -> 9994.6454 | H8: =E8+F8+G8 -> 20822.658 | I8: =H8*0.01 -> 208.22658
B9: Total | D9: =SUM(D4:D8) -> 1803.84 | E9: =SUM(E4:E6) -> 28548.808 | F9: =SUM(F4:F6) -> 2147.2461 | G9: =SUM(G4:G6) -> 28548.808 | H9: =SUM(H4:H6) -> 59244.862 | I9: =SUM(I4:I6) -> 592.44862

Sheet Sage Journal Entry
B1: USD | D1: ZWL
A2: Details | B2: Debit | C2: Credit | D2: Debit | E2: Credit
A3: Gross Salaries | B3: ='Pay Sheet'!W13 -> 1972.32 | D3: ='Pay Sheet'!X13 -> 52651.28
A4: NSSA | E4: ='Pay Sheet'!Y13 -> 4218.7635
A5: PAYE | C5: ='Pay Sheet'!AK13+'Pay Sheet'!AL13 -> 379.37538 | E5: ='Pay Sheet'!AM13+'Pay Sheet'!AN13 -> 10127.464
A6: Maintenance
A7: Garnish
A8: Net | C8: ='Pay Sheet'!AO13 -> 1513.9271 | E8: ='Pay Sheet'!AW13 -> 47451.277
A9: MIPF
A10: Nyaradzo
A11: NEC
A12: Totals | B12: =SUM(B3:B11) -> 1972.32 | C12: =SUM(C3:C11) -> 1893.3024 | D12: =SUM(D3:D11) -> 52651.28 | E12: =SUM(E3:E11) -> 61797.505
