Workbook

Sheet Paysheet
J1: tax ratio | Q1: =D2 -> 26.6951 | S1: =Q1 -> 26.6951 | AA1: Refer to leave section | AG1: Rate | AH1: =Q1 -> 26.6951 | AP1: Rate | AQ1: =AH1 -> 26.6951 | BG1: Garnish Believe Mhererwa
C2: Exchange rate | D2: 26.6951 | J2: USD/ZWL | P2: Basic | R2: Allowances | AC2: CILL | AD2: Bonus | AE2: USD/ZIG | AF2: Gross | AI2: Allowable Deductions | AO2: Taxable Income | AQ2: Total Taxable in | AR2: PAYE in | AS2: Tax Credits | AT2: Net PAYE | AU2: PAYE USD | AW2: PAYE ZIG | AY2: Salary After Tax | BA2: Other Deductions | BJ2: Advances | BL2: Net Salary | BO2: Tax Table USD | BU2: ZWL | BX2: USD | CA2: Leave Days | CH2: Rate | CI2: =AQ1 -> 26.6951
A3: Works # | B3: Netsai | C3: Nhemachena | D3: National 78-171262Y32 | E3: Pay Date | F3: Station | G3: Occupation | H3: Grade | I3: NSSA Number | J3: RATIO | K3: Period | L3: Hours | M3: Rate/hr | N3: UG Shifts | O3: NS Hours | P3: USD | Q3: ZWL | R3: USD | S3: COLA | T3: Underground | U3: Night Shift | V3: Project/Acting | W3: Overtime @2 | X3: Overtime @1.5 | Y3: Hours @2 | Z3: Hours @1.5 | AA3: Days sold | AB3: Gratuity | AC3: USD | AD3: USD | AE3: Ratio | AF3: Total | AG3: usd | AH3: ZWL | AI3: NSSA | AJ3: NSSA USD | AK3: NSSA ZIG | AL3: MIPF | AM3: NEC | AN3: Non Taxable Bonus | AO3: USD | AP3: ZIG | AQ3: USD | AR3: USD | AS3: USD | AT3: USD | AU3: PAYE | AV3: AIDS LEVY | AW3: PAYE | AX3: AIDS LEVY | AY3: USD | AZ3: ZWL | BA3: Nyaradzo | BB3: CBZ Life | BC3: Maint ZIG | BD3: Maint USD | BE3: Funeral Assist ZIG | BF3: Loan Repayment ZIG | BG3: Loan Repayment USD | BH3: Funeral USD | BI3: May Day (USD) | BJ3: USD | BK3: ZIG | BL3: USD | BM3: ZIG | BN3: 0-100 | BO3: 100.01-300 | BP3: 300.01-1000 | BQ3: 1000.01-2000 | BR3: 2000.01-3000 | BS3: 3000 and Above | BT3: Total | BU3: Bank | BV3: Branch | BW3: Account Number | BX3: Bank | BY3: Branch | BZ3: Account Number | CA3: Opening | CB3: Acrued | CC3: Taken | CD3: CILL | CE3: Closing | CF3: Daily Rate | CG3: Value of days | CH3: USD | CI3: ZIG
A4: AES-E046 | B4: Tarisai | C4: Zinyama | D4: 53-225710V33 | E4: 45747 | F4: Mimosa | G4: Site Manager | H4: J | I4: 9683481Q | J4: =AO4/AQ4 -> 0.46965834 | K4: 3/2025 | L4: 208 | M4: 6.49 | P4: =L4*M4 -> 1349.92 | Q4: =P4*$Q$1 -> 36036.249 | R4: =1700 -> 1700 | S4: =P4*0.3*$S$1*0.5 -> 5405.4374 | U4: =O4*M4*0.1 -> 0 | W4: =Y4*M4*2 -> 0 | X4: =Z4*M4*1.5 -> 0 | AA4: =CD4 -> 0 | AB4: =P4*0.075 -> 101.244 | AC4: =M4*8*AA4 -> 0 | AE4: =AO4/AQ4 -> 0.46965834 | AF4: =P4+R4+T4+U4+V4+W4+X4+AB4+AC4+AD4 -> 3151.164 | AG4: =AF4*0.5 -> 1575.582 | AH4: =((AF4-AG4)*AH1)+S4 -> 47465.756 | AI4: =IF(Q4>18519.27,0.045*18519.27,Q4*0.045) -> 833.36715 | AJ4: =(AI4*0.5)/$AQ$1 -> 15.608991 | AK4: =(AI4*0.4) -> 333.34686 | AL4: 0 | AM4: =(Q4*0.003) -> 108.10875 | AN4: =IF(AD4>320,320,AD4) -> 0 | AO4: =AG4-AN4-AJ4 -> 1559.973 | AP4: =AH4-AK4-AL4-AM4-BB4 -> 47024.301 | AQ4: =AO4+(AP4/$AQ$1) -> 3321.5061 | AR4: =BT4 -> 993.60242 | AS4: 75 | AT4: =AR4-AS4 -> 918.60242 | AU4: =AT4*AE4 -> 431.42929 | AV4: =AU4*0.03 -> 12.942879 | AW4: =(AT4-AU4)*$AQ$1 -> 13005.136 | AX4: =AW4*0.03 -> 390.15407 | AY4: =AO4-AU4-AV4 -> 1115.6008 | AZ4: =AP4-AW4-AX4 -> 33629.011 | BA4: ='Nyaradzo Workings'!K8 -> 1177.3392 | BE4: 0 | BI4: 12.5 | BL4: =AY4-BI4-BG4-BH4-BD4+BJ4 -> 1103.1008 | BM4: =AZ4-BA4-BC4-BE4-BF4+BK4 -> 32451.672 | BN4: =IF(AQ4<100,0,0) -> 0 | BO4: =IF(AQ4<100,"",IF(AQ4<=300,AQ4*0.2-20,)) -> 0 | BP4: =IF(AQ4<300.01,"",IF(AQ4<=1000,AQ4*0.25-35,)) -> 0 | BQ4: =IF(AQ4<1000.01,"",IF(AQ4<=2000,AQ4*0.3-85,)) -> 0 | BR4: =IF(AQ4<2000.01,"",IF(AQ4<=3000,AQ4*0.35-185,)) -> 0 | BS4: =IF(AQ4<3000.01,"",IF(AQ4>3000,AQ4*0.4-335,)) -> 993.60242 | BT4: =SUM(BN4:BS4) -> 993.60242 | BU4: FBC | BV4: Zvishavane | BW4: 8374810963284 | BX4: FBC | BY4: Zvishavane | BZ4: 4591712639586 | CA4: 20.75 | CB4: 2.5 | CC4: 1 | CE4: =CA4+CB4-CC4-CD4 -> 22.25 | CF4: =M4*8 -> 51.92 | CG4: =CE4*CF4 -> 1155.22 | CH4: =CG4*0.4 -> 462.088 | CI4: =(CG4-CH4)*$CI$2 -> 18503.228
A5: AES-E049 | B5: Marvellous | C5: Chakanetsa | D5: 42-350280J52 | E5: =E4 -> 45747 | F5: Mimosa | G5: SHE Officer | H5: 4/11 | I5: 8930103H | J5: =AO5/AQ5 -> 0.37661718 | K5: =K4 -> 3/2025 | L5: 208 | M5: 3.85 | N5: 11 | P5: =L5*M5 -> 800.8 | Q5: =P5*$Q$1 -> 21377.436 | R5: 438 | S5: =P5*0.3*$S$1*0.5 -> 3206.6154 | T5: =N5*M5*8*0.05 -> 16.94 | U5: =O5*M5*0.1 -> 0 | W5: =Y5*M5*2 -> 0 | X5: =Z5*M5*1.5 -> 0 | AA5: =CD5 -> 0 | AB5: =P5*0.075 -> 60.06 | AC5: =M5*8*AA5 -> 0 | AE5: =AO5/AQ5 -> 0.37661718 | AF5: =P5+R5+T5+U5+V5+W5+X5+AB5+AC5+AD5 -> 1315.8 | AG5: =AF5*0.5 -> 657.9 | AH5: =(AF5-AG5)*AH1+(300*AH1)+S5 -> 28777.852 | AI5: =IF(Q5>18519.27,0.045*18519.27,Q5*0.045) -> 833.36715 | AJ5: =(AI5*0.5)/$AQ$1 -> 15.608991 | AK5: =(AI5*0.4) -> 333.34686 | AL5: 0 | AM5: =(Q5*0.003) -> 64.132308 | AN5: =IF(AD5>320,320,AD5) -> 0 | AO5: =AG5-AN5-AJ5 -> 642.29101 | AP5: =AH5-AK5-AL5-AM5-BB5 -> 28380.373 | AQ5: =AO5+(AP5/$AQ$1) -> 1705.4214 | AR5: =BT5 -> 426.62642 | AS5: 0 | AT5: =AR5-AS5 -> 426.62642 | AU5: =AT5*AE5 -> 160.67484 | AV5: =AU5*0.03 -> 4.8202453 | AW5: =(AT5-AU5)*$AQ$1 -> 7099.6041 | AX5: =AW5*0.03 -> 212.98812 | AY5: =AO5-AU5-AV5 -> 476.79592 | AZ5: =AP5-AW5-AX5 -> 21067.78 | BA5: ='Nyaradzo Workings'!K9 -> 711.2292 | BE5: 0 | BI5: 12.5 | BL5: =AY5-BI5-BG5-BH5-BD5+BJ5 -> 464.29592 | BM5: =AZ5-BA5-BC5-BE5-BF5+BK5 -> 20356.551 | BN5: =IF(AQ5<100,0,0) -> 0 | BO5: =IF(AQ5<100,"",IF(AQ5<=300,AQ5*0.2-20,)) -> 0 | BP5: =IF(AQ5<300.01,"",IF(AQ5<=1000,AQ5*0.25-35,)) -> 0 | BQ5: =IF(AQ5<1000.01,"",IF(AQ5<=2000,AQ5*0.3-85,)) -> 426.62642 | BR5: =IF(AQ5<2000.01,"",IF(AQ5<=3000,AQ5*0.35-185,)) | BS5: =IF(AQ5<3000.01,"",IF(AQ5>3000,AQ5*0.4-335,)) | BT5: =SUM(BN5:BS5) -> 426.62642 | BU5: FBC | BV5: Zvishavane | BW5: 6276992244264 | BX5: FBC | BY5: Zvishavane | BZ5: 6563946412917 | CA5: 27.96 | CB5: 2.5 | CE5: =CA5+CB5-CC5-CD5 -> 30.46 | CF5: =M5*8 -> 30.8 | CG5: =CE5*CF5 -> 938.168 | CH5: =CG5*0.4 -> 375.2672 | CI5: =(CG5-CH5)*$CI$2 -> 15026.693
A6: AES-E022 | B6: Obvious | C6: Mpofu | D6: 11-109767Q74 | E6: =E5 -> 45747 | F6: Mimosa | G6: Overseer Miner | H6: 4/11 | I6: 9143903G | J6: =AO6/AQ6 -> 0.46517559 | K6: =K5 -> 3/2025 | L6: 208 | M6: 3.85 | N6: 25 | P6: =L6*M6 -> 800.8 | Q6: =P6*$Q$1 -> 21377.436 | R6: 438 | S6: =P6*0.3*$S$1*0.5 -> 3206.6154 | T6: =N6*M6*8*0.05 -> 38.5 | U6: =O6*M6*0.1 -> 0 | W6: =Y6*M6*2 -> 0 | X6: =Z6*M6*1.5 -> 0 | AA6: =CD6 -> 10 | AB6: 60.06 | AC6: =M6*8*AA6 -> 308 | AE6: =AO6/AQ6 -> 0.46517559 | AF6: =P6+R6+T6+U6+V6+W6+X6+AB6+AC6+AD6 -> 1645.36 | AG6: =AF6*0.5 -> 822.68 | AH6: =(AF6-AG6)*AH1+S6 -> 25168.14 | AI6: =IF(Q6>18519.27,0.045*18519.27,Q6*0.045) -> 833.36715 | AJ6: =(AI6*0.5)/$AQ$1 -> 15.608991 | AK6: =(AI6*0.4) -> 333.34686 | AL6: 0 | AM6: =Q6*0.003 -> 64.132308 | AN6: =IF(AD6>320,320,AD6) -> 0 | AO6: =AG6-AN6-AJ6 -> 807.07101 | AP6: =AH6-AK6-AL6-AM6-BB6 -> 24770.661 | AQ6: =AO6+(AP6/$AQ$1) -> 1734.9814 | AR6: =BT6 -> 435.49442 | AS6: 0 | AT6: =AR6-AS6 -> 435.49442 | AU6: =AT6*AE6 -> 202.58138 | AV6: =AU6*0.03 -> 6.0774413 | AW6: =(AT6-AU6)*$AQ$1 -> 6217.6371 | AX6: =AW6*0.03 -> 186.52911 | AY6: =AO6-AU6-AV6 -> 598.41219 | AZ6: =AP6-AW6-AX6 -> 18366.495 | BA6: ='Nyaradzo Workings'!K10 -> 1260.2092 | BE6: 0 | BI6: 12.5 | BL6: =AY6-BI6-BG6-BH6-BD6+BJ6 -> 585.91219 | BM6: =AZ6-BA6-BC6-BE6-BF6+BK6 -> 17106.286 | BN6: =IF(AQ6<100,0,0) -> 0 | BO6: =IF(AQ6<100,"",IF(AQ6<=300,AQ6*0.2-20,)) -> 0 | BP6: =IF(AQ6<300.01,"",IF(AQ6<=1000,AQ6*0.25-35,)) -> 0 | BQ6: =IF(AQ6<1000.01,"",IF(AQ6<=2000,AQ6*0.3-85,)) -> 435.49442 | BR6: =IF(AQ6<2000.01,"",IF(AQ6<=3000,AQ6*0.35-185,)) | BS6: =IF(AQ6<3000.01,"",IF(AQ6>3000,AQ6*0.4-335,)) | BT6: =SUM(BN6:BS6) -> 435.49442 | BU6: FBC | BV6: VIRTUAL | BW6: 2760919825741 | BX6: FBC | BY6: VIRTUAL | BZ6: 9900087728107 | CA6: 19.35 | CB6: 2.5 | CD6: 10 | CE6: =CA6+CB6-CC6-CD6 -> 11.85 | CF6: =M6*8 -> 30.8 | CG6: =CE6*CF6 -> 364.98 | CH6: =CG6*0.4 -> 145.992 | CI6: =(CG6-CH6)*$CI$2 -> 5845.9066
A7: AES-E035 | B7: Polite | C7: Mudarikwa | D7: 35-238890M10 | E7: =E6 -> 45747 | F7: Mimosa | G7: Admin Clerk | H7: 4/6 | I7: 2130789B | J7: =AO7/AQ7 -> 0.44557586 | K7: =K6 -> 3/2025 | L7: 208 | M7: 3.6 | P7: =L7*M7 -> 748.8 | Q7: =P7*$Q$1 -> 19989.291 | R7: 153 | S7: =P7*0.3*$S$1*0.5 -> 2998.3936 | T7: =N7*M7*8*0.05 -> 0 | U7: =O7*M7*0.1 -> 0 | W7: =Y7*M7*2 -> 0 | X7: =Z7*M7*1.5 -> 0 | AA7: =CD7 -> 0 | AB7: 56.16 | AC7: =M7*8*AA7 -> 0 | AE7: =AO7/AQ7 -> 0.44557586 | AF7: =P7+R7+T7+U7+V7+W7+X7+AB7+AC7+AD7 -> 957.96 | AG7: =AF7*0.5 -> 478.98 | AH7: =(AF7-AG7)*AH1+S7 -> 15784.813 | AI7: =IF(Q7>18519.27,0.045*18519.27,Q7*0.045) -> 833.36715 | AJ7: =(AI7*0.5)/$AQ$1 -> 15.608991 | AK7: =(AI7*0.4) -> 333.34686 | AL7: 0 | AM7: =(Q7*0.003) -> 59.967873 | AN7: =IF(AD7>320,320,AD7) -> 0 | AO7: =AG7-AN7-AJ7 -> 463.37101 | AP7: =AH7-AK7-AL7-AM7-BB7 -> 15391.498 | AQ7: =AO7+(AP7/$AQ$1) -> 1039.9374 | AR7: =BT7 -> 226.98122 | AS7: 0 | AT7: =AR7-AS7 -> 226.98122 | AU7: =AT7*AE7 -> 101.13735 | AV7: =AU7*0.03 -> 3.0341206 | AW7: =(AT7-AU7)*$AQ$1 -> 3359.4147 | AX7: =AW7*0.03 -> 100.78244 | AY7: =AO7-AU7-AV7 -> 359.19953 | AZ7: =AP7-AW7-AX7 -> 11931.301 | BA7: ='Nyaradzo Workings'!K11 -> 1196.4492 | BE7: 0 | BI7: 12.5 | BL7: =AY7-BI7-BG7-BH7-BD7+BJ7 -> 346.69953 | BM7: =AZ7-BA7-BC7-BE7-BF7+BK7 -> 10734.852 | BN7: =IF(AQ7<100,0,0) -> 0 | BO7: =IF(AQ7<100,"",IF(AQ7<=300,AQ7*0.2-20,)) -> 0 | BP7: =IF(AQ7<300.01,"",IF(AQ7<=1000,AQ7*0.25-35,)) -> 0 | BQ7: =IF(AQ7<1000.01,"",IF(AQ7<=2000,AQ7*0.3-85,)) -> 226.98122 | BR7: =IF(AQ7<2000.01,"",IF(AQ7<=3000,AQ7*0.35-185,)) | BS7: =IF(AQ7<3000.01,"",IF(AQ7>3000,AQ7*0.4-335,)) | BT7: =SUM(BN7:BS7) -> 226.98122 | BU7: FBC | BV7: Zvishavane | BW7: 5298743732931 | BX7: FBC | BY7: Zvishavane | BZ7: 6013813941202 | CA7: 7.56 | CB7: 2.5 | CE7: =CA7+CB7-CC7-CD7 -> 10.06 | CF7: =M7*8 -> 28.8 | CG7: =CE7*CF7 -> 289.728 | CH7: =CG7*0.4 -> 115.8912 | CI7: =(CG7-CH7)*$CI$2 -> 4640.5908
A8: AES-E041 | B8: Chenai | C8: Runesu | D8: 22-559469T40 | E8: =E7 -> 45747 | F8: Head Office | G8: Bus Dev Officer | H8: 4/11 | I8: 7754864L | J8: =AO8/AQ8 -> 0.42908737 | K8: =K7 -> 3/2025 | L8: 208 | M8: 4.76 | P8: =L8*M8 -> 990.08 | Q8: =P8*$Q$1 -> 26430.285 | R8: 290 | S8: =P8*0.3*$S$1*0.5 -> 3964.5427 | T8: =N8*M8*8*0.05 -> 0 | U8: =O8*M8*0.1 -> 0 | W8: =Y8*M8*2 -> 0 | X8: =Z8*M8*1.5 -> 0 | AA8: =CD8 -> 0 | AB8: =P8*0.075 -> 74.256 | AC8: =M8*8*AA8 -> 0 | AE8: =AO8/AQ8 -> 0.42908737 | AF8: =P8+R8+T8+U8+V8+W8+X8+AB8+AC8+AD8 -> 1354.336 | AG8: =AF8*0.5 -> 677.168 | AH8: =(AF8-AG8)*AH1+(70*AH1)+S8 -> 23910.267 | AI8: =IF(Q8>18519.27,0.045*18519.27,Q8*0.045) -> 833.36715 | AJ8: =(AI8*0.5)/$AQ$1 -> 15.608991 | AK8: =(AI8*0.4) -> 333.34686 | AL8: 0 | AM8: =Q8*0.003 -> 79.290854 | AN8: =IF(AD8>320,320,AD8) -> 0 | AO8: =AG8-AN8-AJ8 -> 661.55901 | AP8: =AH8-AK8-AL8-AM8-BB8 -> 23497.629 | AQ8: =AO8+(AP8/$AQ$1) -> 1541.7816 | AR8: =BT8 -> 377.53447 | AS8: 0 | AT8: =AR8-AS8 -> 377.53447 | AU8: =AT8*AE8 -> 161.99528 | AV8: =AU8*0.03 -> 4.8598583 | AW8: =(AT8-AU8)*$AQ$1 -> 5753.8404 | AX8: =AW8*0.03 -> 172.61521 | AY8: =AO8-AU8-AV8 -> 494.70387 | AZ8: =AP8-AW8-AX8 -> 17571.174 | BA8: ='Nyaradzo Workings'!K12 -> 959.5492 | BE8: 0 | BL8: =AY8-BI8-BG8-BH8-BD8+BJ8 -> 494.70387 | BM8: =AZ8-BA8-BC8-BE8-BF8+BK8 -> 16611.625 | BN8: =IF(AQ8<100,0,0) -> 0 | BO8: =IF(AQ8<100,"",IF(AQ8<=300,AQ8*0.2-20,)) -> 0 | BP8: =IF(AQ8<300.01,"",IF(AQ8<=1000,AQ8*0.25-35,)) -> 0 | BQ8: =IF(AQ8<1000.01,"",IF(AQ8<=2000,AQ8*0.3-85,)) -> 377.53447 | BR8: =IF(AQ8<2000.01,"",IF(AQ8<=3000,AQ8*0.35-185,)) | BS8: =IF(AQ8<3000.01,"",IF(AQ8>3000,AQ8*0.4-335,)) | BT8: =SUM(BN8:BS8) -> 377.53447 | BU8: FBC | BV8: Zvishavane | BW8: 2823915366343 | BX8: FBC | BY8: Zvishavane | BZ8: 5652026357519 | CA8: 82.86 | CB8: 2.5 | CE8: =CA8+CB8-CC8-CD8 -> 85.36 | CF8: =M8*8 -> 38.08 | CG8: =CE8*CF8 -> 3250.5088 | CH8: =CG8*0.4 -> 1300.2035 | CI8: =(CG8-CH8)*$CI$2 -> 52063.594
A9: AES-E033 | B9: Tafadzwa | C9: Mafukidze | D9: 16-212235T21 | E9: =E8 -> 45747 | F9: Mimosa | G9: Team Leader | H9: 4/7 | I9: 6229731N | J9: =AO9/AQ9 -> 0.46928971 | K9: =K8 -> 3/2025 | L9: 208 | M9: 2.8 | N9: 22 | P9: =L9*M9 -> 582.4 | Q9: =P9*$Q$1 -> 15547.226 | R9: 100 | S9: =P9*0.3*$S$1*0.5 -> 2332.0839 | T9: =N9*M9*8*0.05 -> 24.64 | U9: =O9*M9*0.1 -> 0 | W9: =Y9*M9*2 -> 0 | X9: =Z9*M9*1.5 -> 0 | AA9: =CD9 -> 0 | AC9: =M9*8*AA9 -> 0 | AE9: =AO9/AQ9 -> 0.46928971 | AF9: =P9+R9+T9+U9+V9+W9+X9+AB9+AC9+AD9 -> 707.04 | AG9: =AF9*0.5 -> 353.52 | AH9: =(AF9-AG9)*AH1+S9 -> 11769.336 | AI9: =IF(Q9>18519.27,0.045*18519.27,Q9*0.045) -> 699.62518 | AJ9: =(AI9*0.5)/$AQ$1 -> 13.104 | AK9: =(AI9*0.4) -> 279.85007 | AL9: =Q9*0.075 -> 1166.042 | AM9: =Q9*0.003 -> 46.641679 | AN9: =IF(AD9>320,320,AD9) -> 0 | AO9: =AG9-AN9-AJ9 -> 340.416 | AP9: =AH9-AK9-AL9-AM9-BB9 -> 10276.802 | AQ9: =AO9+(AP9/$AQ$1) -> 725.3856 | AR9: =BT9 -> 146.3464 | AS9: 0 | AT9: =AR9-AS9 -> 146.3464 | AU9: =AT9*AE9 -> 68.67886 | AV9: =AU9*0.03 -> 2.0603658 | AW9: =(AT9-AU9)*$AQ$1 -> 2073.3427 | AX9: =AW9*0.03 -> 62.200282 | AY9: =AO9-AU9-AV9 -> 269.67677 | AZ9: =AP9-AW9-AX9 -> 8141.2589 | BA9: ='Nyaradzo Workings'!K13 -> 698.9992 | BB9: 0 | BE9: 0 | BI9: 12.5 | BL9: =AY9-BI9-BG9-BH9-BD9+BJ9 -> 257.17677 | BM9: =AZ9-BA9-BC9-BE9-BF9+BK9 -> 7442.2597 | BN9: =IF(AQ9<100,0,0) -> 0 | BO9: =IF(AQ9<100,"",IF(AQ9<=300,AQ9*0.2-20,)) -> 0 | BP9: =IF(AQ9<300.01,"",IF(AQ9<=1000,AQ9*0.25-35,)) -> 146.3464 | BQ9: =IF(AQ9<1000.01,"",IF(AQ9<=2000,AQ9*0.3-85,)) | BR9: =IF(AQ9<2000.01,"",IF(AQ9<=3000,AQ9*0.35-185,)) | BS9: =IF(AQ9<3000.01,"",IF(AQ9>3000,AQ9*0.4-335,)) | BT9: =SUM(BN9:BS9) -> 146.3464 | BU9: FBC | BV9: Zvishavane | BW9: 5957561986265 | BX9: FBC | BY9: Zvishavane | BZ9: 4704859533483 | CA9: 16 | CB9: 2.5 | CE9: =CA9+CB9-CC9-CD9 -> 18.5 | CF9: =M9*8 -> 22.4 | CG9: =CE9*CF9 -> 414.4 | CH9: =CG9*0.4 -> 165.76 | CI9: =(CG9-CH9)*$CI$2 -> 6637.4697
A10: AES-E034 | B10: Kudzai | C10: Gwatidzo | D10: 45-313487Y35 | E10: =E9 -> 45747 | F10: Mimosa | G10: Team Leader | H10: 4/7 | I10: 1987737H | J10: =AO10/AQ10 -> 0.47690915 | K10: =K9 -> 3/2025 | L10: 208 | M10: 2.8 | N10: 25 | P10: =L10*M10 -> 582.4 | Q10: =P10*$Q$1 -> 15547.226 | S10: =P10*0.3*$S$1*0.5 -> 2332.0839 | T10: =N10*M10*8*0.05 -> 28 | U10: =O10*M10*0.1 -> 0 | W10: =Y10*M10*2 -> 0 | X10: =Z10*M10*1.5 -> 0 | AA10: =CD10 -> 15 | AC10: =M10*8*AA10 -> 336 | AE10: =AO10/AQ10 -> 0.47690915 | AF10: =P10+R10+T10+U10+V10+W10+X10+AB10+AC10+AD10 -> 946.4 | AG10: =AF10*0.5 -> 473.2 | AH10: =(AF10-AG10)*$AH$1+S10 -> 14964.205 | AI10: =IF(Q10>18519.27,0.045*18519.27,Q10*0.045) -> 699.62518 | AJ10: =(AI10*0.5)/$AQ$1 -> 13.104 | AK10: =(AI10*0.4) -> 279.85007 | AL10: =Q10*0.075 -> 1166.042 | AM10: =Q10*0.003 -> 46.641679 | AN10: =IF(AD10>320,320,AD10) -> 0 | AO10: =AG10-AN10-AJ10 -> 460.096 | AP10: =AH10-AK10-AL10-AM10-BB10 -> 13471.672 | AQ10: =AO10+(AP10/$AQ$1) -> 964.7456 | AR10: =BT10 -> 206.1864 | AS10: 0 | AT10: =AR10-AS10 -> 206.1864 | AU10: =AT10*AE10 -> 98.33218 | AV10: =AU10*0.03 -> 2.9499654 | AW10: =(AT10-AU10)*$AQ$1 -> 2879.1792 | AX10: =AW10*0.03 -> 86.375376 | AY10: =AO10-AU10-AV10 -> 358.81385 | AZ10: =AP10-AW10-AX10 -> 10506.117 | BA10: ='Nyaradzo Workings'!K14 -> 901.0247 | BB10: 0 | BE10: 0 | BL10: =AY10-BI10-BG10-BH10-BD10+BJ10 -> 358.81385 | BM10: =AZ10-BA10-BC10-BE10-BF10+BK10 -> 9605.0923 | BN10: =IF(AQ10<100,0,0) -> 0 | BO10: =IF(AQ10<100,"",IF(AQ10<=300,AQ10*0.2-20,)) -> 0 | BP10: =IF(AQ10<300.01,"",IF(AQ10<=1000,AQ10*0.25-35,)) -> 206.1864 | BQ10: =IF(AQ10<1000.01,"",IF(AQ10<=2000,AQ10*0.3-85,)) | BR10: =IF(AQ10<2000.01,"",IF(AQ10<=3000,AQ10*0.35-185,)) | BS10: =IF(AQ10<3000.01,"",IF(AQ10>3000,AQ10*0.4-335,)) | BT10: =SUM(BN10:BS10) -> 206.1864 | BU10: FBC | BV10: Zvishavane | BW10: 9596400274673 | BX10: FBC | BY10: Zvishavane | BZ10: 2623715817487 | CA10: 18.03 | CB10: 2.5 | CD10: 15 | CE10: =CA10+CB10-CC10-CD10 -> 5.53 | CF10: =M10*8 -> 22.4 | CG10: =CE10*CF10 -> 123.872 | CH10: =CG10*0.4 -> 49.5488 | CI10: =(CG10-CH10)*$CI$2 -> 1984.0653
A11: AES-E036 | B11: Dadirai | C11: Nyakudya | D11: 56-969634J07 | E11: =E10 -> 45747 | F11: Mimosa | G11: Service Assitant | H11: 4/3 | I11: 5672073Y | J11: =AO11/AQ11 -> 0.46456945 | K11: =K10 -> 3/2025 | L11: 208 | M11: 1.62 | N11: 25 | P11: =L11*M11 -> 336.96 | Q11: =P11*$Q$1 -> 8995.1809 | S11: =P11*0.3*$S$1*0.5 -> 1349.2771 | T11: =N11*M11*8*0.05 -> 16.2 | U11: =O11*M11*0.1 -> 0 | W11: =Y11*M11*2 -> 0 | X11: =Z11*M11*1.5 -> 0 | AA11: =CD11 -> 0 | AC11: =M11*8*AA11 -> 0 | AE11: =AO11/AQ11 -> 0.46456945 | AF11: =P11+R11+T11+U11+V11+W11+X11+AB11+AC11+AD11 -> 353.16 | AG11: =AF11*0.5 -> 176.58 | AH11: =(AF11-AG11)*$AH$1+S11 -> 6063.0979 | AI11: =IF(Q11>18519.27,0.045*18519.27,Q11*0.045) -> 404.78314 | AJ11: =(AI11*0.5)/$AQ$1 -> 7.5816 | AK11: =(AI11*0.4) -> 161.91326 | AL11: =Q11*0.075 -> 674.63857 | AM11: =Q11*0.003 -> 26.985543 | AN11: =IF(AD11>320,320,AD11) -> 0 | AO11: =AG11-AN11-AJ11 -> 168.9984 | AP11: =AH11-AK11-AL11-AM11-BB11 -> 5199.5605 | AQ11: =AO11+(AP11/$AQ$1) -> 363.77424 | AR11: =BT11 -> 55.94356 | AS11: 0 | AT11: =AR11-AS11 -> 55.94356 | AU11: =AT11*AE11 -> 25.989669 | AV11: =AU11*0.03 -> 0.77969007 | AW11: =(AT11-AU11)*$AQ$1 -> 799.62211 | AX11: =AW11*0.03 -> 23.988663 | AY11: =AO11-AU11-AV11 -> 142.22904 | AZ11: =AP11-AW11-AX11 -> 4375.9498 | BA11: ='Nyaradzo Workings'!K15 -> 785.3847 | BB11: 0 | BL11: =AY11-BI11-BG11-BH11-BD11+BJ11 -> 142.22904 | BM11: =AZ11-BA11-BC11-BE11-BF11+BK11 -> 3590.5651 | BN11: =IF(AQ11<100,0,0) -> 0 | BO11: =IF(AQ11<100,"",IF(AQ11<=300,AQ11*0.2-20,)) -> 0 | BP11: =IF(AQ11<300.01,"",IF(AQ11<=1000,AQ11*0.25-35,)) -> 55.94356 | BQ11: =IF(AQ11<1000.01,"",IF(AQ11<=2000,AQ11*0.3-85,)) | BR11: =IF(AQ11<2000.01,"",IF(AQ11<=3000,AQ11*0.35-185,)) | BS11: =IF(AQ11<3000.01,"",IF(AQ11>3000,AQ11*0.4-335,)) | BT11: =SUM(BN11:BS11) -> 55.94356 | BU11: FBC | BV11: Zvishavane | BW11: 6866940554958 | BX11: FBC | BY11: Zvishavane | BZ11: 3301119435213 | CA11: 13.82 | CB11: 2.5 | CE11: =CA11+CB11-CC11-CD11 -> 16.32 | CF11: =M11*8 -> 12.96 | CG11: =CE11*CF11 -> 211.5072 | CH11: =CG11*0.4 -> 84.60288 | CI11: =(CG11-CH11)*$CI$2 -> 3387.7235
A12: AES-E037 | B12: Tarisai | C12: Chidzambwa | D12: 35-269430Q72 | E12: =E11 -> 45747 | F12: Mimosa | G12: Service Assitant | H12: 4/3 | I12: 4860684V | J12: =AO12/AQ12 -> 0.46456945 | K12: =K11 -> 3/2025 | L12: 208 | M12: 1.62 | N12: 25 | P12: =L12*M12 -> 336.96 | Q12: =P12*$Q$1 -> 8995.1809 | S12: =P12*0.3*$S$1*0.5 -> 1349.2771 | T12: =N12*M12*8*0.05 -> 16.2 | U12: =O12*M12*0.1 -> 0 | W12: =Y12*M12*2 -> 0 | X12: =Z12*M12*1.5 -> 0 | AA12: =CD12 -> 0 | AC12: =M12*8*AA12 -> 0 | AE12: =AO12/AQ12 -> 0.46456945 | AF12: =P12+R12+T12+U12+V12+W12+X12+AB12+AC12+AD12 -> 353.16 | AG12: =AF12*0.5 -> 176.58 | AH12: =(AF12-AG12)*$AH$1+S12 -> 6063.0979 | AI12: =IF(Q12>18519.27,0.045*18519.27,Q12*0.045) -> 404.78314 | AJ12: =(AI12*0.5)/$AQ$1 -> 7.5816 | AK12: =(AI12*0.4) -> 161.91326 | AL12: =Q12*0.075 -> 674.63857 | AM12: =Q12*0.003 -> 26.985543 | AN12: =IF(AD12>320,320,AD12) -> 0 | AO12: =AG12-AN12-AJ12 -> 168.9984 | AP12: =AH12-AK12-AL12-AM12-BB12 -> 5199.5605 | AQ12: =AO12+(AP12/$AQ$1) -> 363.77424 | AR12: =BT12 -> 55.94356 | AS12: 0 | AT12: =AR12-AS12 -> 55.94356 | AU12: =AT12*AE12 -> 25.989669 | AV12: =AU12*0.03 -> 0.77969007 | AW12: =(AT12-AU12)*$AQ$1 -> 799.62211 | AX12: =AW12*0.03 -> 23.988663 | AY12: =AO12-AU12-AV12 -> 142.22904 | AZ12: =AP12-AW12-AX12 -> 4375.9498 | BA12: 0 | BB12: 0 | BL12: =AY12-BI12-BG12-BH12-BD12+BJ12 -> 142.22904 | BM12: =AZ12-BA12-BC12-BE12-BF12+BK12 -> 4375.9498 | BN12: =IF(AQ12<100,0,0) -> 0 | BO12: =IF(AQ12<100,"",IF(AQ12<=300,AQ12*0.2-20,)) -> 0 | BP12: =IF(AQ12<300.01,"",IF(AQ12<=1000,AQ12*0.25-35,)) -> 55.94356 | BQ12: =IF(AQ12<1000.01,"",IF(AQ12<=2000,AQ12*0.3-85,)) | BR12: =IF(AQ12<2000.01,"",IF(AQ12<=3000,AQ12*0.35-185,)) | BS12: =IF(AQ12<3000.01,"",IF(AQ12>3000,AQ12*0.4-335,)) | BT12: =SUM(BN12:BS12) -> 55.94356 | BU12: FBC | BV12: Zvishavane | BW12: 8523518553916 | BX12: FBC | BY12: Zvishavane | BZ12: 1169912801200 | CA12: 20 | CB12: 2.5 | CE12: =CA12+CB12-CC12-CD12 -> 22.5 | CF12: =M12*8 -> 12.96 | CG12: =CE12*CF12 -> 291.6 | CH12: =CG12*0.4 -> 116.64 | CI12: =(CG12-CH12)*$CI$2 -> 4670.5747
A13: AES-E015 | B13: Believe | C13: Mhererwa | D13: 16-178898Z21 | E13: =E12 -> 45747 | F13: Mimosa | G13: Service Assitant | H13: 4/3 | I13: 3351868P | J13: =AO13/AQ13 -> 0.43829694 | K13: =K12 -> 3/2025 | L13: 208 | M13: 1.62 | N13: 24 | P13: =L13*M13 -> 336.96 | Q13: =P13*$Q$1 -> 8995.1809 | S13: =P13*0.3*$S$1*0.5 -> 1349.2771 | T13: =N13*M13*8*0.05 -> 15.552 | U13: =O13*M13*0.1 -> 0 | W13: =Y13*M13*2 -> 0 | X13: =Z13*M13*1.5 -> 0 | AA13: =CD13 -> 0 | AB13: =P13*0.075 -> 25.272 | AC13: =M13*8*AA13 -> 0 | AE13: =AO13/AQ13 -> 0.43829694 | AF13: =P13+R13+T13+U13+V13+W13+X13+AB13+AC13+AD13 -> 377.784 | AG13: =AF13*0.5 -> 188.892 | AH13: =(AF13-AG13)*$AH$1+S13 -> 6391.768 | AI13: =IF(Q13>18519.27,0.045*18519.27,Q13*0.045) -> 404.78314 | AJ13: =(AI13*0.5)/$AQ$1 -> 7.5816 | AK13: =(AI13*0.4) -> 161.91326 | AL13: 0 | AM13: =Q13*0.003 -> 26.985543 | AN13: =IF(AD13>320,320,AD13) -> 0 | AO13: =AG13-AN13-AJ13 -> 181.3104 | AP13: =AH13-AK13-AL13-AM13-BB13 -> 6202.8692 | AQ13: =AO13+(AP13/$AQ$1) -> 413.67024 | AR13: =BT13 -> 68.41756 | AS13: 0 | AT13: =AR13-AS13 -> 68.41756 | AU13: =AT13*AE13 -> 29.987207 | AV13: =AU13*0.03 -> 0.89961621 | AW13: =(AT13-AU13)*$AQ$1 -> 1025.9021 | AX13: =AW13*0.03 -> 30.777063 | AY13: =AO13-AU13-AV13 -> 150.42358 | AZ13: =AP13-AW13-AX13 -> 5146.19 | BA13: 0 | BB13: 0 | BG13: 120 | BL13: =AY13-BI13-BG13-BH13-BD13+BJ13 -> 30.423577 | BM13: =AZ13-BA13-BC13-BE13-BF13+BK13 -> 5146.19 | BN13: =IF(AQ13<100,0,0) -> 0 | BO13: =IF(AQ13<100,"",IF(AQ13<=300,AQ13*0.2-20,)) -> 0 | BP13: =IF(AQ13<300.01,"",IF(AQ13<=1000,AQ13*0.25-35,)) -> 68.41756 | BQ13: =IF(AQ13<1000.01,"",IF(AQ13<=2000,AQ13*0.3-85,)) | BR13: =IF(AQ13<2000.01,"",IF(AQ13<=3000,AQ13*0.35-185,)) | BS13: =IF(AQ13<3000.01,"",IF(AQ13>3000,AQ13*0.4-335,)) | BT13: =SUM(BN13:BS13) -> 68.41756 | BU13: FBC | BV13: Zvishavane | BW13: 1633703484987 | BX13: FBC | BY13: Zvishavane | BZ13: 7497575109867 | CA13: 4.02 | CB13: 2.5 | CC13: 1 | CE13: =CA13+CB13-CC13-CD13 -> 5.52 | CF13: =M13*8 -> 12.96 | CG13: =CE13*CF13 -> 71.5392 | CH13: =CG13*0.4 -> 28.61568 | CI13: =(CG13-CH13)*$CI$2 -> 1145.8477
A14: AES-E016 | B14: Shingai | C14: Rusike | D14: 76-679364E57 | E14: =E13 -> 45747 | F14: Mimosa | G14: Service Assitant | H14: 4/3 | I14: 4078418J | J14: =AO14/AQ14 -> 0.43839344 | K14: =K13 -> 3/2025 | L14: 208 | M14: 1.62 | N14: 25 | P14: =L14*M14 -> 336.96 | Q14: =P14*$Q$1 -> 8995.1809 | S14: =P14*0.3*$S$1*0.5 -> 1349.2771 | T14: =N14*M14*8*0.05 -> 16.2 | U14: =O14*M14*0.1 -> 0 | W14: =Y14*M14*2 -> 0 | X14: =Z14*M14*1.5 -> 0 | AA14: =CD14 -> 0 | AB14: =P14*0.075 -> 25.272 | AC14: =M14*8*AA14 -> 0 | AE14: =AO14/AQ14 -> 0.43839344 | AF14: =P14+R14+T14+U14+V14+W14+X14+AB14+AC14+AD14 -> 378.432 | AG14: =AF14*0.5 -> 189.216 | AH14: =(AF14-AG14)*$AH$1+S14 -> 6400.4172 | AI14: =IF(Q14>18519.27,0.045*18519.27,Q14*0.045) -> 404.78314 | AJ14: =(AI14*0.5)/$AQ$1 -> 7.5816 | AK14: =(AI14*0.4) -> 161.91326 | AL14: 0 | AM14: =Q14*0.003 -> 26.985543 | AN14: =IF(AD14>320,320,AD14) -> 0 | AO14: =AG14-AN14-AJ14 -> 181.6344 | AP14: =AH14-AK14-AL14-AM14-BB14 -> 6211.5184 | AQ14: =AO14+(AP14/$AQ$1) -> 414.31824 | AR14: =BT14 -> 68.57956 | AS14: 0 | AT14: =AR14-AS14 -> 68.57956 | AU14: =AT14*AE14 -> 30.064829 | AV14: =AU14*0.03 -> 0.90194488 | AW14: =(AT14-AU14)*$AQ$1 -> 1028.1546 | AX14: =AW14*0.03 -> 30.844637 | AY14: =AO14-AU14-AV14 -> 150.66763 | AZ14: =AP14-AW14-AX14 -> 5152.5192 | BA14: ='Nyaradzo Workings'!K16 -> 404.5147 | BB14: 0 | BI14: 12.5 | BL14: =AY14-BI14-BG14-BH14-BD14+BJ14 -> 138.16763 | BM14: =AZ14-BA14-BC14-BE14-BF14+BK14 -> 4748.0045 | BN14: =IF(AQ14<100,0,0) -> 0 | BO14: =IF(AQ14<100,"",IF(AQ14<=300,AQ14*0.2-20,)) -> 0 | BP14: =IF(AQ14<300.01,"",IF(AQ14<=1000,AQ14*0.25-35,)) -> 68.57956 | BQ14: =IF(AQ14<1000.01,"",IF(AQ14<=2000,AQ14*0.3-85,)) | BR14: =IF(AQ14<2000.01,"",IF(AQ14<=3000,AQ14*0.35-185,)) | BS14: =IF(AQ14<3000.01,"",IF(AQ14>3000,AQ14*0.4-335,)) | BT14: =SUM(BN14:BS14) -> 68.57956 | BU14: FBC | BV14: Zvishavane | BW14: 1734986781954 | BX14: FBC | BY14: Zvishavane | BZ14: 7413710132455 | CA14: 15.76 | CB14: 2.5 | CE14: =CA14+CB14-CC14-CD14 -> 18.26 | CF14: =M14*8 -> 12.96 | CG14: =CE14*CF14 -> 236.6496 | CH14: =CG14*0.4 -> 94.65984 | CI14: =(CG14-CH14)*$CI$2 -> 3790.4308
A15: AES-E018 | B15: Gamuchirai | C15: Chirenda | D15: 07-475190G33 | E15: =E14 -> 45747 | F15: Mimosa | G15: Service Assitant | H15: 4/3 | I15: 8761611H | J15: =AO15/AQ15 -> 0.43839344 | K15: =K14 -> 3/2025 | L15: 208 | M15: 1.62 | N15: 25 | P15: =L15*M15 -> 336.96 | Q15: =P15*$Q$1 -> 8995.1809 | S15: =P15*0.3*$S$1*0.5 -> 1349.2771 | T15: =N15*M15*8*0.05 -> 16.2 | U15: =O15*M15*0.1 -> 0 | W15: =Y15*M15*2 -> 0 | X15: =Z15*M15*1.5 -> 0 | AA15: =CD15 -> 0 | AB15: =P15*0.075 -> 25.272 | AC15: =M15*8*AA15 -> 0 | AE15: =AO15/AQ15 -> 0.43839344 | AF15: =P15+R15+T15+U15+V15+W15+X15+AB15+AC15+AD15 -> 378.432 | AG15: =AF15*0.5 -> 189.216 | AH15: =(AF15-AG15)*$AH$1+S15 -> 6400.4172 | AI15: =IF(Q15>18519.27,0.045*18519.27,Q15*0.045) -> 404.78314 | AJ15: =(AI15*0.5)/$AQ$1 -> 7.5816 | AK15: =(AI15*0.4) -> 161.91326 | AL15: 0 | AM15: =Q15*0.003 -> 26.985543 | AN15: =IF(AD15>320,320,AD15) -> 0 | AO15: =AG15-AN15-AJ15 -> 181.6344 | AP15: =AH15-AK15-AL15-AM15-BB15 -> 6211.5184 | AQ15: =AO15+(AP15/$AQ$1) -> 414.31824 | AR15: =BT15 -> 68.57956 | AS15: 0 | AT15: =AR15-AS15 -> 68.57956 | AU15: =AT15*AE15 -> 30.064829 | AV15: =AU15*0.03 -> 0.90194488 | AW15: =(AT15-AU15)*$AQ$1 -> 1028.1546 | AX15: =AW15*0.03 -> 30.844637 | AY15: =AO15-AU15-AV15 -> 150.66763 | AZ15: =AP15-AW15-AX15 -> 5152.5192 | BA15: ='Nyaradzo Workings'!K18 -> 472.7647 | BB15: 0 | BI15: 12.5 | BL15: =AY15-BI15-BG15-BH15-BD15+BJ15 -> 138.16763 | BM15: =AZ15-BA15-BC15-BE15-BF15+BK15 -> 4679.7545 | BN15: =IF(AQ15<100,0,0) -> 0 | BO15: =IF(AQ15<100,"",IF(AQ15<=300,AQ15*0.2-20,)) -> 0 | BP15: =IF(AQ15<300.01,"",IF(AQ15<=1000,AQ15*0.25-35,)) -> 68.57956 | BQ15: =IF(AQ15<1000.01,"",IF(AQ15<=2000,AQ15*0.3-85,)) | BR15: =IF(AQ15<2000.01,"",IF(AQ15<=3000,AQ15*0.35-185,)) | BS15: =IF(AQ15<3000.01,"",IF(AQ15>3000,AQ15*0.4-335,)) | BT15: =SUM(BN15:BS15) -> 68.57956 | BU15: FBC | BV15: Zvishavane | BW15: 2811045688826 | BX15: FBC | BY15: Zvishavane | BZ15: 8150582443075 | CA15: 16.81 | CB15: 2.5 | CE15: =CA15+CB15-CC15-CD15 -> 19.31 | CF15: =M15*8 -> 12.96 | CG15: =CE15*CF15 -> 250.2576 | CH15: =CG15*0.4 -> 100.10304 | CI15: =(CG15-CH15)*$CI$2 -> 4008.391
A16: AES-E013 | B16: Chido | C16: Chigumba | D16: 21-348237F24 | E16: =E15 -> 45747 | F16: Mimosa | G16: Service Assitant | H16: 4/3 | I16: 2264748Q | J16: =AO16/AQ16 -> 0.43829694 | K16: =K15 -> 3/2025 | L16: 208 | M16: 1.62 | N16: 24 | P16: =L16*M16 -> 336.96 | Q16: =P16*$Q$1 -> 8995.1809 | S16: =P16*0.3*$S$1*0.5 -> 1349.2771 | T16: =N16*M16*8*0.05 -> 15.552 | U16: =O16*M16*0.1 -> 0 | W16: =Y16*M16*2 -> 0 | X16: =Z16*M16*1.5 -> 0 | AA16: =CD16 -> 0 | AB16: =P16*0.075 -> 25.272 | AC16: =M16*8*AA16 -> 0 | AE16: =AO16/AQ16 -> 0.43829694 | AF16: =P16+R16+T16+U16+V16+W16+X16+AB16+AC16+AD16 -> 377.784 | AG16: =AF16*0.5 -> 188.892 | AH16: =(AF16-AG16)*$AH$1+S16 -> 6391.768 | AI16: =IF(Q16>18519.27,0.045*18519.27,Q16*0.045) -> 404.78314 | AJ16: =(AI16*0.5)/$AQ$1 -> 7.5816 | AK16: =(AI16*0.4) -> 161.91326 | AL16: 0 | AM16: =Q16*0.003 -> 26.985543 | AN16: =IF(AD16>320,320,AD16) -> 0 | AO16: =AG16-AN16-AJ16 -> 181.3104 | AP16: =AH16-AK16-AL16-AM16-BB16 -> 6202.8692 | AQ16: =AO16+(AP16/$AQ$1) -> 413.67024 | AR16: =BT16 -> 68.41756 | AS16: 0 | AT16: =AR16-AS16 -> 68.41756 | AU16: =AT16*AE16 -> 29.987207 | AV16: =AU16*0.03 -> 0.89961621 | AW16: =(AT16-AU16)*$AQ$1 -> 1025.9021 | AX16: =AW16*0.03 -> 30.777063 | AY16: =AO16-AU16-AV16 -> 150.42358 | AZ16: =AP16-AW16-AX16 -> 5146.19 | BA16: ='Nyaradzo Workings'!K19 -> 316.4547 | BB16: 0 | BL16: =AY16-BI16-BG16-BH16-BD16+BJ16 -> 150.42358 | BM16: =AZ16-BA16-BC16-BE16-BF16+BK16 -> 4829.7353 | BN16: =IF(AQ16<100,0,0) -> 0 | BO16: =IF(AQ16<100,"",IF(AQ16<=300,AQ16*0.2-20,)) -> 0 | BP16: =IF(AQ16<300.01,"",IF(AQ16<=1000,AQ16*0.25-35,)) -> 68.41756 | BQ16: =IF(AQ16<1000.01,"",IF(AQ16<=2000,AQ16*0.3-85,)) | BR16: =IF(AQ16<2000.01,"",IF(AQ16<=3000,AQ16*0.35-185,)) | BS16: =IF(AQ16<3000.01,"",IF(AQ16>3000,AQ16*0.4-335,)) | BT16: =SUM(BN16:BS16) -> 68.41756 | BU16: FBC | BV16: Zvishavane | BW16: 8253690449424 | BX16: FBC | BY16: Zvishavane | BZ16: 4152612451898 | CA16: 23.62 | CB16: 2.5 | CC16: 1 | CE16: =CA16+CB16-CC16-CD16 -> 25.12 | CF16: =M16*8 -> 12.96 | CG16: =CE16*CF16 -> 325.5552 | CH16: =CG16*0.4 -> 130.22208 | CI16: =(CG16-CH16)*$CI$2 -> 5214.4372
A17: AES-E045 | B17: Tinotenda | C17: Nyagura | D17: 44-920391P33 | E17: =E16 -> 45747 | F17: Mimosa | G17: Bricklayer | H17: 4/5 | I17: 6543670C | J17: =AO17/AQ17 -> 0.45319333 | K17: =K16 -> 3/2025 | L17: 208 | M17: 1.8 | N17: 23 | P17: =L17*M17 -> 374.4 | Q17: =P17*$Q$1 -> 9994.6454 | R17: 3 | S17: =P17*0.3*$S$1*0.5 -> 1499.1968 | T17: =N17*M17*8*0.05 -> 16.56 | U17: =O17*M17*0.1 -> 0 | W17: =Y17*M17*2 -> 0 | X17: =Z17*M17*1.5 -> 0 | AA17: =CD17 -> 10 | AB17: =P17*0.075 -> 28.08 | AC17: =M17*8*AA17 -> 144 | AE17: =AO17/AQ17 -> 0.45319333 | AF17: =P17+R17+T17+U17+V17+W17+X17+AB17+AC17+AD17 -> 566.04 | AG17: =AF17*0.5 -> 283.02 | AH17: =(AF17-AG17)*$AH$1+S17 -> 9054.444 | AI17: =IF(Q17>18519.27,0.045*18519.27,Q17*0.045) -> 449.75904 | AJ17: =(AI17*0.5)/$AQ$1 -> 8.424 | AK17: =(AI17*0.4) -> 179.90362 | AL17: 0 | AM17: =Q17*0.003 -> 29.983936 | AN17: =IF(AD17>320,320,AD17) -> 0 | AO17: =AG17-AN17-AJ17 -> 274.596 | AP17: =AH17-AK17-AL17-AM17-BB17 -> 8844.5565 | AQ17: =AO17+(AP17/$AQ$1) -> 605.9136 | AR17: =BT17 -> 116.4784 | AS17: 0 | AT17: =AR17-AS17 -> 116.4784 | AU17: =AT17*AE17 -> 52.787234 | AV17: =AU17*0.03 -> 1.583617 | AW17: =(AT17-AU17)*$AQ$1 -> 1700.2421 | AX17: =AW17*0.03 -> 51.007262 | AY17: =AO17-AU17-AV17 -> 220.22515 | AZ17: =AP17-AW17-AX17 -> 7093.3071 | BA17: 0 | BB17: 0 | BI17: 12.5 | BL17: =AY17-BI17-BG17-BH17-BD17+BJ17 -> 207.72515 | BM17: =AZ17-BA17-BC17-BE17-BF17+BK17 -> 7093.3071 | BN17: =IF(AQ17<100,0,0) -> 0 | BO17: =IF(AQ17<100,"",IF(AQ17<=300,AQ17*0.2-20,)) -> 0 | BP17: =IF(AQ17<300.01,"",IF(AQ17<=1000,AQ17*0.25-35,)) -> 116.4784 | BQ17: =IF(AQ17<1000.01,"",IF(AQ17<=2000,AQ17*0.3-85,)) | BR17: =IF(AQ17<2000.01,"",IF(AQ17<=3000,AQ17*0.35-185,)) | BS17: =IF(AQ17<3000.01,"",IF(AQ17>3000,AQ17*0.4-335,)) | BT17: =SUM(BN17:BS17) -> 116.4784 | BU17: FBC | BV17: Zvishavane | BW17: 3801464598795 | BX17: FBC | BY17: Zvishavane | BZ17: 7726383052711 | CA17: 29.42 | CB17: 2.5 | CD17: 10 | CE17: =CA17+CB17-CC17-CD17 -> 21.92 | CF17: =M17*8 -> 14.4 | CG17: =CE17*CF17 -> 315.648 | CH17: =CG17*0.4 -> 126.2592 | CI17: =(CG17-CH17)*$CI$2 -> 5055.753
A18: AES-E048 | B18: Nomatter | C18: Nhira | D18: 06-593554H27 | E18: =E17 -> 45747 | F18: Mimosa | G18: Team Leader Con | H18: 4/7 | I18: 2191066Z | J18: =AO18/AQ18 -> 0.46467508 | K18: =K17 -> 3/2025 | L18: 208 | M18: 2.8 | N18: 24 | P18: =L18*M18 -> 582.4 | Q18: =P18*$Q$1 -> 15547.226 | R18: 3 | S18: =P18*0.3*$S$1*0.5 -> 2332.0839 | T18: =N18*M18*8*0.05 -> 26.88 | U18: =O18*M18*0.1 -> 0 | W18: =Y18*M18*2 -> 0 | X18: =Z18*M18*1.5 -> 0 | AA18: =CD18 -> 0 | AC18: =M18*8*AA18 -> 0 | AE18: =AO18/AQ18 -> 0.46467508 | AF18: =P18+R18+T18+U18+V18+W18+X18+AB18+AC18+AD18 -> 612.28 | AG18: =AF18*0.5 -> 306.14 | AH18: =(AF18-AG18)*$AH$1+S18 -> 10504.522 | AI18: =IF(Q18>18519.27,0.045*18519.27,Q18*0.045) -> 699.62518 | AJ18: =(AI18*0.5)/$AQ$1 -> 13.104 | AK18: =(AI18*0.4) -> 279.85007 | AL18: =Q18*0.075 -> 1166.042 | AM18: =Q18*0.003 -> 46.641679 | AN18: =IF(AD18>320,320,AD18) -> 0 | AO18: =AG18-AN18-AJ18 -> 293.036 | AP18: =AH18-AK18-AL18-AM18-BB18 -> 9011.9881 | AQ18: =AO18+(AP18/$AQ$1) -> 630.6256 | AR18: =BT18 -> 122.6564 | AS18: 0 | AT18: =AR18-AS18 -> 122.6564 | AU18: =AT18*AE18 -> 56.995372 | AV18: =AU18*0.03 -> 1.7098612 | AW18: =(AT18-AU18)*$AQ$1 -> 1752.8277 | AX18: =AW18*0.03 -> 52.584831 | AY18: =AO18-AU18-AV18 -> 234.33077 | AZ18: =AP18-AW18-AX18 -> 7206.5756 | BA18: 0 | BB18: 0 | BC18: =20*AQ1 -> 533.902 | BI18: 12.5 | BL18: =AY18-BI18-BG18-BH18-BD18+BJ18 -> 221.83077 | BM18: =AZ18-BA18-BC18-BE18-BF18+BK18 -> 6672.6736 | BN18: =IF(AQ18<100,0,0) -> 0 | BO18: =IF(AQ18<100,"",IF(AQ18<=300,AQ18*0.2-20,)) -> 0 | BP18: =IF(AQ18<300.01,"",IF(AQ18<=1000,AQ18*0.25-35,)) -> 122.6564 | BQ18: =IF(AQ18<1000.01,"",IF(AQ18<=2000,AQ18*0.3-85,)) | BR18: =IF(AQ18<2000.01,"",IF(AQ18<=3000,AQ18*0.35-185,)) | BS18: =IF(AQ18<3000.01,"",IF(AQ18>3000,AQ18*0.4-335,)) | BT18: =SUM(BN18:BS18) -> 122.6564 | BU18: FBC | BV18: Zvishavane | BW18: 7152370155220 | BX18: FBC | BY18: Zvishavane | BZ18: 4922282656442 | CA18: 29.13 | CB18: 2.5 | CC18: 1 | CE18: =CA18+CB18-CC18-CD18 -> 30.63 | CF18: =M18*8 -> 22.4 | CG18: =CE18*CF18 -> 686.112 | CH18: =CG18*0.4 -> 274.4448 | CI18: =(CG18-CH18)*$CI$2 -> 10989.497
A19: AES-E043 | B19: Zvikomborero | C19: Mpofu | D19: 05-792094G53 | E19: =E18 -> 45747 | F19: Mimosa | G19: Service Assitant | H19: 4/3 | I19: 9626108H | J19: =AO19/AQ19 -> 0.47387638 | K19: =K18 -> 3/2025 | L19: 208 | M19: 1.62 | N19: 25 | P19: =L19*M19 -> 336.96 | Q19: =P19*$Q$1 -> 8995.1809 | S19: =P19*0.3*$S$1*0.5 -> 1349.2771 | T19: =N19*M19*8*0.05 -> 16.2 | U19: =O19*M19*0.1 -> 0 | W19: =Y19*M19*2 -> 0 | X19: =Z19*M19*1.5 -> 0 | AA19: =CD19 -> 10 | AC19: =M19*8*AA19 -> 129.6 | AE19: =AO19/AQ19 -> 0.47387638 | AF19: =P19+R19+T19+U19+V19+W19+X19+AB19+AC19+AD19 -> 482.76 | AG19: =AF19*0.5 -> 241.38 | AH19: =(AF19-AG19)*$AH$1+S19 -> 7792.9404 | AI19: =IF(Q19>18519.27,0.045*18519.27,Q19*0.045) -> 404.78314 | AJ19: =(AI19*0.5)/$AQ$1 -> 7.5816 | AK19: =(AI19*0.4) -> 161.91326 | AL19: =Q19*0.075 -> 674.63857 | AM19: =Q19*0.003 -> 26.985543 | AN19: =IF(AD19>320,320,AD19) -> 0 | AO19: =AG19-AN19-AJ19 -> 233.7984 | AP19: =AH19-AK19-AL19-AM19-BB19 -> 6929.403 | AQ19: =AO19+(AP19/$AQ$1) -> 493.37424 | AR19: =BT19 -> 88.34356 | AS19: 0 | AT19: =AR19-AS19 -> 88.34356 | AU19: =AT19*AE19 -> 41.863927 | AV19: =AU19*0.03 -> 1.2559178 | AW19: =(AT19-AU19)*$AQ$1 -> 1240.7785 | AX19: =AW19*0.03 -> 37.223354 | AY19: =AO19-AU19-AV19 -> 190.67856 | AZ19: =AP19-AW19-AX19 -> 5651.4012 | BA19: ='Nyaradzo Workings'!K20 -> 472.7647 | BB19: 0 | BL19: =AY19-BI19-BG19-BH19-BD19+BJ19 -> 190.67856 | BM19: =AZ19-BA19-BC19-BE19-BF19+BK19 -> 5178.6365 | BN19: =IF(AQ19<100,0,0) -> 0 | BO19: =IF(AQ19<100,"",IF(AQ19<=300,AQ19*0.2-20,)) -> 0 | BP19: =IF(AQ19<300.01,"",IF(AQ19<=1000,AQ19*0.25-35,)) -> 88.34356 | BQ19: =IF(AQ19<1000.01,"",IF(AQ19<=2000,AQ19*0.3-85,)) | BR19: =IF(AQ19<2000.01,"",IF(AQ19<=3000,AQ19*0.35-185,)) | BS19: =IF(AQ19<3000.01,"",IF(AQ19>3000,AQ19*0.4-335,)) | BT19: =SUM(BN19:BS19) -> 88.34356 | BU19: FBC | BV19: Zvishavane | BW19: 5901967559084 | BX19: FBC | BY19: Zvishavane | BZ19: 2223483079689 | CA19: 17.29 | CB19: 2.5 | CD19: 10 | CE19: =CA19+CB19-CC19-CD19 -> 9.79 | CF19: =M19*8 -> 12.96 | CG19: =CE19*CF19 -> 126.8784 | CH19: =CG19*0.4 -> 50.75136 | CI19: =(CG19-CH19)*$CI$2 -> 2032.2189
A20: AES-E044 | B20: Anesu | C20: Chidzambwa | D20: 37-468203X67 | E20: =E19 -> 45747 | F20: Mimosa | G20: Team Leader Tran | H20: 4/7 | I20: 4694634A | J20: =AO20/AQ20 -> 0.48144555 | K20: =K19 -> 3/2025 | L20: 136 | M20: 2.8 | N20: 15 | O20: 116 | P20: =L20*M20 -> 380.8 | Q20: =P20*$Q$1 -> 10165.494 | S20: =P20*0.3*$S$1*0.5 -> 1524.8241 | T20: =N20*M20*8*0.05 -> 16.8 | U20: =O20*M20*0.1 -> 32.48 | W20: =Y20*M20*2 -> 0 | X20: =Z20*M20*1.5 -> 0 | AA20: =CD20 -> 15.31 | AC20: =M20*8*AA20 -> 342.944 | AE20: =AO20/AQ20 -> 0.48144555 | AF20: =P20+R20+T20+U20+V20+W20+X20+AB20+AC20+AD20 -> 773.024 | AG20: =AF20*0.5 -> 386.512 | AH20: =(AF20-AG20)*$AH$1+S20 -> 11842.801 | AI20: =IF(Q20>18519.27,0.045*18519.27,Q20*0.045) -> 457.44723 | AJ20: =(AI20*0.5)/$AQ$1 -> 8.568 | AK20: =(AI20*0.4) -> 182.97889 | AL20: =Q20*0.075 -> 762.41206 | AM20: =Q20*0.003 -> 30.496482 | AN20: =IF(AD20>320,320,AD20) -> 0 | AO20: =AG20-AN20-AJ20 -> 377.944 | AP20: =AH20-AK20-AL20-AM20-BB20 -> 10866.913 | AQ20: =AO20+(AP20/$AQ$1) -> 785.0192 | AR20: =BT20 -> 161.2548 | AS20: 0 | AT20: =AR20-AS20 -> 161.2548 | AU20: =AT20*AE20 -> 77.635406 | AV20: =AU20*0.03 -> 2.3290622 | AW20: =(AT20-AU20)*$AQ$1 -> 2232.2281 | AX20: =AW20*0.03 -> 66.966843 | AY20: =AO20-AU20-AV20 -> 297.97953 | AZ20: =AP20-AW20-AX20 -> 8567.7182 | BA20: ='Nyaradzo Workings'!K21 -> 553.5847 | BB20: 0 | BL20: =AY20-BI20-BG20-BH20-BD20+BJ20 -> 297.97953 | BM20: =AZ20-BA20-BC20-BE20-BF20+BK20 -> 8014.1335 | BN20: =IF(AQ20<100,0,0) -> 0 | BO20: =IF(AQ20<100,"",IF(AQ20<=300,AQ20*0.2-20,)) -> 0 | BP20: =IF(AQ20<300.01,"",IF(AQ20<=1000,AQ20*0.25-35,)) -> 161.2548 | BQ20: =IF(AQ20<1000.01,"",IF(AQ20<=2000,AQ20*0.3-85,)) | BR20: =IF(AQ20<2000.01,"",IF(AQ20<=3000,AQ20*0.35-185,)) | BS20: =IF(AQ20<3000.01,"",IF(AQ20>3000,AQ20*0.4-335,)) | BT20: =SUM(BN20:BS20) -> 161.2548 | BU20: FBC | BV20: Zvishavane | BW20: 6826278682407 | BX20: FBC | BY20: Zvishavane | BZ20: 1489365297273 | CA20: 12.81 | CB20: 2.5 | CD20: 15.31 | CE20: =CA20+CB20-CC20-CD20 -> 0 | CF20: =M20*8 -> 22.4 | CG20: =CE20*CF20 -> 0 | CH20: =CG20*0.4 -> 0 | CI20: =(CG20-CH20)*$CI$2 -> 0
A21: AES-E047 | B21: Innocent | C21: Chihota | D21: 16-373903F76 | E21: =E20 -> 45747 | F21: Mimosa | G21: Team Leader | H21: 4/7 | I21: 4769795C | J21: =AO21/AQ21 -> 0.46333151 | K21: =K20 -> 3/2025 | L21: 208 | M21: 2.8 | N21: 25 | O21: 20 | P21: =L21*M21 -> 582.4 | Q21: =P21*$Q$1 -> 15547.226 | S21: =P21*0.3*$S$1*0.5 -> 2332.0839 | T21: =N21*M21*8*0.05 -> 28 | U21: =O21*M21*0.1 -> 5.6 | V21: =145.42 -> 145.42 | W21: =Y21*M21*2 -> 0 | X21: =Z21*M21*1.5 -> 0 | AA21: =CD21 -> 15 | AB21: =P21*0.075 -> 43.68 | AC21: =M21*8*AA21 -> 336 | AE21: =AO21/AQ21 -> 0.46333151 | AF21: =P21+R21+T21+U21+V21+W21+X21+AB21+AC21+AD21 -> 1141.1 | AG21: =AF21*0.5 -> 570.55 | AH21: =(AF21-AG21)*$AH$1+S21 -> 17562.973 | AI21: =IF(Q21>18519.27,0.045*18519.27,Q21*0.045) -> 699.62518 | AJ21: =(AI21*0.5)/$AQ$1 -> 13.104 | AK21: =(AI21*0.4) -> 279.85007 | AL21: 0 | AM21: =Q21*0.003 -> 46.641679 | AN21: =IF(AD21>320,320,AD21) -> 0 | AO21: =AG21-AN21-AJ21 -> 557.446 | AP21: =AH21-AK21-AL21-AM21-BB21 -> 17236.481 | AQ21: =AO21+(AP21/$AQ$1) -> 1203.1256 | AR21: =BT21 -> 275.93768 | AS21: 0 | AT21: =AR21-AS21 -> 275.93768 | AU21: =AT21*AE21 -> 127.85062 | AV21: =AU21*0.03 -> 3.8355187 | AW21: =(AT21-AU21)*$AQ$1 -> 3953.1988 | AX21: =AW21*0.03 -> 118.59596 | AY21: =AO21-AU21-AV21 -> 425.75986 | AZ21: =AP21-AW21-AX21 -> 13164.687 | BA21: ='Nyaradzo Workings'!K22 -> 316.4547 | BI21: 12.5 | BL21: =AY21-BI21-BG21-BH21-BD21+BJ21 -> 413.25986 | BM21: =AZ21-BA21-BC21-BE21-BF21+BK21 -> 12848.232 | BN21: =IF(AQ21<100,0,0) -> 0 | BO21: =IF(AQ21<100,"",IF(AQ21<=300,AQ21*0.2-20,)) -> 0 | BP21: =IF(AQ21<300.01,"",IF(AQ21<=1000,AQ21*0.25-35,)) -> 0 | BQ21: =IF(AQ21<1000.01,"",IF(AQ21<=2000,AQ21*0.3-85,)) -> 275.93768 | BR21: =IF(AQ21<2000.01,"",IF(AQ21<=3000,AQ21*0.35-185,)) | BS21: =IF(AQ21<3000.01,"",IF(AQ21>3000,AQ21*0.4-335,)) | BT21: =SUM(BN21:BS21) -> 275.93768 | BU21: FBC | BV21: Zvishavane | BW21: 1671155067525 | BX21: FBC | BY21: Zvishavane | BZ21: 7079245160972 | CA21: 21.63 | CB21: 2.5 | CD21: 15 | CE21: =CA21+CB21-CC21-CD21 -> 9.13 | CF21: =M21*8 -> 22.4 | CG21: =CE21*CF21 -> 204.512 | CH21: =CG21*0.4 -> 81.8048 | CI21: =(CG21-CH21)*$CI$2 -> 3275.681
A22: AES-E038 | B22: Munyaradzi | C22: Zhou | D22: 42-557592W67 | E22: =E21 -> 45747 | F22: Mimosa | G22: Service Assitant | H22: 4/3 | I22: 8935169P | J22: =AO22/AQ22 -> 0.43839344 | K22: =K21 -> 3/2025 | L22: 208 | M22: 1.62 | N22: 25 | P22: =L22*M22 -> 336.96 | Q22: =P22*$Q$1 -> 8995.1809 | S22: =P22*0.3*$S$1*0.5 -> 1349.2771 | T22: =N22*M22*8*0.05 -> 16.2 | U22: =O22*M22*0.1 -> 0 | W22: =Y22*M22*2 -> 0 | X22: =Z22*M22*1.5 -> 0 | AA22: =CD22 -> 0 | AB22: =P22*0.075 -> 25.272 | AC22: =M22*8*AA22 -> 0 | AE22: =AO22/AQ22 -> 0.43839344 | AF22: =P22+R22+T22+U22+V22+W22+X22+AB22+AC22+AD22 -> 378.432 | AG22: =AF22*0.5 -> 189.216 | AH22: =(AF22-AG22)*$AH$1+S22 -> 6400.4172 | AI22: =IF(Q22>18519.27,0.045*18519.27,Q22*0.045) -> 404.78314 | AJ22: =(AI22*0.5)/$AQ$1 -> 7.5816 | AK22: =(AI22*0.4) -> 161.91326 | AL22: 0 | AM22: =Q22*0.003 -> 26.985543 | AN22: =IF(AD22>320,320,AD22) -> 0 | AO22: =AG22-AN22-AJ22 -> 181.6344 | AP22: =AH22-AK22-AL22-AM22-BB22 -> 6211.5184 | AQ22: =AO22+(AP22/$AQ$1) -> 414.31824 | AR22: =BT22 -> 68.57956 | AS22: 0 | AT22: =AR22-AS22 -> 68.57956 | AU22: =AT22*AE22 -> 30.064829 | AV22: =AU22*0.03 -> 0.90194488 | AW22: =(AT22-AU22)*$AQ$1 -> 1028.1546 | AX22: =AW22*0.03 -> 30.844637 | AY22: =AO22-AU22-AV22 -> 150.66763 | AZ22: =AP22-AW22-AX22 -> 5152.5192 | BA22: ='Nyaradzo Workings'!K23 -> 577.7647 | BI22: 12.5 | BL22: =AY22-BI22-BG22-BH22-BD22+BJ22 -> 138.16763 | BM22: =AZ22-BA22-BC22-BE22-BF22+BK22 -> 4574.7545 | BN22: =IF(AQ22<100,0,0) -> 0 | BO22: =IF(AQ22<100,"",IF(AQ22<=300,AQ22*0.2-20,)) -> 0 | BP22: =IF(AQ22<300.01,"",IF(AQ22<=1000,AQ22*0.25-35,)) -> 68.57956 | BQ22: =IF(AQ22<1000.01,"",IF(AQ22<=2000,AQ22*0.3-85,)) | BR22: =IF(AQ22<2000.01,"",IF(AQ22<=3000,AQ22*0.35-185,)) | BS22: =IF(AQ22<3000.01,"",IF(AQ22>3000,AQ22*0.4-335,)) | BT22: =SUM(BN22:BS22) -> 68.57956 | BU22: FBC | BV22: Zvishavane | BW22: 7773660120665 | BX22: FBC | BY22: Zvishavane | BZ22: 5480467271853 | CA22: 19.03 | CB22: 2.5 | CE22: =CA22+CB22-CC22-CD22 -> 21.53 | CF22: =M22*8 -> 12.96 | CG22: =CE22*CF22 -> 279.0288 | CH22: =CG22*0.4 -> 111.61152 | CI22: =(CG22-CH22)*$CI$2 -> 4469.221
A23: AES-E040 | B23: Takudzwa | C23: Nyandoro | D23: 07-843215P02 | E23: =E22 -> 45747 | F23: Mimosa | G23: Service Assitant | H23: 4/3 | I23: 4194548D | J23: =AO23/AQ23 -> 0.43839344 | K23: =K22 -> 3/2025 | L23: 208 | M23: 1.62 | N23: 25 | P23: =L23*M23 -> 336.96 | Q23: =P23*$Q$1 -> 8995.1809 | S23: =P23*0.3*$S$1*0.5 -> 1349.2771 | T23: =N23*M23*8*0.05 -> 16.2 | U23: =O23*M23*0.1 -> 0 | W23: =Y23*M23*2 -> 0 | X23: =Z23*M23*1.5 -> 0 | AA23: =CD23 -> 0 | AB23: =P23*0.075 -> 25.272 | AC23: =M23*8*AA23 -> 0 | AE23: =AO23/AQ23 -> 0.43839344 | AF23: =P23+R23+T23+U23+V23+W23+X23+AB23+AC23+AD23 -> 378.432 | AG23: =AF23*0.5 -> 189.216 | AH23: =(AF23-AG23)*$AH$1+S23 -> 6400.4172 | AI23: =IF(Q23>18519.27,0.045*18519.27,Q23*0.045) -> 404.78314 | AJ23: =(AI23*0.5)/$AQ$1 -> 7.5816 | AK23: =(AI23*0.4) -> 161.91326 | AL23: 0 | AM23: =Q23*0.003 -> 26.985543 | AN23: =IF(AD23>320,320,AD23) -> 0 | AO23: =AG23-AN23-AJ23 -> 181.6344 | AP23: =AH23-AK23-AL23-AM23-BB23 -> 6211.5184 | AQ23: =AO23+(AP23/$AQ$1) -> 414.31824 | AR23: =BT23 -> 68.57956 | AS23: 0 | AT23: =AR23-AS23 -> 68.57956 | AU23: =AT23*AE23 -> 30.064829 | AV23: =AU23*0.03 -> 0.90194488 | AW23: =(AT23-AU23)*$AQ$1 -> 1028.1546 | AX23: =AW23*0.03 -> 30.844637 | AY23: =AO23-AU23-AV23 -> 150.66763 | AZ23: =AP23-AW23-AX23 -> 5152.5192 | BA23: 0 | BB23: 0 | BL23: =AY23-BI23-BG23-BH23-BD23+BJ23 -> 150.66763 | BM23: =AZ23-BA23-BC23-BE23-BF23+BK23 -> 5152.5192 | BN23: =IF(AQ23<100,0,0) -> 0 | BO23: =IF(AQ23<100,"",IF(AQ23<=300,AQ23*0.2-20,)) -> 0 | BP23: =IF(AQ23<300.01,"",IF(AQ23<=1000,AQ23*0.25-35,)) -> 68.57956 | BQ23: =IF(AQ23<1000.01,"",IF(AQ23<=2000,AQ23*0.3-85,)) | BR23: =IF(AQ23<2000.01,"",IF(AQ23<=3000,AQ23*0.35-185,)) | BS23: =IF(AQ23<3000.01,"",IF(AQ23>3000,AQ23*0.4-335,)) | BT23: =SUM(BN23:BS23) -> 68.57956 | BU23: FBC | BV23: Zvishavane | BW23: 7404642497786 | BX23: FBC | BY23: Zvishavane | BZ23: 2230213054883 | CA23: 18.44 | CB23: 2.5 | CE23: =CA23+CB23-CC23-CD23 -> 20.94 | CF23: =M23*8 -> 12.96 | CG23: =CE23*CF23 -> 271.3824 | CH23: =CG23*0.4 -> 108.55296 | CI23: =(CG23-CH23)*$CI$2 -> 4346.7482
A24: AES-E039 | B24: Chiedza | C24: Mucheki | D24: 44-753425L17 | E24: =E23 -> 45747 | F24: Mimosa | G24: Service Assitant | H24: 4/3 | I24: 2626229Y | J24: =AO24/AQ24 -> 0.44210588 | K24: =K23 -> 3/2025 | L24: 208 | M24: 1.62 | N24: 26 | P24: =L24*M24 -> 336.96 | Q24: =P24*$Q$1 -> 8995.1809 | S24: =P24*0.3*$S$1*0.5 -> 1349.2771 | T24: =N24*M24*8*0.05 -> 16.848 | U24: =O24*M24*0.1 -> 0 | W24: =Y24*M24*2 -> 25.92 | X24: =Z24*M24*1.5 -> 0 | Y24: 8 | AA24: =CD24 -> 0 | AB24: =P24*0.075 -> 25.272 | AC24: =M24*8*AA24 -> 0 | AE24: =AO24/AQ24 -> 0.44210588 | AF24: =P24+R24+T24+U24+V24+W24+X24+AB24+AC24+AD24 -> 405 | AG24: =AF24*0.5 -> 202.5 | AH24: =(AF24-AG24)*$AH$1+S24 -> 6755.0349 | AI24: =IF(Q24>18519.27,0.045*18519.27,Q24*0.045) -> 404.78314 | AJ24: =(AI24*0.5)/$AQ$1 -> 7.5816 | AK24: =(AI24*0.4) -> 161.91326 | AL24: 0 | AM24: =Q24*0.003 -> 26.985543 | AN24: =IF(AD24>320,320,AD24) -> 0 | AO24: =AG24-AN24-AJ24 -> 194.9184 | AP24: =AH24-AK24-AL24-AM24-BB24 -> 6566.1361 | AQ24: =AO24+(AP24/$AQ$1) -> 440.88624 | AR24: =BT24 -> 75.22156 | AS24: 0 | AT24: =AR24-AS24 -> 75.22156 | AU24: =AT24*AE24 -> 33.255894 | AV24: =AU24*0.03 -> 0.99767682 | AW24: =(AT24-AU24)*$AQ$1 -> 1120.2776 | AX24: =AW24*0.03 -> 33.608329 | AY24: =AO24-AU24-AV24 -> 160.66483 | AZ24: =AP24-AW24-AX24 -> 5412.2501 | BA24: ='Nyaradzo Workings'!K24 -> 734.0747 | BB24: 0 | BI24: 12.5 | BL24: =AY24-BI24-BG24-BH24-BD24+BJ24 -> 148.16483 | BM24: =AZ24-BA24-BC24-BE24-BF24+BK24 -> 4678.1754 | BN24: =IF(AQ24<100,0,0) -> 0 | BO24: =IF(AQ24<100,"",IF(AQ24<=300,AQ24*0.2-20,)) -> 0 | BP24: =IF(AQ24<300.01,"",IF(AQ24<=1000,AQ24*0.25-35,)) -> 75.22156 | BQ24: =IF(AQ24<1000.01,"",IF(AQ24<=2000,AQ24*0.3-85,)) | BR24: =IF(AQ24<2000.01,"",IF(AQ24<=3000,AQ24*0.35-185,)) | BS24: =IF(AQ24<3000.01,"",IF(AQ24>3000,AQ24*0.4-335,)) | BT24: =SUM(BN24:BS24) -> 75.22156 | BU24: FBC | BV24: Zvishavane | BW24: 9921936948112 | BX24: FBC | BY24: Zvishavane | BZ24: 6739830341653 | CA24: 15.04 | CB24: 2.5 | CE24: =CA24+CB24-CC24-CD24 -> 17.54 | CF24: =M24*8 -> 12.96 | CG24: =CE24*CF24 -> 227.3184 | CH24: =CG24*0.4 -> 90.92736 | CI24: =(CG24-CH24)*$CI$2 -> 3640.9725
A25: AES-E010 | B25: Farai | C25: Dhliwayo | D25: 53-831076K72 | E25: =E24 -> 45747 | F25: Mimosa | G25: Service Assitant | H25: 4/3 | I25: 6672134A | J25: =AO25/AQ25 -> 0.4419352 | K25: =K24 -> 3/2025 | L25: 208 | M25: 1.62 | N25: 24 | P25: =L25*M25 -> 336.96 | Q25: =P25*$Q$1 -> 8995.1809 | S25: =P25*0.3*$S$1*0.5 -> 1349.2771 | T25: =N25*M25*8*0.05 -> 15.552 | U25: =O25*M25*0.1 -> 0 | W25: =Y25*M25*2 -> 25.92 | X25: =Z25*M25*1.5 -> 0 | Y25: 8 | AA25: =CD25 -> 0 | AB25: =P25*0.075 -> 25.272 | AC25: =M25*8*AA25 -> 0 | AE25: =AO25/AQ25 -> 0.4419352 | AF25: =P25+R25+T25+U25+V25+W25+X25+AB25+AC25+AD25 -> 403.704 | AG25: =AF25*0.5 -> 201.852 | AH25: =(AF25-AG25)*$AH$1+S25 -> 6737.7365 | AI25: =IF(Q25>18519.27,0.045*18519.27,Q25*0.045) -> 404.78314 | AJ25: =(AI25*0.5)/$AQ$1 -> 7.5816 | AK25: =(AI25*0.4) -> 161.91326 | AL25: 0 | AM25: =Q25*0.003 -> 26.985543 | AN25: =IF(AD25>320,320,AD25) -> 0 | AO25: =AG25-AN25-AJ25 -> 194.2704 | AP25: =AH25-AK25-AL25-AM25-BB25 -> 6548.8377 | AQ25: =AO25+(AP25/$AQ$1) -> 439.59024 | AR25: =BT25 -> 74.89756 | AS25: 0 | AT25: =AR25-AS25 -> 74.89756 | AU25: =AT25*AE25 -> 33.099868 | AV25: =AU25*0.03 -> 0.99299604 | AW25: =(AT25-AU25)*$AQ$1 -> 1115.7936 | AX25: =AW25*0.03 -> 33.473807 | AY25: =AO25-AU25-AV25 -> 160.17754 | AZ25: =AP25-AW25-AX25 -> 5399.5703 | BA25: ='Nyaradzo Workings'!K25 -> 316.4547 | BB25: 0 | BL25: =AY25-BI25-BG25-BH25-BD25+BJ25 -> 160.17754 | BM25: =AZ25-BA25-BC25-BE25-BF25+BK25 -> 5083.1156 | BN25: =IF(AQ25<100,0,0) -> 0 | BO25: =IF(AQ25<100,"",IF(AQ25<=300,AQ25*0.2-20,)) -> 0 | BP25: =IF(AQ25<300.01,"",IF(AQ25<=1000,AQ25*0.25-35,)) -> 74.89756 | BQ25: =IF(AQ25<1000.01,"",IF(AQ25<=2000,AQ25*0.3-85,)) | BR25: =IF(AQ25<2000.01,"",IF(AQ25<=3000,AQ25*0.35-185,)) | BS25: =IF(AQ25<3000.01,"",IF(AQ25>3000,AQ25*0.4-335,)) | BT25: =SUM(BN25:BS25) -> 74.89756 | BU25: FBC | BV25: Zvishavane | BW25: 4372096024310 | BX25: FBC | BY25: Zvishavane | BZ25: 7669828074599 | CA25: 23.56 | CB25: 2.5 | CE25: =CA25+CB25-CC25-CD25 -> 26.06 | CF25: =M25*8 -> 12.96 | CG25: =CE25*CF25 -> 337.7376 | CH25: =CG25*0.4 -> 135.09504 | CI25: =(CG25-CH25)*$CI$2 -> 5409.5634
A26: AES-E011 | B26: Kundai | C26: Chataika | D26: 24-745414V40 | E26: =E25 -> 45747 | F26: Mimosa | G26: Service Assitant | H26: 4/3 | I26: 2833230H | J26: =AO26/AQ26 -> 0.45953276 | K26: =K25 -> 3/2025 | L26: 208 | M26: 1.62 | N26: 25 | O26: 136 | P26: =L26*M26 -> 336.96 | Q26: =P26*$Q$1 -> 8995.1809 | S26: =P26*0.3*$S$1*0.5 -> 1349.2771 | T26: =N26*M26*8*0.05 -> 16.2 | U26: =O26*M26*0.1 -> 22.032 | W26: =Y26*M26*2 -> 0 | X26: =Z26*M26*1.5 -> 0 | AA26: =CD26 -> 15 | AB26: =P26*0.075 -> 25.272 | AC26: =M26*8*AA26 -> 194.4 | AE26: =AO26/AQ26 -> 0.45953276 | AF26: =P26+R26+T26+U26+V26+W26+X26+AB26+AC26+AD26 -> 594.864 | AG26: =AF26*0.5 -> 297.432 | AH26: =(AF26-AG26)*$AH$1+S26 -> 9289.2541 | AI26: =IF(Q26>18519.27,0.045*18519.27,Q26*0.045) -> 404.78314 | AJ26: =(AI26*0.5)/$AQ$1 -> 7.5816 | AK26: =(AI26*0.4) -> 161.91326 | AL26: 0 | AM26: =Q26*0.003 -> 26.985543 | AN26: =IF(AD26>320,320,AD26) -> 0 | AO26: =AG26-AN26-AJ26 -> 289.8504 | AP26: =AH26-AK26-AL26-AM26-BB26 -> 9100.3553 | AQ26: =AO26+(AP26/$AQ$1) -> 630.75024 | AR26: =BT26 -> 122.68756 | AS26: 0 | AT26: =AR26-AS26 -> 122.68756 | AU26: =AT26*AE26 -> 56.378953 | AV26: =AU26*0.03 -> 1.6913686 | AW26: =(AT26-AU26)*$AQ$1 -> 1770.1149 | AX26: =AW26*0.03 -> 53.103447 | AY26: =AO26-AU26-AV26 -> 231.78008 | AZ26: =AP26-AW26-AX26 -> 7277.137 | BA26: ='Nyaradzo Workings'!K26 -> 316.4547 | BB26: 0 | BL26: =AY26-BI26-BG26-BH26-BD26+BJ26 -> 231.78008 | BM26: =AZ26-BA26-BC26-BE26-BF26+BK26 -> 6960.6823 | BN26: =IF(AQ26<100,0,0) -> 0 | BO26: =IF(AQ26<100,"",IF(AQ26<=300,AQ26*0.2-20,)) -> 0 | BP26: =IF(AQ26<300.01,"",IF(AQ26<=1000,AQ26*0.25-35,)) -> 122.68756 | BQ26: =IF(AQ26<1000.01,"",IF(AQ26<=2000,AQ26*0.3-85,)) | BR26: =IF(AQ26<2000.01,"",IF(AQ26<=3000,AQ26*0.35-185,)) | BS26: =IF(AQ26<3000.01,"",IF(AQ26>3000,AQ26*0.4-335,)) | BT26: =SUM(BN26:BS26) -> 122.68756 | BU26: FBC | BV26: Zvishavane | BW26: 1007875789648 | BX26: FBC | BY26: Zvishavane | BZ26: 6047891705783 | CA26: 17.11 | CB26: 2.5 | CD26: 15 | CE26: =CA26+CB26-CC26-CD26 -> 4.61 | CF26: =M26*8 -> 12.96 | CG26: =CE26*CF26 -> 59.7456 | CH26: =CG26*0.4 -> 23.89824 | CI26: =(CG26-CH26)*$CI$2 -> 956.94886
A27: AES-E014 | B27: Mufaro | C27: Nemukuyu | D27: 28-550770V79 | E27: =E26 -> 45747 | F27: Mimosa | G27: G/ Machine Op | H27: 4/4 | I27: 2642635B | J27: =AO27/AQ27 -> 0.43829694 | K27: =K26 -> 3/2025 | L27: 208 | M27: 1.76 | N27: 24 | P27: =L27*M27 -> 366.08 | Q27: =P27*$Q$1 -> 9772.5422 | S27: =P27*0.3*$S$1*0.5 -> 1465.8813 | T27: =N27*M27*8*0.05 -> 16.896 | U27: =O27*M27*0.1 -> 0 | W27: =Y27*M27*2 -> 0 | X27: =Z27*M27*1.5 -> 0 | AA27: =CD27 -> 0 | AB27: =P27*0.075 -> 27.456 | AC27: =M27*8*AA27 -> 0 | AE27: =AO27/AQ27 -> 0.43829694 | AF27: =P27+R27+T27+U27+V27+W27+X27+AB27+AC27+AD27 -> 410.432 | AG27: =AF27*0.5 -> 205.216 | AH27: =(AF27-AG27)*$AH$1+S27 -> 6944.143 | AI27: =IF(Q27>18519.27,0.045*18519.27,Q27*0.045) -> 439.7644 | AJ27: =(AI27*0.5)/$AQ$1 -> 8.2368 | AK27: =(AI27*0.4) -> 175.90576 | AL27: 0 | AM27: =Q27*0.003 -> 29.317627 | AN27: =IF(AD27>320,320,AD27) -> 0 | AO27: =AG27-AN27-AJ27 -> 196.9792 | AP27: =AH27-AK27-AL27-AM27-BB27 -> 6738.9196 | AQ27: =AO27+(AP27/$AQ$1) -> 449.41952 | AR27: =BT27 -> 77.35488 | AS27: 0 | AT27: =AR27-AS27 -> 77.35488 | AU27: =AT27*AE27 -> 33.904407 | AV27: =AU27*0.03 -> 1.0171322 | AW27: =(AT27-AU27)*$AQ$1 -> 1159.9147 | AX27: =AW27*0.03 -> 34.797442 | AY27: =AO27-AU27-AV27 -> 162.05766 | AZ27: =AP27-AW27-AX27 -> 5544.2074 | BA27: 0 | BB27: 0 | BI27: 12.5 | BL27: =AY27-BI27-BG27-BH27-BD27+BJ27 -> 149.55766 | BM27: =AZ27-BA27-BC27-BE27-BF27+BK27 -> 5544.2074 | BN27: =IF(AQ27<100,0,0) -> 0 | BO27: =IF(AQ27<100,"",IF(AQ27<=300,AQ27*0.2-20,)) -> 0 | BP27: =IF(AQ27<300.01,"",IF(AQ27<=1000,AQ27*0.25-35,)) -> 77.35488 | BQ27: =IF(AQ27<1000.01,"",IF(AQ27<=2000,AQ27*0.3-85,)) | BR27: =IF(AQ27<2000.01,"",IF(AQ27<=3000,AQ27*0.35-185,)) | BS27: =IF(AQ27<3000.01,"",IF(AQ27>3000,AQ27*0.4-335,)) | BT27: =SUM(BN27:BS27) -> 77.35488 | BU27: FBC | BV27: Zvishavane | BW27: 6667873802666 | BX27: FBC | BY27: Zvishavane | BZ27: 8771592947529 | CA27: 0.5 | CB27: 2.5 | CE27: =CA27+CB27-CC27-CD27 -> 3 | CF27: =M27*8 -> 14.08 | CG27: =CE27*CF27 -> 42.24 | CH27: =CG27*0.4 -> 16.896 | CI27: =(CG27-CH27)*$CI$2 -> 676.56061
A28: AES-E019 | B28: Rufaro | C28: Mashingaidze | D28: 58-808446G67 | E28: =E27 -> 45747 | F28: Mimosa | G28: Service Assitant | H28: 4/3 | I28: 1247595C | J28: =AO28/AQ28 -> 0.45489936 | K28: =K27 -> 3/2025 | L28: 208 | M28: 1.62 | N28: 25 | O28: 136 | P28: =L28*M28 -> 336.96 | Q28: =P28*$Q$1 -> 8995.1809 | S28: =P28*0.3*$S$1*0.5 -> 1349.2771 | T28: =N28*M28*8*0.05 -> 16.2 | U28: =O28*M28*0.1 -> 22.032 | W28: =Y28*M28*2 -> 0 | X28: =Z28*M28*1.5 -> 0 | AA28: =CD28 -> 10 | AB28: =P28*0.075 -> 25.272 | AC28: =M28*8*AA28 -> 129.6 | AE28: =AO28/AQ28 -> 0.45489936 | AF28: =P28+R28+T28+U28+V28+W28+X28+AB28+AC28+AD28 -> 530.064 | AG28: =AF28*0.5 -> 265.032 | AH28: =(AF28-AG28)*$AH$1+S28 -> 8424.3329 | AI28: =IF(Q28>18519.27,0.045*18519.27,Q28*0.045) -> 404.78314 | AJ28: =(AI28*0.5)/$AQ$1 -> 7.5816 | AK28: =(AI28*0.4) -> 161.91326 | AL28: 0 | AM28: =Q28*0.003 -> 26.985543 | AN28: =IF(AD28>320,320,AD28) -> 0 | AO28: =AG28-AN28-AJ28 -> 257.4504 | AP28: =AH28-AK28-AL28-AM28-BB28 -> 8235.4341 | AQ28: =AO28+(AP28/$AQ$1) -> 565.95024 | AR28: =BT28 -> 106.48756 | AS28: 0 | AT28: =AR28-AS28 -> 106.48756 | AU28: =AT28*AE28 -> 48.441123 | AV28: =AU28*0.03 -> 1.4532337 | AW28: =(AT28-AU28)*$AQ$1 -> 1549.5555 | AX28: =AW28*0.03 -> 46.486664 | AY28: =AO28-AU28-AV28 -> 207.55604 | AZ28: =AP28-AW28-AX28 -> 6639.392 | BA28: ='Nyaradzo Workings'!K27 -> 316.4547 | BB28: 0 | BL28: =AY28-BI28-BG28-BH28-BD28+BJ28 -> 207.55604 | BM28: =AZ28-BA28-BC28-BE28-BF28+BK28 -> 6322.9373 | BN28: =IF(AQ28<100,0,0) -> 0 | BO28: =IF(AQ28<100,"",IF(AQ28<=300,AQ28*0.2-20,)) -> 0 | BP28: =IF(AQ28<300.01,"",IF(AQ28<=1000,AQ28*0.25-35,)) -> 106.48756 | BQ28: =IF(AQ28<1000.01,"",IF(AQ28<=2000,AQ28*0.3-85,)) | BR28: =IF(AQ28<2000.01,"",IF(AQ28<=3000,AQ28*0.35-185,)) | BS28: =IF(AQ28<3000.01,"",IF(AQ28>3000,AQ28*0.4-335,)) | BT28: =SUM(BN28:BS28) -> 106.48756 | BU28: FBC | BV28: Zvishavane | BW28: 5991116192008 | BX28: FBC | BY28: Zvishavane | BZ28: 2642117129691 | CA28: 11.84 | CB28: 2.5 | CD28: 10 | CE28: =CA28+CB28-CC28-CD28 -> 4.34 | CF28: =M28*8 -> 12.96 | CG28: =CE28*CF28 -> 56.2464 | CH28: =CG28*0.4 -> 22.49856 | CI28: =(CG28-CH28)*$CI$2 -> 900.90196
A29: AES-E017 | B29: Ropafadzo | C29: Mangwende | D29: 32-805477K30 | E29: =E28 -> 45747 | F29: Mimosa | G29: Service Assitant | H29: 4/3 | I29: 8106470P | J29: =AO29/AQ29 -> 0.437315 | K29: =K28 -> 3/2025 | L29: 208 | M29: 1.62 | N29: 14 | P29: =L29*M29 -> 336.96 | Q29: =P29*$Q$1 -> 8995.1809 | S29: =P29*0.3*$S$1*0.5 -> 1349.2771 | T29: =N29*M29*8*0.05 -> 9.072 | U29: =O29*M29*0.1 -> 0 | W29: =Y29*M29*2 -> 0 | X29: =Z29*M29*1.5 -> 0 | AA29: =CD29 -> 0 | AB29: =P29*0.075 -> 25.272 | AC29: =M29*8*AA29 -> 0 | AE29: =AO29/AQ29 -> 0.437315 | AF29: =P29+R29+T29+U29+V29+W29+X29+AB29+AC29+AD29 -> 371.304 | AG29: =AF29*0.5 -> 185.652 | AH29: =(AF29-AG29)*$AH$1+S29 -> 6305.2758 | AI29: =IF(Q29>18519.27,0.045*18519.27,Q29*0.045) -> 404.78314 | AJ29: =(AI29*0.5)/$AQ$1 -> 7.5816 | AK29: =(AI29*0.4) -> 161.91326 | AL29: 0 | AM29: =Q29*0.003 -> 26.985543 | AN29: =IF(AD29>320,320,AD29) -> 0 | AO29: =AG29-AN29-AJ29 -> 178.0704 | AP29: =AH29-AK29-AL29-AM29-BB29 -> 6116.377 | AQ29: =AO29+(AP29/$AQ$1) -> 407.19024 | AR29: =BT29 -> 66.79756 | AS29: 0 | AT29: =AR29-AS29 -> 66.79756 | AU29: =AT29*AE29 -> 29.211575 | AV29: =AU29*0.03 -> 0.87634725 | AW29: =(AT29-AU29)*$AQ$1 -> 1003.3616 | AX29: =AW29*0.03 -> 30.100849 | AY29: =AO29-AU29-AV29 -> 147.98248 | AZ29: =AP29-AW29-AX29 -> 5082.9146 | BA29: 0 | BB29: 0 | BC29: =20000/2499.9263 -> 8.0002358 | BI29: 12.5 | BL29: =AY29-BI29-BG29-BH29-BD29+BJ29 -> 135.48248 | BM29: =AZ29-BA29-BC29-BE29-BF29+BK29 -> 5074.9143 | BN29: =IF(AQ29<100,0,0) -> 0 | BO29: =IF(AQ29<100,"",IF(AQ29<=300,AQ29*0.2-20,)) -> 0 | BP29: =IF(AQ29<300.01,"",IF(AQ29<=1000,AQ29*0.25-35,)) -> 66.79756 | BQ29: =IF(AQ29<1000.01,"",IF(AQ29<=2000,AQ29*0.3-85,)) | BR29: =IF(AQ29<2000.01,"",IF(AQ29<=3000,AQ29*0.35-185,)) | BS29: =IF(AQ29<3000.01,"",IF(AQ29>3000,AQ29*0.4-335,)) | BT29: =SUM(BN29:BS29) -> 66.79756 | BU29: FBC | BV29: Zvishavane | BW29: 4503862507510 | BX29: FBC | BY29: Zvishavane | BZ29: 1430129610059 | CA29: 13.1 | CB29: 2.5 | CE29: =CA29+CB29-CC29-CD29 -> 15.6 | CF29: =M29*8 -> 12.96 | CG29: =CE29*CF29 -> 202.176 | CH29: =CG29*0.4 -> 80.8704 | CI29: =(CG29-CH29)*$CI$2 -> 3238.2651
A30: AES-E042 | B30: Vimbai | C30: Mpofu | D30: 07-356736R11 | E30: =E29 -> 45747 | F30: Mimosa | G30: UV Operator | H30: 4/4 | I30: 8231838M | J30: =AO30/AQ30 -> 0.44126518 | K30: =K29 -> 3/2025 | L30: 208 | M30: 1.76 | N30: 23 | O30: 116 | P30: =L30*M30 -> 366.08 | Q30: =P30*$Q$1 -> 9772.5422 | R30: =3 -> 3 | S30: =P30*0.3*$S$1*0.5 -> 1465.8813 | T30: =N30*M30*8*0.05 -> 16.192 | U30: =O30*M30*0.1 -> 20.416 | W30: =Y30*M30*2 -> 0 | X30: =Z30*M30*1.5 -> 0 | AA30: =CD30 -> 0 | AB30: =P30*0.075 -> 27.456 | AC30: =M30*8*AA30 -> 0 | AE30: =AO30/AQ30 -> 0.44126518 | AF30: =P30+R30+T30+U30+V30+W30+X30+AB30+AC30+AD30 -> 433.144 | AG30: =AF30*0.5 -> 216.572 | AH30: =(AF30-AG30)*$AH$1+S30 -> 7247.2925 | AI30: =IF(Q30>18519.27,0.045*18519.27,Q30*0.045) -> 439.7644 | AJ30: =(AI30*0.5)/$AQ$1 -> 8.2368 | AK30: =(AI30*0.4) -> 175.90576 | AL30: 0 | AM30: =Q30*0.003 -> 29.317627 | AN30: =IF(AD30>320,320,AD30) -> 0 | AO30: =AG30-AN30-AJ30 -> 208.3352 | AP30: =AH30-AK30-AL30-AM30-BB30 -> 7042.0691 | AQ30: =AO30+(AP30/$AQ$1) -> 472.13152 | AR30: =BT30 -> 83.03288 | AS30: 0 | AT30: =AR30-AS30 -> 83.03288 | AU30: =AT30*AE30 -> 36.639519 | AV30: =AU30*0.03 -> 1.0991856 | AW30: =(AT30-AU30)*$AQ$1 -> 1238.4754 | AX30: =AW30*0.03 -> 37.154263 | AY30: =AO30-AU30-AV30 -> 170.5965 | AZ30: =AP30-AW30-AX30 -> 5766.4395 | BA30: 0 | BB30: 0 | BD30: =70+50 -> 120 | BL30: =AY30-BI30-BG30-BH30-BD30+BJ30 -> 50.596496 | BM30: =AZ30-BA30-BC30-BE30-BF30+BK30 -> 5766.4395 | BN30: =IF(AQ30<100,0,0) -> 0 | BO30: =IF(AQ30<100,"",IF(AQ30<=300,AQ30*0.2-20,)) -> 0 | BP30: =IF(AQ30<300.01,"",IF(AQ30<=1000,AQ30*0.25-35,)) -> 83.03288 | BQ30: =IF(AQ30<1000.01,"",IF(AQ30<=2000,AQ30*0.3-85,)) | BR30: =IF(AQ30<2000.01,"",IF(AQ30<=3000,AQ30*0.35-185,)) | BS30: =IF(AQ30<3000.01,"",IF(AQ30>3000,AQ30*0.4-335,)) | BT30: =SUM(BN30:BS30) -> 83.03288 | BU30: NEDBANK | BV30: Zvishavane | BW30: 67790572388 | BX30: FBC | BY30: Zvishavane | CA30: 5.41 | CB30: 2.5 | CC30: 2 | CE30: =CA30+CB30-CC30-CD30 -> 5.91 | CF30: =M30*8 -> 14.08 | CG30: =CE30*CF30 -> 83.2128 | CH30: =CG30*0.4 -> 33.28512 | CI30: =(CG30-CH30)*$CI$2 -> 1332.8244
