Workbook

Sheet Cover
B2: OPERATIONAL CASHFLOW REPORT
B3: Airflow Environmental Solutions | www.aes.co.zw
B5: Mine ventilation, refuge chambers, safety & environmental solutions
B6: Report date: | C6: =RptDate -> 46227
B8: WORKBOOK CONTENTS
B9: =HYPERLINK("#Settings!A1","Settings") -> Settings | C9: Global rates, VAT %, exchange rates - set these first
B10: =HYPERLINK("#Clients!A1","Clients") -> Clients | C10: Customer master list (feeds all drop-downs)
B11: =HYPERLINK("#Contracts!A1","Contracts") -> Contracts | C11: Contract values, budgets and claim variance
B12: =HYPERLINK("#Orders!A1","Orders") -> Orders | C12: Every order: health, payment, VAT, profit
B13: =HYPERLINK("#OrderExpenses!A1","OrderExpenses") -> OrderExpenses | C13: Costs tied to each order
B14: =HYPERLINK("#GeneralExpenses!A1","GeneralExpenses") -> GeneralExpenses | C14: Costs not tied to an order
B15: =HYPERLINK("#Overheads!A1","Overheads") -> Overheads | C15: Monthly salaries, PAYE, software, rentals
B16: =HYPERLINK("#Loans!A1","Loans") -> Loans | C16: Order-linked loans and interest
B17: =HYPERLINK("#ContractPayments!A1","ContractPayments") -> ContractPayments | C17: Monthly contract claims and VAT
B18: =HYPERLINK("#OtherTaxDebt!A1","OtherTaxDebt") -> OtherTaxDebt | C18: Tax brought forward from prior periods
B19: =HYPERLINK("#Tax!A1","Tax") -> Tax | C19: VAT & PAYE ledger (auto-consolidated)
B20: =HYPERLINK("#TaxDashboard!A1","TaxDashboard") -> TaxDashboard | C20: Compare to ZIMRA, interest, total liability
B21: =HYPERLINK("#OrdersDashboard!A1","OrdersDashboard") -> OrdersDashboard | C21: Order KPIs, charts and status board
B22: =HYPERLINK("#Receivables!A1","Receivables") -> Receivables | C22: Serviced orders awaiting payment
B23: =HYPERLINK("#VAT_Paid!A1","VAT_Paid") -> VAT_Paid | C23: VAT due, paid and outstanding per order
B24: =HYPERLINK("#Performance!A1","Performance") -> Performance | C24: Income vs expenses, debt funding, pending
B25: =HYPERLINK("#FinancialSummary!A1","FinancialSummary") -> FinancialSummary | C25: One-glance colour-coded health board
B26: =HYPERLINK("#Manual!A1","Manual") -> Manual | C26: Full user guide (also a separate document)
B28: Colour key:
B29: Yellow = you type here
B30: Black = formula result
B31: Green = pulled from another sheet
B33: Tip: click any blue name above to jump straight to that sheet.

Sheet Settings
A1: SETTINGS & ASSUMPTIONS
A2: Airflow Environmental Solutions | www.aes.co.zw | Update yellow cells regularly
A4: GLOBAL PARAMETERS
A5: Parameter | B5: Value | D5: Notes
A6: VAT Rate (Zimbabwe standard) | B6: 0.155 | D6: ZIMRA standard rate from 1 Jan 2026 (was 15%).
A7: Official Exchange Rate (ZiG per USD) | B7: 26.5 | D7: RBZ interbank rate. UPDATE regularly.
A8: Street / Parallel Rate (ZiG per USD) | B8: 33 | D8: Parallel-market rate. UPDATE regularly.
A9: ZIMRA Overdue-Tax Interest (per annum) | B9: 0.1 | D9: Foreign-currency rate per 2025 Rate of Interest Notice. Penalties up to 100% may also apply.
A10: Default Loan Interest (per week) | B10: 0.05 | D10: Default weekly rate for informal/bridging loans. Override per loan.
A11: Report / Valuation Date | B11: =TODAY() -> 46227 | D11: Auto. Drives all ageing & interest calcs.
A13: BUSINESS INFORMATION
A14: Business Name | B14: Airflow Environmental Solutions
A15: Website | B15: www.aes.co.zw
A16: Sector | B16: Mine ventilation, refuge chambers, safety & environmental solutions
A17: Reporting Currency | B17: USD
A19: PICK-LISTS (used by drop-downs)
A20: Yes/No | B20: Order Status | C20: Expense Category | D20: Tax Type
A21: Yes | B21: Open | C21: Materials | D21: VAT
A22: No | B22: Awaiting Payment | C22: Labour | D22: PAYE
B23: Overdue Payment | C23: Transport
B24: Overdue Service | C24: Equipment
B25: Advance Paid | C25: Subcontract
B26: Paid | C26: Admin
C27: Finance
C28: Other
A30: HEALTH COLOUR LEGEND
A31: Paid | B31: Order fully settled.
A32: Advance Paid | B32: Money received before service delivered.
A33: Awaiting Payment | B33: Serviced, invoice outstanding, not yet overdue.
A34: Overdue Payment | B34: Serviced, payment past closing date.
A35: Overdue Service | B35: Not serviced and past closing date.
A36: Open | B36: Active, within timeline, no money in.

Sheet Clients
A1: CLIENTS
A2: Master list of clients. Names here feed every drop-down in the workbook.
A4: Client Name | B4: Contact Person | C4: Phone | D4: Email | E4: Physical Address | F4: BP / TIN No. | G4: VAT Reg No. | H4: Notes
A5: Zimplats | B5: Procurement Office | C5: +263 71 000 0001 | D5: procurement@zimplats.com | E5: Ngezi, Mhondoro-Ngezi | F5: BP2000001 | G5: 10000001 | H5: Frequent ad-hoc orders
A6: Mimosa Mining | B6: Engineering Dept | C6: +263 71 000 0002 | D6: eng@mimosa.co.zw | E6: Mimosa Mine, Zvishavane | F6: BP2000002 | G6: 10000002 | H6: 2 contracts + orders
A7: Unki Mine | B7: SHE Department | C7: +263 71 000 0003 | D7: she@unki.co.zw | E7: Shurugwi | F7: BP2000003 | G7: 10000003 | H7: Refuge chambers contract
A8: Zvishavane Engineering Ltd | B8: T. Marufu | C8: +263 71 555 0142 | D8: orders@zvisheng.co.zw | E8: Zvishavane | F8: BP2000104 | G8: 10000104 | H8: Occasional fabrication orders (sample)
A9: GreatDyke Contractors | B9: R. Nyamande | C9: +263 77 555 0968 | D9: admin@gdcon.co.zw | E9: Shurugwi | F9: BP2000177 | G9: 10000177 | H9: Sub-contract partner (sample)

Sheet Contracts
A1: CONTRACTS REGISTER
A2: Long-term contracts. Monthly budget = value / duration; variance shows under/over-claiming vs. expected to date.
A4: Contract ID | B4: Client | C4: Title / Scope | D4: Contract Value (ex VAT, $) | E4: Start Date | F4: End Date | G4: Duration (mths) | H4: Monthly Budget ($) | I4: Invoiced to Date ($) | J4: Months Elapsed | K4: Expected to Date ($) | L4: Variance ($) +over/-under | M4: Status | N4: Notes
A5: UNK-CT-01 | B5: Unki Mine | C5: Construction of refuge chambers & installation of lifelines | D5: 480000 | E5: 46023 | F5: 46387 | G5: =IF(OR($E5="",$F5=""),"",DATEDIF($E5,$F5,"m")+1) -> 12 | H5: =IF(OR($D5="",$G5="",$G5=0),"",$D5/$G5) -> 40000 | I5: =IF($A5="","",SUMIFS(ContractPayments!$F$5:$F$64,ContractPayments!$B$5:$B$64,$A5)) -> 165000 | J5: =IF($E5="","",IF(TODAY()<$E5,0,MIN($G5,DATEDIF($E5,TODAY(),"m")+1))) -> 7 | K5: =IF(OR($H5="",$J5=""),"",$H5*$J5) -> 280000 | L5: =IF(OR($I5="",$K5=""),"",$I5-$K5) -> -115000 | M5: =IF($A5="","",IF(TODAY()<$E5,"Upcoming",IF(TODAY()>$F5,"Completed","Active"))) -> Active
A6: MIM-CT-02 | B6: Mimosa Mining | C6: Underground roadway construction | D6: 360000 | E6: 46054 | F6: 46356 | G6: =IF(OR($E6="",$F6=""),"",DATEDIF($E6,$F6,"m")+1) -> 10 | H6: =IF(OR($D6="",$G6="",$G6=0),"",$D6/$G6) -> 36000 | I6: =IF($A6="","",SUMIFS(ContractPayments!$F$5:$F$64,ContractPayments!$B$5:$B$64,$A6)) -> 35000 | J6: =IF($E6="","",IF(TODAY()<$E6,0,MIN($G6,DATEDIF($E6,TODAY(),"m")+1))) -> 6 | K6: =IF(OR($H6="",$J6=""),"",$H6*$J6) -> 216000 | L6: =IF(OR($I6="",$K6=""),"",$I6-$K6) -> -181000 | M6: =IF($A6="","",IF(TODAY()<$E6,"Upcoming",IF(TODAY()>$F6,"Completed","Active"))) -> Active
A7: MIM-CT-03 | B7: Mimosa Mining | C7: Ventilation construction | D7: 300000 | E7: 46082 | F7: 46387 | G7: =IF(OR($E7="",$F7=""),"",DATEDIF($E7,$F7,"m")+1) -> 10 | H7: =IF(OR($D7="",$G7="",$G7=0),"",$D7/$G7) -> 30000 | I7: =IF($A7="","",SUMIFS(ContractPayments!$F$5:$F$64,ContractPayments!$B$5:$B$64,$A7)) -> 47000 | J7: =IF($E7="","",IF(TODAY()<$E7,0,MIN($G7,DATEDIF($E7,TODAY(),"m")+1))) -> 5 | K7: =IF(OR($H7="",$J7=""),"",$H7*$J7) -> 150000 | L7: =IF(OR($I7="",$K7=""),"",$I7-$K7) -> -103000 | M7: =IF($A7="","",IF(TODAY()<$E7,"Upcoming",IF(TODAY()>$F7,"Completed","Active"))) -> Active
A8: MIM-CT-03 | B8: Mimosa Mining | C8: Ventilation walls phase 2 (sample) | D8: 264000 | E8: 46082 | F8: 46387 | G8: =IF(OR($E8="",$F8=""),"",DATEDIF($E8,$F8,"m")+1) -> 10 | H8: =IF(OR($D8="",$G8="",$G8=0),"",$D8/$G8) -> 26400 | I8: =IF($A8="","",SUMIFS(ContractPayments!$F$5:$F$64,ContractPayments!$B$5:$B$64,$A8)) -> 47000 | J8: =IF($E8="","",IF(TODAY()<$E8,0,MIN($G8,DATEDIF($E8,TODAY(),"m")+1))) -> 5 | K8: =IF(OR($H8="",$J8=""),"",$H8*$J8) -> 132000 | L8: =IF(OR($I8="",$K8=""),"",$I8-$K8) -> -85000 | M8: =IF($A8="","",IF(TODAY()<$E8,"Upcoming",IF(TODAY()>$F8,"Completed","Active"))) -> Active | N8: Sample data
G9: =IF(OR($E9="",$F9=""),"",DATEDIF($E9,$F9,"m")+1) | H9: =IF(OR($D9="",$G9="",$G9=0),"",$D9/$G9) | I9: =IF($A9="","",SUMIFS(ContractPayments!$F$5:$F$64,ContractPayments!$B$5:$B$64,$A9)) | J9: =IF($E9="","",IF(TODAY()<$E9,0,MIN($G9,DATEDIF($E9,TODAY(),"m")+1))) | K9: =IF(OR($H9="",$J9=""),"",$H9*$J9) | L9: =IF(OR($I9="",$K9=""),"",$I9-$K9) | M9: =IF($A9="","",IF(TODAY()<$E9,"Upcoming",IF(TODAY()>$F9,"Completed","Active")))
G10: =IF(OR($E10="",$F10=""),"",DATEDIF($E10,$F10,"m")+1) | H10: =IF(OR($D10="",$G10="",$G10=0),"",$D10/$G10) | I10: =IF($A10="","",SUMIFS(ContractPayments!$F$5:$F$64,ContractPayments!$B$5:$B$64,$A10)) | J10: =IF($E10="","",IF(TODAY()<$E10,0,MIN($G10,DATEDIF($E10,TODAY(),"m")+1))) | K10: =IF(OR($H10="",$J10=""),"",$H10*$J10) | L10: =IF(OR($I10="",$K10=""),"",$I10-$K10) | M10: =IF($A10="","",IF(TODAY()<$E10,"Upcoming",IF(TODAY()>$F10,"Completed","Active")))
G11: =IF(OR($E11="",$F11=""),"",DATEDIF($E11,$F11,"m")+1) | H11: =IF(OR($D11="",$G11="",$G11=0),"",$D11/$G11) | I11: =IF($A11="","",SUMIFS(ContractPayments!$F$5:$F$64,ContractPayments!$B$5:$B$64,$A11)) | J11: =IF($E11="","",IF(TODAY()<$E11,0,MIN($G11,DATEDIF($E11,TODAY(),"m")+1))) | K11: =IF(OR($H11="",$J11=""),"",$H11*$J11) | L11: =IF(OR($I11="",$K11=""),"",$I11-$K11) | M11: =IF($A11="","",IF(TODAY()<$E11,"Upcoming",IF(TODAY()>$F11,"Completed","Active")))
G12: =IF(OR($E12="",$F12=""),"",DATEDIF($E12,$F12,"m")+1) | H12: =IF(OR($D12="",$G12="",$G12=0),"",$D12/$G12) | I12: =IF($A12="","",SUMIFS(ContractPayments!$F$5:$F$64,ContractPayments!$B$5:$B$64,$A12)) | J12: =IF($E12="","",IF(TODAY()<$E12,0,MIN($G12,DATEDIF($E12,TODAY(),"m")+1))) | K12: =IF(OR($H12="",$J12=""),"",$H12*$J12) | L12: =IF(OR($I12="",$K12=""),"",$I12-$K12) | M12: =IF($A12="","",IF(TODAY()<$E12,"Upcoming",IF(TODAY()>$F12,"Completed","Active")))
G13: =IF(OR($E13="",$F13=""),"",DATEDIF($E13,$F13,"m")+1) | H13: =IF(OR($D13="",$G13="",$G13=0),"",$D13/$G13) | I13: =IF($A13="","",SUMIFS(ContractPayments!$F$5:$F$64,ContractPayments!$B$5:$B$64,$A13)) | J13: =IF($E13="","",IF(TODAY()<$E13,0,MIN($G13,DATEDIF($E13,TODAY(),"m")+1))) | K13: =IF(OR($H13="",$J13=""),"",$H13*$J13) | L13: =IF(OR($I13="",$K13=""),"",$I13-$K13) | M13: =IF($A13="","",IF(TODAY()<$E13,"Upcoming",IF(TODAY()>$F13,"Completed","Active")))
G14: =IF(OR($E14="",$F14=""),"",DATEDIF($E14,$F14,"m")+1) | H14: =IF(OR($D14="",$G14="",$G14=0),"",$D14/$G14) | I14: =IF($A14="","",SUMIFS(ContractPayments!$F$5:$F$64,ContractPayments!$B$5:$B$64,$A14)) | J14: =IF($E14="","",IF(TODAY()<$E14,0,MIN($G14,DATEDIF($E14,TODAY(),"m")+1))) | K14: =IF(OR($H14="",$J14=""),"",$H14*$J14) | L14: =IF(OR($I14="",$K14=""),"",$I14-$K14) | M14: =IF($A14="","",IF(TODAY()<$E14,"Upcoming",IF(TODAY()>$F14,"Completed","Active")))
G15: =IF(OR($E15="",$F15=""),"",DATEDIF($E15,$F15,"m")+1) | H15: =IF(OR($D15="",$G15="",$G15=0),"",$D15/$G15) | I15: =IF($A15="","",SUMIFS(ContractPayments!$F$5:$F$64,ContractPayments!$B$5:$B$64,$A15)) | J15: =IF($E15="","",IF(TODAY()<$E15,0,MIN($G15,DATEDIF($E15,TODAY(),"m")+1))) | K15: =IF(OR($H15="",$J15=""),"",$H15*$J15) | L15: =IF(OR($I15="",$K15=""),"",$I15-$K15) | M15: =IF($A15="","",IF(TODAY()<$E15,"Upcoming",IF(TODAY()>$F15,"Completed","Active")))
G16: =IF(OR($E16="",$F16=""),"",DATEDIF($E16,$F16,"m")+1) | H16: =IF(OR($D16="",$G16="",$G16=0),"",$D16/$G16) | I16: =IF($A16="","",SUMIFS(ContractPayments!$F$5:$F$64,ContractPayments!$B$5:$B$64,$A16)) | J16: =IF($E16="","",IF(TODAY()<$E16,0,MIN($G16,DATEDIF($E16,TODAY(),"m")+1))) | K16: =IF(OR($H16="",$J16=""),"",$H16*$J16) | L16: =IF(OR($I16="",$K16=""),"",$I16-$K16) | M16: =IF($A16="","",IF(TODAY()<$E16,"Upcoming",IF(TODAY()>$F16,"Completed","Active")))
G17: =IF(OR($E17="",$F17=""),"",DATEDIF($E17,$F17,"m")+1) | H17: =IF(OR($D17="",$G17="",$G17=0),"",$D17/$G17) | I17: =IF($A17="","",SUMIFS(ContractPayments!$F$5:$F$64,ContractPayments!$B$5:$B$64,$A17)) | J17: =IF($E17="","",IF(TODAY()<$E17,0,MIN($G17,DATEDIF($E17,TODAY(),"m")+1))) | K17: =IF(OR($H17="",$J17=""),"",$H17*$J17) | L17: =IF(OR($I17="",$K17=""),"",$I17-$K17) | M17: =IF($A17="","",IF(TODAY()<$E17,"Upcoming",IF(TODAY()>$F17,"Completed","Active")))
G18: =IF(OR($E18="",$F18=""),"",DATEDIF($E18,$F18,"m")+1) | H18: =IF(OR($D18="",$G18="",$G18=0),"",$D18/$G18) | I18: =IF($A18="","",SUMIFS(ContractPayments!$F$5:$F$64,ContractPayments!$B$5:$B$64,$A18)) | J18: =IF($E18="","",IF(TODAY()<$E18,0,MIN($G18,DATEDIF($E18,TODAY(),"m")+1))) | K18: =IF(OR($H18="",$J18=""),"",$H18*$J18) | L18: =IF(OR($I18="",$K18=""),"",$I18-$K18) | M18: =IF($A18="","",IF(TODAY()<$E18,"Upcoming",IF(TODAY()>$F18,"Completed","Active")))
G19: =IF(OR($E19="",$F19=""),"",DATEDIF($E19,$F19,"m")+1) | H19: =IF(OR($D19="",$G19="",$G19=0),"",$D19/$G19) | I19: =IF($A19="","",SUMIFS(ContractPayments!$F$5:$F$64,ContractPayments!$B$5:$B$64,$A19)) | J19: =IF($E19="","",IF(TODAY()<$E19,0,MIN($G19,DATEDIF($E19,TODAY(),"m")+1))) | K19: =IF(OR($H19="",$J19=""),"",$H19*$J19) | L19: =IF(OR($I19="",$K19=""),"",$I19-$K19) | M19: =IF($A19="","",IF(TODAY()<$E19,"Upcoming",IF(TODAY()>$F19,"Completed","Active")))
G20: =IF(OR($E20="",$F20=""),"",DATEDIF($E20,$F20,"m")+1) | H20: =IF(OR($D20="",$G20="",$G20=0),"",$D20/$G20) | I20: =IF($A20="","",SUMIFS(ContractPayments!$F$5:$F$64,ContractPayments!$B$5:$B$64,$A20)) | J20: =IF($E20="","",IF(TODAY()<$E20,0,MIN($G20,DATEDIF($E20,TODAY(),"m")+1))) | K20: =IF(OR($H20="",$J20=""),"",$H20*$J20) | L20: =IF(OR($I20="",$K20=""),"",$I20-$K20) | M20: =IF($A20="","",IF(TODAY()<$E20,"Upcoming",IF(TODAY()>$F20,"Completed","Active")))
... G34: =IF(OR($E34="",$F34=""),"",DATEDIF($E34,$F34,"m")+1) | H34: =IF(OR($D34="",$G34="",$G34=0),"",$D34/$G34) | I34: =IF($A34="","",SUMIFS(ContractPayments!$F$5:$F$64,ContractPayments!$B$5:$B$64,$A34)) | J34: =IF($E34="","",IF(TODAY()<$E34,0,MIN($G34,DATEDIF($E34,TODAY(),"m")+1))) | K34: =IF(OR($H34="",$J34=""),"",$H34*$J34) | L34: =IF(OR($I34="",$K34=""),"",$I34-$K34) | M34: =IF($A34="","",IF(TODAY()<$E34,"Upcoming",IF(TODAY()>$F34,"Completed","Active")))

Sheet Orders
A1: ORDERS
A2: Ad-hoc orders. Health auto-colours from service/payment status. USD shown at both official & street rates.
A4: Order No | B4: Order Title | C4: Client | D4: Date Issued | E4: Closing Date | F4: Order Value (ex VAT, $) | G4: VAT @15.5% ($) | H4: Total incl VAT ($) | I4: Spent to Date (ex VAT, $) | J4: Serviced? | K4: Date Serviced | L4: Advance Paid? | M4: Received USD (direct) | N4: Received ZiG | O4: Official Rate | P4: ZiG→USD @Official | Q4: Street Rate | R4: ZiG→USD @Street | S4: Total USD @Official | T4: Total USD @Street | U4: Outstanding ($) | V4: VAT Paid to Date ($) | W4: Payment Status | X4: Profit/Loss ex VAT ($) | Y4: Loan Interest ($) | Z4: Net Profit after Loan ($) | AA4: Margin % | AB4: Health | AC4: Notes
A5: AES-O-001 | B5: Underground ventilation doors (x10) | C5: Zimplats | D5: 46147 | E5: 46188 | F5: 18000 | G5: =IF($F5="","",$F5*VATRate) -> 2790 | H5: =IF($F5="","",$F5+$G5) -> 20790 | I5: =IF($A5="","",SUMIFS(OrderExpenses!$G$5:$G$84,OrderExpenses!$B$5:$B$84,$A5)) -> 8300 | J5: Yes | K5: 46174 | L5: No | M5: 10000 | N5: 120000 | O5: =OffRate -> 26.5 | P5: =IF($N5="","",$N5/$O5) -> 4528.3019 | Q5: =StreetRate -> 33 | R5: =IF($N5="","",$N5/$Q5) -> 3636.3636 | S5: =IF($A5="","",IF($M5="",0,$M5)+IF($N5="",0,$N5/$O5)) -> 14528.302 | T5: =IF($A5="","",IF($M5="",0,$M5)+IF($N5="",0,$N5/$Q5)) -> 13636.364 | U5: =IF($A5="","",$H5-$S5) -> 6261.6981 | V5: 0 | W5: =IF($A5="","",IF($S5>=$H5-0.01,"Paid",IF($S5>0,"Partially Paid","Unpaid"))) -> Partially Paid | X5: =IF($A5="","",$F5-$I5) -> 9700 | Y5: =IF($A5="","",SUMIFS(Loans!$H$5:$H$44,Loans!$B$5:$B$44,$A5)) -> 2750 | Z5: =IF($A5="","",$X5-$Y5) -> 6950 | AA5: =IF(OR($A5="",$F5=0),"",$X5/$F5) -> 0.53888889 | AB5: =IF($A5="","",IF($S5>=$H5-0.01,"Paid",IF(AND($S5>0,$J5<>"Yes"),"Advance Paid",IF($J5="Yes",IF(AND($E5<>"",TODAY()>$E5),"Overdue Payment","Awaiting Payment"),IF(AND($E5<>"",TODAY()>$E5),"Overdue Service","Open"))))) -> Overdue Payment
A6: AES-O-002 | B6: Safety explosive storage boxes (x6) | C6: Mimosa Mining | D6: 46162 | E6: 46203 | F6: 9500 | G6: =IF($F6="","",$F6*VATRate) -> 1472.5 | H6: =IF($F6="","",$F6+$G6) -> 10972.5 | I6: =IF($A6="","",SUMIFS(OrderExpenses!$G$5:$G$84,OrderExpenses!$B$5:$B$84,$A6)) -> 3200 | J6: Yes | K6: 46183 | L6: No | M6: 0 | N6: 0 | O6: =OffRate -> 26.5 | P6: =IF($N6="","",$N6/$O6) -> 0 | Q6: =StreetRate -> 33 | R6: =IF($N6="","",$N6/$Q6) -> 0 | S6: =IF($A6="","",IF($M6="",0,$M6)+IF($N6="",0,$N6/$O6)) -> 0 | T6: =IF($A6="","",IF($M6="",0,$M6)+IF($N6="",0,$N6/$Q6)) -> 0 | U6: =IF($A6="","",$H6-$S6) -> 10972.5 | V6: 0 | W6: =IF($A6="","",IF($S6>=$H6-0.01,"Paid",IF($S6>0,"Partially Paid","Unpaid"))) -> Unpaid | X6: =IF($A6="","",$F6-$I6) -> 6300 | Y6: =IF($A6="","",SUMIFS(Loans!$H$5:$H$44,Loans!$B$5:$B$44,$A6)) -> 1350 | Z6: =IF($A6="","",$X6-$Y6) -> 4950 | AA6: =IF(OR($A6="",$F6=0),"",$X6/$F6) -> 0.66315789 | AB6: =IF($A6="","",IF($S6>=$H6-0.01,"Paid",IF(AND($S6>0,$J6<>"Yes"),"Advance Paid",IF($J6="Yes",IF(AND($E6<>"",TODAY()>$E6),"Overdue Payment","Awaiting Payment"),IF(AND($E6<>"",TODAY()>$E6),"Overdue Service","Open"))))) -> Overdue Payment
A7: AES-O-003 | B7: Air sampling services - Q2 | C7: Unki Mine | D7: 46175 | E7: 46198 | F7: 6200 | G7: =IF($F7="","",$F7*VATRate) -> 961 | H7: =IF($F7="","",$F7+$G7) -> 7161 | I7: =IF($A7="","",SUMIFS(OrderExpenses!$G$5:$G$84,OrderExpenses!$B$5:$B$84,$A7)) -> 1500 | J7: No | L7: Yes | M7: 3000 | N7: 0 | O7: =OffRate -> 26.5 | P7: =IF($N7="","",$N7/$O7) -> 0 | Q7: =StreetRate -> 33 | R7: =IF($N7="","",$N7/$Q7) -> 0 | S7: =IF($A7="","",IF($M7="",0,$M7)+IF($N7="",0,$N7/$O7)) -> 3000 | T7: =IF($A7="","",IF($M7="",0,$M7)+IF($N7="",0,$N7/$Q7)) -> 3000 | U7: =IF($A7="","",$H7-$S7) -> 4161 | V7: 0 | W7: =IF($A7="","",IF($S7>=$H7-0.01,"Paid",IF($S7>0,"Partially Paid","Unpaid"))) -> Partially Paid | X7: =IF($A7="","",$F7-$I7) -> 4700 | Y7: =IF($A7="","",SUMIFS(Loans!$H$5:$H$44,Loans!$B$5:$B$44,$A7)) -> 0 | Z7: =IF($A7="","",$X7-$Y7) -> 4700 | AA7: =IF(OR($A7="",$F7=0),"",$X7/$F7) -> 0.75806452 | AB7: =IF($A7="","",IF($S7>=$H7-0.01,"Paid",IF(AND($S7>0,$J7<>"Yes"),"Advance Paid",IF($J7="Yes",IF(AND($E7<>"",TODAY()>$E7),"Overdue Payment","Awaiting Payment"),IF(AND($E7<>"",TODAY()>$E7),"Overdue Service","Open"))))) -> Advance Paid
A8: AES-O-004 | B8: Underground ventilation doors - batch 2 | C8: Zimplats | D8: 46183 | E8: 46223 | F8: 15000 | G8: =IF($F8="","",$F8*VATRate) -> 2325 | H8: =IF($F8="","",$F8+$G8) -> 17325 | I8: =IF($A8="","",SUMIFS(OrderExpenses!$G$5:$G$84,OrderExpenses!$B$5:$B$84,$A8)) -> 0 | J8: No | L8: No | M8: 0 | N8: 0 | O8: =OffRate -> 26.5 | P8: =IF($N8="","",$N8/$O8) -> 0 | Q8: =StreetRate -> 33 | R8: =IF($N8="","",$N8/$Q8) -> 0 | S8: =IF($A8="","",IF($M8="",0,$M8)+IF($N8="",0,$N8/$O8)) -> 0 | T8: =IF($A8="","",IF($M8="",0,$M8)+IF($N8="",0,$N8/$Q8)) -> 0 | U8: =IF($A8="","",$H8-$S8) -> 17325 | V8: 0 | W8: =IF($A8="","",IF($S8>=$H8-0.01,"Paid",IF($S8>0,"Partially Paid","Unpaid"))) -> Unpaid | X8: =IF($A8="","",$F8-$I8) -> 15000 | Y8: =IF($A8="","",SUMIFS(Loans!$H$5:$H$44,Loans!$B$5:$B$44,$A8)) -> 2011.4286 | Z8: =IF($A8="","",$X8-$Y8) -> 12988.571 | AA8: =IF(OR($A8="",$F8=0),"",$X8/$F8) -> 1 | AB8: =IF($A8="","",IF($S8>=$H8-0.01,"Paid",IF(AND($S8>0,$J8<>"Yes"),"Advance Paid",IF($J8="Yes",IF(AND($E8<>"",TODAY()>$E8),"Overdue Payment","Awaiting Payment"),IF(AND($E8<>"",TODAY()>$E8),"Overdue Service","Open"))))) -> Overdue Service
A9: AES-O-005 | B9: Safety explosive storage boxes x6 | C9: Zimplats | D9: 46118 | E9: 46172 | F9: 21600 | G9: =IF($F9="","",$F9*VATRate) -> 3348 | H9: =IF($F9="","",$F9+$G9) -> 24948 | I9: =IF($A9="","",SUMIFS(OrderExpenses!$G$5:$G$84,OrderExpenses!$B$5:$B$84,$A9)) -> 11300 | J9: Yes | K9: 46154 | L9: No | M9: 25000 | N9: 0 | O9: =OffRate -> 26.5 | P9: =IF($N9="","",$N9/$O9) -> 0 | Q9: =StreetRate -> 33 | R9: =IF($N9="","",$N9/$Q9) -> 0 | S9: =IF($A9="","",IF($M9="",0,$M9)+IF($N9="",0,$N9/$O9)) -> 25000 | T9: =IF($A9="","",IF($M9="",0,$M9)+IF($N9="",0,$N9/$Q9)) -> 25000 | U9: =IF($A9="","",$H9-$S9) -> -52 | V9: 1200 | W9: =IF($A9="","",IF($S9>=$H9-0.01,"Paid",IF($S9>0,"Partially Paid","Unpaid"))) -> Paid | X9: =IF($A9="","",$F9-$I9) -> 10300 | Y9: =IF($A9="","",SUMIFS(Loans!$H$5:$H$44,Loans!$B$5:$B$44,$A9)) -> 0 | Z9: =IF($A9="","",$X9-$Y9) -> 10300 | AA9: =IF(OR($A9="",$F9=0),"",$X9/$F9) -> 0.47685185 | AB9: =IF($A9="","",IF($S9>=$H9-0.01,"Paid",IF(AND($S9>0,$J9<>"Yes"),"Advance Paid",IF($J9="Yes",IF(AND($E9<>"",TODAY()>$E9),"Overdue Payment","Awaiting Payment"),IF(AND($E9<>"",TODAY()>$E9),"Overdue Service","Open"))))) -> Paid | AC9: Sample data
A10: AES-O-006 | B10: Air sampling services Q2 | C10: Mimosa Mining | D10: 46126 | E10: 46187 | F10: 7800 | G10: =IF($F10="","",$F10*VATRate) -> 1209 | H10: =IF($F10="","",$F10+$G10) -> 9009 | I10: =IF($A10="","",SUMIFS(OrderExpenses!$G$5:$G$84,OrderExpenses!$B$5:$B$84,$A10)) -> 1150 | J10: Yes | K10: 46175 | L10: No | M10: 0 | N10: 98000 | O10: =OffRate -> 26.5 | P10: =IF($N10="","",$N10/$O10) -> 3698.1132 | Q10: =StreetRate -> 33 | R10: =IF($N10="","",$N10/$Q10) -> 2969.697 | S10: =IF($A10="","",IF($M10="",0,$M10)+IF($N10="",0,$N10/$O10)) -> 3698.1132 | T10: =IF($A10="","",IF($M10="",0,$M10)+IF($N10="",0,$N10/$Q10)) -> 2969.697 | U10: =IF($A10="","",$H10-$S10) -> 5310.8868 | V10: 0 | W10: =IF($A10="","",IF($S10>=$H10-0.01,"Paid",IF($S10>0,"Partially Paid","Unpaid"))) -> Partially Paid | X10: =IF($A10="","",$F10-$I10) -> 6650 | Y10: =IF($A10="","",SUMIFS(Loans!$H$5:$H$44,Loans!$B$5:$B$44,$A10)) -> 0 | Z10: =IF($A10="","",$X10-$Y10) -> 6650 | AA10: =IF(OR($A10="",$F10=0),"",$X10/$F10) -> 0.8525641 | AB10: =IF($A10="","",IF($S10>=$H10-0.01,"Paid",IF(AND($S10>0,$J10<>"Yes"),"Advance Paid",IF($J10="Yes",IF(AND($E10<>"",TODAY()>$E10),"Overdue Payment","Awaiting Payment"),IF(AND($E10<>"",TODAY()>$E10),"Overdue Service","Open"))))) -> Overdue Payment | AC10: Sample data
A11: AES-O-007 | B11: Underground ventilation doors x4 | C11: Unki Mine | D11: 46146 | E11: 46213 | F11: 30400 | G11: =IF($F11="","",$F11*VATRate) -> 4712 | H11: =IF($F11="","",$F11+$G11) -> 35112 | I11: =IF($A11="","",SUMIFS(OrderExpenses!$G$5:$G$84,OrderExpenses!$B$5:$B$84,$A11)) -> 17000 | J11: Yes | K11: 46205 | L11: No | M11: 0 | N11: 0 | O11: =OffRate -> 26.5 | P11: =IF($N11="","",$N11/$O11) -> 0 | Q11: =StreetRate -> 33 | R11: =IF($N11="","",$N11/$Q11) -> 0 | S11: =IF($A11="","",IF($M11="",0,$M11)+IF($N11="",0,$N11/$O11)) -> 0 | T11: =IF($A11="","",IF($M11="",0,$M11)+IF($N11="",0,$N11/$Q11)) -> 0 | U11: =IF($A11="","",$H11-$S11) -> 35112 | V11: 0 | W11: =IF($A11="","",IF($S11>=$H11-0.01,"Paid",IF($S11>0,"Partially Paid","Unpaid"))) -> Unpaid | X11: =IF($A11="","",$F11-$I11) -> 13400 | Y11: =IF($A11="","",SUMIFS(Loans!$H$5:$H$44,Loans!$B$5:$B$44,$A11)) -> 5142.8571 | Z11: =IF($A11="","",$X11-$Y11) -> 8257.1429 | AA11: =IF(OR($A11="",$F11=0),"",$X11/$F11) -> 0.44078947 | AB11: =IF($A11="","",IF($S11>=$H11-0.01,"Paid",IF(AND($S11>0,$J11<>"Yes"),"Advance Paid",IF($J11="Yes",IF(AND($E11<>"",TODAY()>$E11),"Overdue Payment","Awaiting Payment"),IF(AND($E11<>"",TODAY()>$E11),"Overdue Service","Open"))))) -> Overdue Payment | AC11: Sample data
A12: AES-O-008 | B12: Refuge chamber service kit | C12: Zimplats | D12: 46162 | E12: 46193 | F12: 5400 | G12: =IF($F12="","",$F12*VATRate) -> 837 | H12: =IF($F12="","",$F12+$G12) -> 6237 | I12: =IF($A12="","",SUMIFS(OrderExpenses!$G$5:$G$84,OrderExpenses!$B$5:$B$84,$A12)) -> 1900 | J12: No | L12: Yes | M12: 6237 | N12: 0 | O12: =OffRate -> 26.5 | P12: =IF($N12="","",$N12/$O12) -> 0 | Q12: =StreetRate -> 33 | R12: =IF($N12="","",$N12/$Q12) -> 0 | S12: =IF($A12="","",IF($M12="",0,$M12)+IF($N12="",0,$N12/$O12)) -> 6237 | T12: =IF($A12="","",IF($M12="",0,$M12)+IF($N12="",0,$N12/$Q12)) -> 6237 | U12: =IF($A12="","",$H12-$S12) -> 0 | V12: 0 | W12: =IF($A12="","",IF($S12>=$H12-0.01,"Paid",IF($S12>0,"Partially Paid","Unpaid"))) -> Paid | X12: =IF($A12="","",$F12-$I12) -> 3500 | Y12: =IF($A12="","",SUMIFS(Loans!$H$5:$H$44,Loans!$B$5:$B$44,$A12)) -> 0 | Z12: =IF($A12="","",$X12-$Y12) -> 3500 | AA12: =IF(OR($A12="",$F12=0),"",$X12/$F12) -> 0.64814815 | AB12: =IF($A12="","",IF($S12>=$H12-0.01,"Paid",IF(AND($S12>0,$J12<>"Yes"),"Advance Paid",IF($J12="Yes",IF(AND($E12<>"",TODAY()>$E12),"Overdue Payment","Awaiting Payment"),IF(AND($E12<>"",TODAY()>$E12),"Overdue Service","Open"))))) -> Paid | AC12: Sample data
A13: AES-O-009 | B13: Ducting fabrication 300m | C13: Mimosa Mining | D13: 46174 | E13: 46249 | F13: 26000 | G13: =IF($F13="","",$F13*VATRate) -> 4030 | H13: =IF($F13="","",$F13+$G13) -> 30030 | I13: =IF($A13="","",SUMIFS(OrderExpenses!$G$5:$G$84,OrderExpenses!$B$5:$B$84,$A13)) -> 8600 | J13: No | L13: No | M13: 0 | N13: 0 | O13: =OffRate -> 26.5 | P13: =IF($N13="","",$N13/$O13) -> 0 | Q13: =StreetRate -> 33 | R13: =IF($N13="","",$N13/$Q13) -> 0 | S13: =IF($A13="","",IF($M13="",0,$M13)+IF($N13="",0,$N13/$O13)) -> 0 | T13: =IF($A13="","",IF($M13="",0,$M13)+IF($N13="",0,$N13/$Q13)) -> 0 | U13: =IF($A13="","",$H13-$S13) -> 30030 | V13: 0 | W13: =IF($A13="","",IF($S13>=$H13-0.01,"Paid",IF($S13>0,"Partially Paid","Unpaid"))) -> Unpaid | X13: =IF($A13="","",$F13-$I13) -> 17400 | Y13: =IF($A13="","",SUMIFS(Loans!$H$5:$H$44,Loans!$B$5:$B$44,$A13)) -> 2800 | Z13: =IF($A13="","",$X13-$Y13) -> 14600 | AA13: =IF(OR($A13="",$F13=0),"",$X13/$F13) -> 0.66923077 | AB13: =IF($A13="","",IF($S13>=$H13-0.01,"Paid",IF(AND($S13>0,$J13<>"Yes"),"Advance Paid",IF($J13="Yes",IF(AND($E13<>"",TODAY()>$E13),"Overdue Payment","Awaiting Payment"),IF(AND($E13<>"",TODAY()>$E13),"Overdue Service","Open"))))) -> Open | AC13: Sample data
A14: AES-O-010 | B14: Airflow measurement audit | C14: Zvishavane Engineering Ltd | D14: 46182 | E14: 46208 | F14: 4200 | G14: =IF($F14="","",$F14*VATRate) -> 651 | H14: =IF($F14="","",$F14+$G14) -> 4851 | I14: =IF($A14="","",SUMIFS(OrderExpenses!$G$5:$G$84,OrderExpenses!$B$5:$B$84,$A14)) -> 900 | J14: Yes | K14: 46201 | L14: No | M14: 0 | N14: 0 | O14: =OffRate -> 26.5 | P14: =IF($N14="","",$N14/$O14) -> 0 | Q14: =StreetRate -> 33 | R14: =IF($N14="","",$N14/$Q14) -> 0 | S14: =IF($A14="","",IF($M14="",0,$M14)+IF($N14="",0,$N14/$O14)) -> 0 | T14: =IF($A14="","",IF($M14="",0,$M14)+IF($N14="",0,$N14/$Q14)) -> 0 | U14: =IF($A14="","",$H14-$S14) -> 4851 | V14: 0 | W14: =IF($A14="","",IF($S14>=$H14-0.01,"Paid",IF($S14>0,"Partially Paid","Unpaid"))) -> Unpaid | X14: =IF($A14="","",$F14-$I14) -> 3300 | Y14: =IF($A14="","",SUMIFS(Loans!$H$5:$H$44,Loans!$B$5:$B$44,$A14)) -> 0 | Z14: =IF($A14="","",$X14-$Y14) -> 3300 | AA14: =IF(OR($A14="",$F14=0),"",$X14/$F14) -> 0.78571429 | AB14: =IF($A14="","",IF($S14>=$H14-0.01,"Paid",IF(AND($S14>0,$J14<>"Yes"),"Advance Paid",IF($J14="Yes",IF(AND($E14<>"",TODAY()>$E14),"Overdue Payment","Awaiting Payment"),IF(AND($E14<>"",TODAY()>$E14),"Overdue Service","Open"))))) -> Overdue Payment | AC14: Sample data
G15: =IF($F15="","",$F15*VATRate) | H15: =IF($F15="","",$F15+$G15) | I15: =IF($A15="","",SUMIFS(OrderExpenses!$G$5:$G$84,OrderExpenses!$B$5:$B$84,$A15)) | O15: =OffRate -> 26.5 | P15: =IF($N15="","",$N15/$O15) | Q15: =StreetRate -> 33 | R15: =IF($N15="","",$N15/$Q15) | S15: =IF($A15="","",IF($M15="",0,$M15)+IF($N15="",0,$N15/$O15)) | T15: =IF($A15="","",IF($M15="",0,$M15)+IF($N15="",0,$N15/$Q15)) | U15: =IF($A15="","",$H15-$S15) | W15: =IF($A15="","",IF($S15>=$H15-0.01,"Paid",IF($S15>0,"Partially Paid","Unpaid"))) | X15: =IF($A15="","",$F15-$I15) | Y15: =IF($A15="","",SUMIFS(Loans!$H$5:$H$44,Loans!$B$5:$B$44,$A15)) | Z15: =IF($A15="","",$X15-$Y15) | AA15: =IF(OR($A15="",$F15=0),"",$X15/$F15) | AB15: =IF($A15="","",IF($S15>=$H15-0.01,"Paid",IF(AND($S15>0,$J15<>"Yes"),"Advance Paid",IF($J15="Yes",IF(AND($E15<>"",TODAY()>$E15),"Overdue Payment","Awaiting Payment"),IF(AND($E15<>"",TODAY()>$E15),"Overdue Service","Open")))))
G16: =IF($F16="","",$F16*VATRate) | H16: =IF($F16="","",$F16+$G16) | I16: =IF($A16="","",SUMIFS(OrderExpenses!$G$5:$G$84,OrderExpenses!$B$5:$B$84,$A16)) | O16: =OffRate -> 26.5 | P16: =IF($N16="","",$N16/$O16) | Q16: =StreetRate -> 33 | R16: =IF($N16="","",$N16/$Q16) | S16: =IF($A16="","",IF($M16="",0,$M16)+IF($N16="",0,$N16/$O16)) | T16: =IF($A16="","",IF($M16="",0,$M16)+IF($N16="",0,$N16/$Q16)) | U16: =IF($A16="","",$H16-$S16) | W16: =IF($A16="","",IF($S16>=$H16-0.01,"Paid",IF($S16>0,"Partially Paid","Unpaid"))) | X16: =IF($A16="","",$F16-$I16) | Y16: =IF($A16="","",SUMIFS(Loans!$H$5:$H$44,Loans!$B$5:$B$44,$A16)) | Z16: =IF($A16="","",$X16-$Y16) | AA16: =IF(OR($A16="",$F16=0),"",$X16/$F16) | AB16: =IF($A16="","",IF($S16>=$H16-0.01,"Paid",IF(AND($S16>0,$J16<>"Yes"),"Advance Paid",IF($J16="Yes",IF(AND($E16<>"",TODAY()>$E16),"Overdue Payment","Awaiting Payment"),IF(AND($E16<>"",TODAY()>$E16),"Overdue Service","Open")))))
G17: =IF($F17="","",$F17*VATRate) | H17: =IF($F17="","",$F17+$G17) | I17: =IF($A17="","",SUMIFS(OrderExpenses!$G$5:$G$84,OrderExpenses!$B$5:$B$84,$A17)) | O17: =OffRate -> 26.5 | P17: =IF($N17="","",$N17/$O17) | Q17: =StreetRate -> 33 | R17: =IF($N17="","",$N17/$Q17) | S17: =IF($A17="","",IF($M17="",0,$M17)+IF($N17="",0,$N17/$O17)) | T17: =IF($A17="","",IF($M17="",0,$M17)+IF($N17="",0,$N17/$Q17)) | U17: =IF($A17="","",$H17-$S17) | W17: =IF($A17="","",IF($S17>=$H17-0.01,"Paid",IF($S17>0,"Partially Paid","Unpaid"))) | X17: =IF($A17="","",$F17-$I17) | Y17: =IF($A17="","",SUMIFS(Loans!$H$5:$H$44,Loans!$B$5:$B$44,$A17)) | Z17: =IF($A17="","",$X17-$Y17) | AA17: =IF(OR($A17="",$F17=0),"",$X17/$F17) | AB17: =IF($A17="","",IF($S17>=$H17-0.01,"Paid",IF(AND($S17>0,$J17<>"Yes"),"Advance Paid",IF($J17="Yes",IF(AND($E17<>"",TODAY()>$E17),"Overdue Payment","Awaiting Payment"),IF(AND($E17<>"",TODAY()>$E17),"Overdue Service","Open")))))
G18: =IF($F18="","",$F18*VATRate) | H18: =IF($F18="","",$F18+$G18) | I18: =IF($A18="","",SUMIFS(OrderExpenses!$G$5:$G$84,OrderExpenses!$B$5:$B$84,$A18)) | O18: =OffRate -> 26.5 | P18: =IF($N18="","",$N18/$O18) | Q18: =StreetRate -> 33 | R18: =IF($N18="","",$N18/$Q18) | S18: =IF($A18="","",IF($M18="",0,$M18)+IF($N18="",0,$N18/$O18)) | T18: =IF($A18="","",IF($M18="",0,$M18)+IF($N18="",0,$N18/$Q18)) | U18: =IF($A18="","",$H18-$S18) | W18: =IF($A18="","",IF($S18>=$H18-0.01,"Paid",IF($S18>0,"Partially Paid","Unpaid"))) | X18: =IF($A18="","",$F18-$I18) | Y18: =IF($A18="","",SUMIFS(Loans!$H$5:$H$44,Loans!$B$5:$B$44,$A18)) | Z18: =IF($A18="","",$X18-$Y18) | AA18: =IF(OR($A18="",$F18=0),"",$X18/$F18) | AB18: =IF($A18="","",IF($S18>=$H18-0.01,"Paid",IF(AND($S18>0,$J18<>"Yes"),"Advance Paid",IF($J18="Yes",IF(AND($E18<>"",TODAY()>$E18),"Overdue Payment","Awaiting Payment"),IF(AND($E18<>"",TODAY()>$E18),"Overdue Service","Open")))))
G19: =IF($F19="","",$F19*VATRate) | H19: =IF($F19="","",$F19+$G19) | I19: =IF($A19="","",SUMIFS(OrderExpenses!$G$5:$G$84,OrderExpenses!$B$5:$B$84,$A19)) | O19: =OffRate -> 26.5 | P19: =IF($N19="","",$N19/$O19) | Q19: =StreetRate -> 33 | R19: =IF($N19="","",$N19/$Q19) | S19: =IF($A19="","",IF($M19="",0,$M19)+IF($N19="",0,$N19/$O19)) | T19: =IF($A19="","",IF($M19="",0,$M19)+IF($N19="",0,$N19/$Q19)) | U19: =IF($A19="","",$H19-$S19) | W19: =IF($A19="","",IF($S19>=$H19-0.01,"Paid",IF($S19>0,"Partially Paid","Unpaid"))) | X19: =IF($A19="","",$F19-$I19) | Y19: =IF($A19="","",SUMIFS(Loans!$H$5:$H$44,Loans!$B$5:$B$44,$A19)) | Z19: =IF($A19="","",$X19-$Y19) | AA19: =IF(OR($A19="",$F19=0),"",$X19/$F19) | AB19: =IF($A19="","",IF($S19>=$H19-0.01,"Paid",IF(AND($S19>0,$J19<>"Yes"),"Advance Paid",IF($J19="Yes",IF(AND($E19<>"",TODAY()>$E19),"Overdue Payment","Awaiting Payment"),IF(AND($E19<>"",TODAY()>$E19),"Overdue Service","Open")))))
G20: =IF($F20="","",$F20*VATRate) | H20: =IF($F20="","",$F20+$G20) | I20: =IF($A20="","",SUMIFS(OrderExpenses!$G$5:$G$84,OrderExpenses!$B$5:$B$84,$A20)) | O20: =OffRate -> 26.5 | P20: =IF($N20="","",$N20/$O20) | Q20: =StreetRate -> 33 | R20: =IF($N20="","",$N20/$Q20) | S20: =IF($A20="","",IF($M20="",0,$M20)+IF($N20="",0,$N20/$O20)) | T20: =IF($A20="","",IF($M20="",0,$M20)+IF($N20="",0,$N20/$Q20)) | U20: =IF($A20="","",$H20-$S20) | W20: =IF($A20="","",IF($S20>=$H20-0.01,"Paid",IF($S20>0,"Partially Paid","Unpaid"))) | X20: =IF($A20="","",$F20-$I20) | Y20: =IF($A20="","",SUMIFS(Loans!$H$5:$H$44,Loans!$B$5:$B$44,$A20)) | Z20: =IF($A20="","",$X20-$Y20) | AA20: =IF(OR($A20="",$F20=0),"",$X20/$F20) | AB20: =IF($A20="","",IF($S20>=$H20-0.01,"Paid",IF(AND($S20>0,$J20<>"Yes"),"Advance Paid",IF($J20="Yes",IF(AND($E20<>"",TODAY()>$E20),"Overdue Payment","Awaiting Payment"),IF(AND($E20<>"",TODAY()>$E20),"Overdue Service","Open")))))
G21: =IF($F21="","",$F21*VATRate) | H21: =IF($F21="","",$F21+$G21) | I21: =IF($A21="","",SUMIFS(OrderExpenses!$G$5:$G$84,OrderExpenses!$B$5:$B$84,$A21)) | O21: =OffRate -> 26.5 | P21: =IF($N21="","",$N21/$O21) | Q21: =StreetRate -> 33 | R21: =IF($N21="","",$N21/$Q21) | S21: =IF($A21="","",IF($M21="",0,$M21)+IF($N21="",0,$N21/$O21)) | T21: =IF($A21="","",IF($M21="",0,$M21)+IF($N21="",0,$N21/$Q21)) | U21: =IF($A21="","",$H21-$S21) | W21: =IF($A21="","",IF($S21>=$H21-0.01,"Paid",IF($S21>0,"Partially Paid","Unpaid"))) | X21: =IF($A21="","",$F21-$I21) | Y21: =IF($A21="","",SUMIFS(Loans!$H$5:$H$44,Loans!$B$5:$B$44,$A21)) | Z21: =IF($A21="","",$X21-$Y21) | AA21: =IF(OR($A21="",$F21=0),"",$X21/$F21) | AB21: =IF($A21="","",IF($S21>=$H21-0.01,"Paid",IF(AND($S21>0,$J21<>"Yes"),"Advance Paid",IF($J21="Yes",IF(AND($E21<>"",TODAY()>$E21),"Overdue Payment","Awaiting Payment"),IF(AND($E21<>"",TODAY()>$E21),"Overdue Service","Open")))))
G22: =IF($F22="","",$F22*VATRate) | H22: =IF($F22="","",$F22+$G22) | I22: =IF($A22="","",SUMIFS(OrderExpenses!$G$5:$G$84,OrderExpenses!$B$5:$B$84,$A22)) | O22: =OffRate -> 26.5 | P22: =IF($N22="","",$N22/$O22) | Q22: =StreetRate -> 33 | R22: =IF($N22="","",$N22/$Q22) | S22: =IF($A22="","",IF($M22="",0,$M22)+IF($N22="",0,$N22/$O22)) | T22: =IF($A22="","",IF($M22="",0,$M22)+IF($N22="",0,$N22/$Q22)) | U22: =IF($A22="","",$H22-$S22) | W22: =IF($A22="","",IF($S22>=$H22-0.01,"Paid",IF($S22>0,"Partially Paid","Unpaid"))) | X22: =IF($A22="","",$F22-$I22) | Y22: =IF($A22="","",SUMIFS(Loans!$H$5:$H$44,Loans!$B$5:$B$44,$A22)) | Z22: =IF($A22="","",$X22-$Y22) | AA22: =IF(OR($A22="",$F22=0),"",$X22/$F22) | AB22: =IF($A22="","",IF($S22>=$H22-0.01,"Paid",IF(AND($S22>0,$J22<>"Yes"),"Advance Paid",IF($J22="Yes",IF(AND($E22<>"",TODAY()>$E22),"Overdue Payment","Awaiting Payment"),IF(AND($E22<>"",TODAY()>$E22),"Overdue Service","Open")))))
G23: =IF($F23="","",$F23*VATRate) | H23: =IF($F23="","",$F23+$G23) | I23: =IF($A23="","",SUMIFS(OrderExpenses!$G$5:$G$84,OrderExpenses!$B$5:$B$84,$A23)) | O23: =OffRate -> 26.5 | P23: =IF($N23="","",$N23/$O23) | Q23: =StreetRate -> 33 | R23: =IF($N23="","",$N23/$Q23) | S23: =IF($A23="","",IF($M23="",0,$M23)+IF($N23="",0,$N23/$O23)) | T23: =IF($A23="","",IF($M23="",0,$M23)+IF($N23="",0,$N23/$Q23)) | U23: =IF($A23="","",$H23-$S23) | W23: =IF($A23="","",IF($S23>=$H23-0.01,"Paid",IF($S23>0,"Partially Paid","Unpaid"))) | X23: =IF($A23="","",$F23-$I23) | Y23: =IF($A23="","",SUMIFS(Loans!$H$5:$H$44,Loans!$B$5:$B$44,$A23)) | Z23: =IF($A23="","",$X23-$Y23) | AA23: =IF(OR($A23="",$F23=0),"",$X23/$F23) | AB23: =IF($A23="","",IF($S23>=$H23-0.01,"Paid",IF(AND($S23>0,$J23<>"Yes"),"Advance Paid",IF($J23="Yes",IF(AND($E23<>"",TODAY()>$E23),"Overdue Payment","Awaiting Payment"),IF(AND($E23<>"",TODAY()>$E23),"Overdue Service","Open")))))
G24: =IF($F24="","",$F24*VATRate) | H24: =IF($F24="","",$F24+$G24) | I24: =IF($A24="","",SUMIFS(OrderExpenses!$G$5:$G$84,OrderExpenses!$B$5:$B$84,$A24)) | O24: =OffRate -> 26.5 | P24: =IF($N24="","",$N24/$O24) | Q24: =StreetRate -> 33 | R24: =IF($N24="","",$N24/$Q24) | S24: =IF($A24="","",IF($M24="",0,$M24)+IF($N24="",0,$N24/$O24)) | T24: =IF($A24="","",IF($M24="",0,$M24)+IF($N24="",0,$N24/$Q24)) | U24: =IF($A24="","",$H24-$S24) | W24: =IF($A24="","",IF($S24>=$H24-0.01,"Paid",IF($S24>0,"Partially Paid","Unpaid"))) | X24: =IF($A24="","",$F24-$I24) | Y24: =IF($A24="","",SUMIFS(Loans!$H$5:$H$44,Loans!$B$5:$B$44,$A24)) | Z24: =IF($A24="","",$X24-$Y24) | AA24: =IF(OR($A24="",$F24=0),"",$X24/$F24) | AB24: =IF($A24="","",IF($S24>=$H24-0.01,"Paid",IF(AND($S24>0,$J24<>"Yes"),"Advance Paid",IF($J24="Yes",IF(AND($E24<>"",TODAY()>$E24),"Overdue Payment","Awaiting Payment"),IF(AND($E24<>"",TODAY()>$E24),"Overdue Service","Open")))))
G25: =IF($F25="","",$F25*VATRate) | H25: =IF($F25="","",$F25+$G25) | I25: =IF($A25="","",SUMIFS(OrderExpenses!$G$5:$G$84,OrderExpenses!$B$5:$B$84,$A25)) | O25: =OffRate -> 26.5 | P25: =IF($N25="","",$N25/$O25) | Q25: =StreetRate -> 33 | R25: =IF($N25="","",$N25/$Q25) | S25: =IF($A25="","",IF($M25="",0,$M25)+IF($N25="",0,$N25/$O25)) | T25: =IF($A25="","",IF($M25="",0,$M25)+IF($N25="",0,$N25/$Q25)) | U25: =IF($A25="","",$H25-$S25) | W25: =IF($A25="","",IF($S25>=$H25-0.01,"Paid",IF($S25>0,"Partially Paid","Unpaid"))) | X25: =IF($A25="","",$F25-$I25) | Y25: =IF($A25="","",SUMIFS(Loans!$H$5:$H$44,Loans!$B$5:$B$44,$A25)) | Z25: =IF($A25="","",$X25-$Y25) | AA25: =IF(OR($A25="",$F25=0),"",$X25/$F25) | AB25: =IF($A25="","",IF($S25>=$H25-0.01,"Paid",IF(AND($S25>0,$J25<>"Yes"),"Advance Paid",IF($J25="Yes",IF(AND($E25<>"",TODAY()>$E25),"Overdue Payment","Awaiting Payment"),IF(AND($E25<>"",TODAY()>$E25),"Overdue Service","Open")))))
G26: =IF($F26="","",$F26*VATRate) | H26: =IF($F26="","",$F26+$G26) | I26: =IF($A26="","",SUMIFS(OrderExpenses!$G$5:$G$84,OrderExpenses!$B$5:$B$84,$A26)) | O26: =OffRate -> 26.5 | P26: =IF($N26="","",$N26/$O26) | Q26: =StreetRate -> 33 | R26: =IF($N26="","",$N26/$Q26) | S26: =IF($A26="","",IF($M26="",0,$M26)+IF($N26="",0,$N26/$O26)) | T26: =IF($A26="","",IF($M26="",0,$M26)+IF($N26="",0,$N26/$Q26)) | U26: =IF($A26="","",$H26-$S26) | W26: =IF($A26="","",IF($S26>=$H26-0.01,"Paid",IF($S26>0,"Partially Paid","Unpaid"))) | X26: =IF($A26="","",$F26-$I26) | Y26: =IF($A26="","",SUMIFS(Loans!$H$5:$H$44,Loans!$B$5:$B$44,$A26)) | Z26: =IF($A26="","",$X26-$Y26) | AA26: =IF(OR($A26="",$F26=0),"",$X26/$F26) | AB26: =IF($A26="","",IF($S26>=$H26-0.01,"Paid",IF(AND($S26>0,$J26<>"Yes"),"Advance Paid",IF($J26="Yes",IF(AND($E26<>"",TODAY()>$E26),"Overdue Payment","Awaiting Payment"),IF(AND($E26<>"",TODAY()>$E26),"Overdue Service","Open")))))
... G64: =IF($F64="","",$F64*VATRate) | H64: =IF($F64="","",$F64+$G64) | I64: =IF($A64="","",SUMIFS(OrderExpenses!$G$5:$G$84,OrderExpenses!$B$5:$B$84,$A64)) | O64: =OffRate -> 26.5 | P64: =IF($N64="","",$N64/$O64) | Q64: =StreetRate -> 33 | R64: =IF($N64="","",$N64/$Q64) | S64: =IF($A64="","",IF($M64="",0,$M64)+IF($N64="",0,$N64/$O64)) | T64: =IF($A64="","",IF($M64="",0,$M64)+IF($N64="",0,$N64/$Q64)) | U64: =IF($A64="","",$H64-$S64) | W64: =IF($A64="","",IF($S64>=$H64-0.01,"Paid",IF($S64>0,"Partially Paid","Unpaid"))) | X64: =IF($A64="","",$F64-$I64) | Y64: =IF($A64="","",SUMIFS(Loans!$H$5:$H$44,Loans!$B$5:$B$44,$A64)) | Z64: =IF($A64="","",$X64-$Y64) | AA64: =IF(OR($A64="",$F64=0),"",$X64/$F64) | AB64: =IF($A64="","",IF($S64>=$H64-0.01,"Paid",IF(AND($S64>0,$J64<>"Yes"),"Advance Paid",IF($J64="Yes",IF(AND($E64<>"",TODAY()>$E64),"Overdue Payment","Awaiting Payment"),IF(AND($E64<>"",TODAY()>$E64),"Overdue Service","Open")))))

Sheet OrderExpenses
A1: ORDER EXPENSES
A2: Costs tied to a specific order. Pick the Order No; title & client auto-fill. These feed 'Spent to Date' on Orders.
A4: Date | B4: Order No | C4: Order Title | D4: Client | E4: Description | F4: Category | G4: Amount ex VAT ($) | H4: VAT Paid? | I4: Input VAT ($) | J4: Total incl VAT ($) | K4: Notes
A5: 46152 | B5: AES-O-001 | C5: =IFERROR(VLOOKUP($B5,Orders!$A$5:$B$64,2,0),"") -> Underground ventilation doors (x10) | D5: =IFERROR(VLOOKUP($B5,Orders!$A$5:$C$64,3,0),"") -> Zimplats | E5: Steel sheets, frames & hinges | F5: Materials | G5: 6500 | H5: Yes | I5: =IF($G5="","",IF($H5="Yes",$G5*VATRate,0)) -> 1007.5 | J5: =IF($G5="","",$G5+IF($I5="",0,$I5)) -> 7507.5
A6: 46154 | B6: AES-O-001 | C6: =IFERROR(VLOOKUP($B6,Orders!$A$5:$B$64,2,0),"") -> Underground ventilation doors (x10) | D6: =IFERROR(VLOOKUP($B6,Orders!$A$5:$C$64,3,0),"") -> Zimplats | E6: Welding & fabrication labour | F6: Labour | G6: 1800 | H6: No | I6: =IF($G6="","",IF($H6="Yes",$G6*VATRate,0)) -> 0 | J6: =IF($G6="","",$G6+IF($I6="",0,$I6)) -> 1800
A7: 46167 | B7: AES-O-002 | C7: =IFERROR(VLOOKUP($B7,Orders!$A$5:$B$64,2,0),"") -> Safety explosive storage boxes (x6) | D7: =IFERROR(VLOOKUP($B7,Orders!$A$5:$C$64,3,0),"") -> Mimosa Mining | E7: Steel plate, locks & seals | F7: Materials | G7: 3200 | H7: Yes | I7: =IF($G7="","",IF($H7="Yes",$G7*VATRate,0)) -> 496 | J7: =IF($G7="","",$G7+IF($I7="",0,$I7)) -> 3696
A8: 46176 | B8: AES-O-003 | C8: =IFERROR(VLOOKUP($B8,Orders!$A$5:$B$64,2,0),"") -> Air sampling services - Q2 | D8: =IFERROR(VLOOKUP($B8,Orders!$A$5:$C$64,3,0),"") -> Unki Mine | E8: Sampling consumables & lab analysis | F8: Subcontract | G8: 1500 | H8: Yes | I8: =IF($G8="","",IF($H8="Yes",$G8*VATRate,0)) -> 232.5 | J8: =IF($G8="","",$G8+IF($I8="",0,$I8)) -> 1732.5
A9: 46122 | B9: AES-O-005 | C9: =IFERROR(VLOOKUP($B9,Orders!$A$5:$B$64,2,0),"") -> Safety explosive storage boxes x6 | D9: =IFERROR(VLOOKUP($B9,Orders!$A$5:$C$64,3,0),"") -> Zimplats | E9: Steel plate & locks | F9: Materials | G9: 9200 | H9: Yes | I9: =IF($G9="","",IF($H9="Yes",$G9*VATRate,0)) -> 1426 | J9: =IF($G9="","",$G9+IF($I9="",0,$I9)) -> 10626 | K9: Sample data
A10: 46130 | B10: AES-O-005 | C10: =IFERROR(VLOOKUP($B10,Orders!$A$5:$B$64,2,0),"") -> Safety explosive storage boxes x6 | D10: =IFERROR(VLOOKUP($B10,Orders!$A$5:$C$64,3,0),"") -> Zimplats | E10: Powder coating | F10: Subcontract | G10: 2100 | H10: Yes | I10: =IF($G10="","",IF($H10="Yes",$G10*VATRate,0)) -> 325.5 | J10: =IF($G10="","",$G10+IF($I10="",0,$I10)) -> 2425.5 | K10: Sample data
A11: 46132 | B11: AES-O-006 | C11: =IFERROR(VLOOKUP($B11,Orders!$A$5:$B$64,2,0),"") -> Air sampling services Q2 | D11: =IFERROR(VLOOKUP($B11,Orders!$A$5:$C$64,3,0),"") -> Mimosa Mining | E11: Sampling consumables | F11: Materials | G11: 1150 | H11: Yes | I11: =IF($G11="","",IF($H11="Yes",$G11*VATRate,0)) -> 178.25 | J11: =IF($G11="","",$G11+IF($I11="",0,$I11)) -> 1328.25 | K11: Sample data
A12: 46150 | B12: AES-O-007 | C12: =IFERROR(VLOOKUP($B12,Orders!$A$5:$B$64,2,0),"") -> Underground ventilation doors x4 | D12: =IFERROR(VLOOKUP($B12,Orders!$A$5:$C$64,3,0),"") -> Unki Mine | E12: Door frames & seals | F12: Materials | G12: 11800 | H12: Yes | I12: =IF($G12="","",IF($H12="Yes",$G12*VATRate,0)) -> 1829 | J12: =IF($G12="","",$G12+IF($I12="",0,$I12)) -> 13629 | K12: Sample data
A13: 46157 | B13: AES-O-007 | C13: =IFERROR(VLOOKUP($B13,Orders!$A$5:$B$64,2,0),"") -> Underground ventilation doors x4 | D13: =IFERROR(VLOOKUP($B13,Orders!$A$5:$C$64,3,0),"") -> Unki Mine | E13: Site installation labour | F13: Labour | G13: 5200 | H13: No | I13: =IF($G13="","",IF($H13="Yes",$G13*VATRate,0)) -> 0 | J13: =IF($G13="","",$G13+IF($I13="",0,$I13)) -> 5200 | K13: Sample data
A14: 46167 | B14: AES-O-008 | C14: =IFERROR(VLOOKUP($B14,Orders!$A$5:$B$64,2,0),"") -> Refuge chamber service kit | D14: =IFERROR(VLOOKUP($B14,Orders!$A$5:$C$64,3,0),"") -> Zimplats | E14: Filter cartridges | F14: Materials | G14: 1900 | H14: Yes | I14: =IF($G14="","",IF($H14="Yes",$G14*VATRate,0)) -> 294.5 | J14: =IF($G14="","",$G14+IF($I14="",0,$I14)) -> 2194.5 | K14: Sample data
A15: 46178 | B15: AES-O-009 | C15: =IFERROR(VLOOKUP($B15,Orders!$A$5:$B$64,2,0),"") -> Ducting fabrication 300m | D15: =IFERROR(VLOOKUP($B15,Orders!$A$5:$C$64,3,0),"") -> Mimosa Mining | E15: Galvanised sheeting | F15: Materials | G15: 8600 | H15: Yes | I15: =IF($G15="","",IF($H15="Yes",$G15*VATRate,0)) -> 1333 | J15: =IF($G15="","",$G15+IF($I15="",0,$I15)) -> 9933 | K15: Sample data
A16: 46185 | B16: AES-O-010 | C16: =IFERROR(VLOOKUP($B16,Orders!$A$5:$B$64,2,0),"") -> Airflow measurement audit | D16: =IFERROR(VLOOKUP($B16,Orders!$A$5:$C$64,3,0),"") -> Zvishavane Engineering Ltd | E16: Calibration hire | F16: Equipment | G16: 900 | H16: Yes | I16: =IF($G16="","",IF($H16="Yes",$G16*VATRate,0)) -> 139.5 | J16: =IF($G16="","",$G16+IF($I16="",0,$I16)) -> 1039.5 | K16: Sample data
C17: =IFERROR(VLOOKUP($B17,Orders!$A$5:$B$64,2,0),"") | D17: =IFERROR(VLOOKUP($B17,Orders!$A$5:$C$64,3,0),"") | I17: =IF($G17="","",IF($H17="Yes",$G17*VATRate,0)) | J17: =IF($G17="","",$G17+IF($I17="",0,$I17))
C18: =IFERROR(VLOOKUP($B18,Orders!$A$5:$B$64,2,0),"") | D18: =IFERROR(VLOOKUP($B18,Orders!$A$5:$C$64,3,0),"") | I18: =IF($G18="","",IF($H18="Yes",$G18*VATRate,0)) | J18: =IF($G18="","",$G18+IF($I18="",0,$I18))
C19: =IFERROR(VLOOKUP($B19,Orders!$A$5:$B$64,2,0),"") | D19: =IFERROR(VLOOKUP($B19,Orders!$A$5:$C$64,3,0),"") | I19: =IF($G19="","",IF($H19="Yes",$G19*VATRate,0)) | J19: =IF($G19="","",$G19+IF($I19="",0,$I19))
C20: =IFERROR(VLOOKUP($B20,Orders!$A$5:$B$64,2,0),"") | D20: =IFERROR(VLOOKUP($B20,Orders!$A$5:$C$64,3,0),"") | I20: =IF($G20="","",IF($H20="Yes",$G20*VATRate,0)) | J20: =IF($G20="","",$G20+IF($I20="",0,$I20))
C21: =IFERROR(VLOOKUP($B21,Orders!$A$5:$B$64,2,0),"") | D21: =IFERROR(VLOOKUP($B21,Orders!$A$5:$C$64,3,0),"") | I21: =IF($G21="","",IF($H21="Yes",$G21*VATRate,0)) | J21: =IF($G21="","",$G21+IF($I21="",0,$I21))
C22: =IFERROR(VLOOKUP($B22,Orders!$A$5:$B$64,2,0),"") | D22: =IFERROR(VLOOKUP($B22,Orders!$A$5:$C$64,3,0),"") | I22: =IF($G22="","",IF($H22="Yes",$G22*VATRate,0)) | J22: =IF($G22="","",$G22+IF($I22="",0,$I22))
C23: =IFERROR(VLOOKUP($B23,Orders!$A$5:$B$64,2,0),"") | D23: =IFERROR(VLOOKUP($B23,Orders!$A$5:$C$64,3,0),"") | I23: =IF($G23="","",IF($H23="Yes",$G23*VATRate,0)) | J23: =IF($G23="","",$G23+IF($I23="",0,$I23))
C24: =IFERROR(VLOOKUP($B24,Orders!$A$5:$B$64,2,0),"") | D24: =IFERROR(VLOOKUP($B24,Orders!$A$5:$C$64,3,0),"") | I24: =IF($G24="","",IF($H24="Yes",$G24*VATRate,0)) | J24: =IF($G24="","",$G24+IF($I24="",0,$I24))
C25: =IFERROR(VLOOKUP($B25,Orders!$A$5:$B$64,2,0),"") | D25: =IFERROR(VLOOKUP($B25,Orders!$A$5:$C$64,3,0),"") | I25: =IF($G25="","",IF($H25="Yes",$G25*VATRate,0)) | J25: =IF($G25="","",$G25+IF($I25="",0,$I25))
C26: =IFERROR(VLOOKUP($B26,Orders!$A$5:$B$64,2,0),"") | D26: =IFERROR(VLOOKUP($B26,Orders!$A$5:$C$64,3,0),"") | I26: =IF($G26="","",IF($H26="Yes",$G26*VATRate,0)) | J26: =IF($G26="","",$G26+IF($I26="",0,$I26))
C27: =IFERROR(VLOOKUP($B27,Orders!$A$5:$B$64,2,0),"") | D27: =IFERROR(VLOOKUP($B27,Orders!$A$5:$C$64,3,0),"") | I27: =IF($G27="","",IF($H27="Yes",$G27*VATRate,0)) | J27: =IF($G27="","",$G27+IF($I27="",0,$I27))
C28: =IFERROR(VLOOKUP($B28,Orders!$A$5:$B$64,2,0),"") | D28: =IFERROR(VLOOKUP($B28,Orders!$A$5:$C$64,3,0),"") | I28: =IF($G28="","",IF($H28="Yes",$G28*VATRate,0)) | J28: =IF($G28="","",$G28+IF($I28="",0,$I28))
... C84: =IFERROR(VLOOKUP($B84,Orders!$A$5:$B$64,2,0),"") | D84: =IFERROR(VLOOKUP($B84,Orders!$A$5:$C$64,3,0),"") | I84: =IF($G84="","",IF($H84="Yes",$G84*VATRate,0)) | J84: =IF($G84="","",$G84+IF($I84="",0,$I84))

Sheet GeneralExpenses
A1: GENERAL EXPENSES
A2: Operating costs NOT tied to any single order or contract. Comment is encouraged for the audit trail.
A4: Date | B4: Description | C4: Category | D4: Amount ex VAT ($) | E4: VAT Paid? | F4: Input VAT ($) | G4: Total incl VAT ($) | H4: Comment
A5: 46173 | B5: Office stationery & printing | C5: Admin | D5: 250 | E5: Yes | F5: =IF($D5="","",IF($E5="Yes",$D5*VATRate,0)) -> 38.75 | G5: =IF($D5="","",$D5+IF($F5="",0,$F5)) -> 288.75
A6: 46178 | B6: Vehicle fuel - site visits | C6: Transport | D6: 600 | E6: No | F6: =IF($D6="","",IF($E6="Yes",$D6*VATRate,0)) -> 0 | G6: =IF($D6="","",$D6+IF($F6="",0,$F6)) -> 600
A7: 46188 | B7: Bank charges | C7: Finance | D7: 180 | E7: No | F7: =IF($D7="","",IF($E7="Yes",$D7*VATRate,0)) -> 0 | G7: =IF($D7="","",$D7+IF($F7="",0,$F7)) -> 180
A8: 46145 | B8: Vehicle service - Hilux | C8: Transport | D8: 480 | E8: Yes | F8: =IF($D8="","",IF($E8="Yes",$D8*VATRate,0)) -> 74.4 | G8: =IF($D8="","",$D8+IF($F8="",0,$F8)) -> 554.4 | H8: Sample data
A9: 46175 | B9: PPE restock | C9: Safety | D9: 760 | E9: Yes | F9: =IF($D9="","",IF($E9="Yes",$D9*VATRate,0)) -> 117.8 | G9: =IF($D9="","",$D9+IF($F9="",0,$F9)) -> 877.8 | H9: Sample data
A10: 46193 | B10: Bank charges June | C10: Finance | D10: 95 | E10: No | F10: =IF($D10="","",IF($E10="Yes",$D10*VATRate,0)) -> 0 | G10: =IF($D10="","",$D10+IF($F10="",0,$F10)) -> 95 | H10: Sample data
F11: =IF($D11="","",IF($E11="Yes",$D11*VATRate,0)) | G11: =IF($D11="","",$D11+IF($F11="",0,$F11))
F12: =IF($D12="","",IF($E12="Yes",$D12*VATRate,0)) | G12: =IF($D12="","",$D12+IF($F12="",0,$F12))
F13: =IF($D13="","",IF($E13="Yes",$D13*VATRate,0)) | G13: =IF($D13="","",$D13+IF($F13="",0,$F13))
F14: =IF($D14="","",IF($E14="Yes",$D14*VATRate,0)) | G14: =IF($D14="","",$D14+IF($F14="",0,$F14))
F15: =IF($D15="","",IF($E15="Yes",$D15*VATRate,0)) | G15: =IF($D15="","",$D15+IF($F15="",0,$F15))
F16: =IF($D16="","",IF($E16="Yes",$D16*VATRate,0)) | G16: =IF($D16="","",$D16+IF($F16="",0,$F16))
F17: =IF($D17="","",IF($E17="Yes",$D17*VATRate,0)) | G17: =IF($D17="","",$D17+IF($F17="",0,$F17))
F18: =IF($D18="","",IF($E18="Yes",$D18*VATRate,0)) | G18: =IF($D18="","",$D18+IF($F18="",0,$F18))
F19: =IF($D19="","",IF($E19="Yes",$D19*VATRate,0)) | G19: =IF($D19="","",$D19+IF($F19="",0,$F19))
F20: =IF($D20="","",IF($E20="Yes",$D20*VATRate,0)) | G20: =IF($D20="","",$D20+IF($F20="",0,$F20))
F21: =IF($D21="","",IF($E21="Yes",$D21*VATRate,0)) | G21: =IF($D21="","",$D21+IF($F21="",0,$F21))
F22: =IF($D22="","",IF($E22="Yes",$D22*VATRate,0)) | G22: =IF($D22="","",$D22+IF($F22="",0,$F22))
... F44: =IF($D44="","",IF($E44="Yes",$D44*VATRate,0)) | G44: =IF($D44="","",$D44+IF($F44="",0,$F44))

Sheet Overheads
A1: MONTHLY OVERHEADS
A2: Recurring monthly costs. PAYE due & paid flow to the Tax page (balance carried automatically).
A4: Month | B4: Salaries ($) | C4: PAYE Due ($) | D4: PAYE Paid ($) | E4: PAYE Balance ($) | F4: Software ($) | G4: Internet ($) | H4: Rentals ($) | I4: Other ($) | J4: Input VAT ($) | K4: Total Overheads ($) | L4: Comment
A5: 46142 | B5: 8000 | C5: 1200 | D5: 1200 | E5: =IF($A5="","",IF($C5="",0,$C5)-IF($D5="",0,$D5)) -> 0 | F5: 300 | G5: 150 | H5: 1000 | I5: 200 | J5: 200 | K5: =IF($A5="","",IF($B5="",0,$B5)+IF($F5="",0,$F5)+IF($G5="",0,$G5)+IF($H5="",0,$H5)+IF($I5="",0,$I5)) -> 9650
A6: 46173 | B6: 8000 | C6: 1200 | D6: 600 | E6: =IF($A6="","",IF($C6="",0,$C6)-IF($D6="",0,$D6)) -> 600 | F6: 300 | G6: 150 | H6: 1000 | I6: 250 | J6: 200 | K6: =IF($A6="","",IF($B6="",0,$B6)+IF($F6="",0,$F6)+IF($G6="",0,$G6)+IF($H6="",0,$H6)+IF($I6="",0,$I6)) -> 9700
A7: 46203 | B7: 8500 | C7: 1300 | D7: 0 | E7: =IF($A7="","",IF($C7="",0,$C7)-IF($D7="",0,$D7)) -> 1300 | F7: 300 | G7: 150 | H7: 1000 | I7: 300 | J7: 200 | K7: =IF($A7="","",IF($B7="",0,$B7)+IF($F7="",0,$F7)+IF($G7="",0,$G7)+IF($H7="",0,$H7)+IF($I7="",0,$I7)) -> 10250
A8: 46142 | B8: 9200 | C8: 1380 | D8: 1380 | E8: =IF($A8="","",IF($C8="",0,$C8)-IF($D8="",0,$D8)) -> 0 | F8: 300 | G8: 150 | H8: 1000 | I8: 240 | J8: 210 | K8: =IF($A8="","",IF($B8="",0,$B8)+IF($F8="",0,$F8)+IF($G8="",0,$G8)+IF($H8="",0,$H8)+IF($I8="",0,$I8)) -> 10890 | L8: Sample data
A9: 46173 | B9: 9200 | C9: 1380 | D9: 900 | E9: =IF($A9="","",IF($C9="",0,$C9)-IF($D9="",0,$D9)) -> 480 | F9: 300 | G9: 150 | H9: 1000 | I9: 310 | J9: 205 | K9: =IF($A9="","",IF($B9="",0,$B9)+IF($F9="",0,$F9)+IF($G9="",0,$G9)+IF($H9="",0,$H9)+IF($I9="",0,$I9)) -> 10960 | L9: Sample data
A10: 46203 | B10: 9650 | C10: 1447 | D10: 0 | E10: =IF($A10="","",IF($C10="",0,$C10)-IF($D10="",0,$D10)) -> 1447 | F10: 300 | G10: 150 | H10: 1000 | I10: 180 | J10: 198 | K10: =IF($A10="","",IF($B10="",0,$B10)+IF($F10="",0,$F10)+IF($G10="",0,$G10)+IF($H10="",0,$H10)+IF($I10="",0,$I10)) -> 11280 | L10: Sample data
E11: =IF($A11="","",IF($C11="",0,$C11)-IF($D11="",0,$D11)) | K11: =IF($A11="","",IF($B11="",0,$B11)+IF($F11="",0,$F11)+IF($G11="",0,$G11)+IF($H11="",0,$H11)+IF($I11="",0,$I11))
E12: =IF($A12="","",IF($C12="",0,$C12)-IF($D12="",0,$D12)) | K12: =IF($A12="","",IF($B12="",0,$B12)+IF($F12="",0,$F12)+IF($G12="",0,$G12)+IF($H12="",0,$H12)+IF($I12="",0,$I12))
E13: =IF($A13="","",IF($C13="",0,$C13)-IF($D13="",0,$D13)) | K13: =IF($A13="","",IF($B13="",0,$B13)+IF($F13="",0,$F13)+IF($G13="",0,$G13)+IF($H13="",0,$H13)+IF($I13="",0,$I13))
E14: =IF($A14="","",IF($C14="",0,$C14)-IF($D14="",0,$D14)) | K14: =IF($A14="","",IF($B14="",0,$B14)+IF($F14="",0,$F14)+IF($G14="",0,$G14)+IF($H14="",0,$H14)+IF($I14="",0,$I14))
E15: =IF($A15="","",IF($C15="",0,$C15)-IF($D15="",0,$D15)) | K15: =IF($A15="","",IF($B15="",0,$B15)+IF($F15="",0,$F15)+IF($G15="",0,$G15)+IF($H15="",0,$H15)+IF($I15="",0,$I15))
E16: =IF($A16="","",IF($C16="",0,$C16)-IF($D16="",0,$D16)) | K16: =IF($A16="","",IF($B16="",0,$B16)+IF($F16="",0,$F16)+IF($G16="",0,$G16)+IF($H16="",0,$H16)+IF($I16="",0,$I16))
E17: =IF($A17="","",IF($C17="",0,$C17)-IF($D17="",0,$D17)) | K17: =IF($A17="","",IF($B17="",0,$B17)+IF($F17="",0,$F17)+IF($G17="",0,$G17)+IF($H17="",0,$H17)+IF($I17="",0,$I17))
E18: =IF($A18="","",IF($C18="",0,$C18)-IF($D18="",0,$D18)) | K18: =IF($A18="","",IF($B18="",0,$B18)+IF($F18="",0,$F18)+IF($G18="",0,$G18)+IF($H18="",0,$H18)+IF($I18="",0,$I18))
E19: =IF($A19="","",IF($C19="",0,$C19)-IF($D19="",0,$D19)) | K19: =IF($A19="","",IF($B19="",0,$B19)+IF($F19="",0,$F19)+IF($G19="",0,$G19)+IF($H19="",0,$H19)+IF($I19="",0,$I19))
E20: =IF($A20="","",IF($C20="",0,$C20)-IF($D20="",0,$D20)) | K20: =IF($A20="","",IF($B20="",0,$B20)+IF($F20="",0,$F20)+IF($G20="",0,$G20)+IF($H20="",0,$H20)+IF($I20="",0,$I20))
E21: =IF($A21="","",IF($C21="",0,$C21)-IF($D21="",0,$D21)) | K21: =IF($A21="","",IF($B21="",0,$B21)+IF($F21="",0,$F21)+IF($G21="",0,$G21)+IF($H21="",0,$H21)+IF($I21="",0,$I21))
E22: =IF($A22="","",IF($C22="",0,$C22)-IF($D22="",0,$D22)) | K22: =IF($A22="","",IF($B22="",0,$B22)+IF($F22="",0,$F22)+IF($G22="",0,$G22)+IF($H22="",0,$H22)+IF($I22="",0,$I22))
... E44: =IF($A44="","",IF($C44="",0,$C44)-IF($D44="",0,$D44)) | K44: =IF($A44="","",IF($B44="",0,$B44)+IF($F44="",0,$F44)+IF($G44="",0,$G44)+IF($H44="",0,$H44)+IF($I44="",0,$I44))

Sheet Loans
A1: LOANS
A2: All loans in USD. Interest = principal x weekly rate x weeks elapsed. Repayments accepted in USD and/or ZiG.
A4: Loan ID | B4: Order No | C4: Lender | D4: Date Taken | E4: Principal ($) | F4: Weekly Rate | G4: Weeks Elapsed | H4: Interest Accrued ($) | I4: Total Due ($) | J4: Paid USD (direct) | K4: Paid ZiG | L4: Paid USD @Official ($) | M4: Balance ($) | N4: Status | O4: Notes
A5: LN-01 | B5: AES-O-001 | C5: QuickCash Lender | D5: 46150 | E5: 5000 | F5: 0.05 | G5: =IF($D5="","",(TODAY()-$D5)/7) -> 11 | H5: =IF($E5="","",$E5*$F5*$G5) -> 2750 | I5: =IF($E5="","",$E5+$H5) -> 7750 | J5: 2000 | K5: 0 | L5: =IF($A5="","",IF($J5="",0,$J5)+IF($K5="",0,$K5/OffRate)) -> 2000 | M5: =IF($A5="","",$I5-$L5) -> 5750 | N5: =IF($A5="","",IF($M5<=0.01,"Settled","Outstanding")) -> Outstanding
A6: LN-02 | B6: AES-O-002 | C6: QuickCash Lender | D6: 46164 | E6: 3000 | F6: 0.05 | G6: =IF($D6="","",(TODAY()-$D6)/7) -> 9 | H6: =IF($E6="","",$E6*$F6*$G6) -> 1350 | I6: =IF($E6="","",$E6+$H6) -> 4350 | J6: 0 | K6: 0 | L6: =IF($A6="","",IF($J6="",0,$J6)+IF($K6="",0,$K6/OffRate)) -> 0 | M6: =IF($A6="","",$I6-$L6) -> 4350 | N6: =IF($A6="","",IF($M6<=0.01,"Settled","Outstanding")) -> Outstanding
A7: LN-03 | B7: AES-O-004 | C7: Trade Finance Co | D7: 46183 | E7: 8000 | F7: 0.04 | G7: =IF($D7="","",(TODAY()-$D7)/7) -> 6.2857143 | H7: =IF($E7="","",$E7*$F7*$G7) -> 2011.4286 | I7: =IF($E7="","",$E7+$H7) -> 10011.429 | J7: 0 | K7: 0 | L7: =IF($A7="","",IF($J7="",0,$J7)+IF($K7="",0,$K7/OffRate)) -> 0 | M7: =IF($A7="","",$I7-$L7) -> 10011.429 | N7: =IF($A7="","",IF($M7<=0.01,"Settled","Outstanding")) -> Outstanding
A8: LN-04 | B8: AES-O-007 | C8: Bridge Capital (sample) | D8: 46152 | E8: 12000 | F8: 0.04 | G8: =IF($D8="","",(TODAY()-$D8)/7) -> 10.714286 | H8: =IF($E8="","",$E8*$F8*$G8) -> 5142.8571 | I8: =IF($E8="","",$E8+$H8) -> 17142.857 | J8: 4000 | K8: 0 | L8: =IF($A8="","",IF($J8="",0,$J8)+IF($K8="",0,$K8/OffRate)) -> 4000 | M8: =IF($A8="","",$I8-$L8) -> 13142.857 | N8: =IF($A8="","",IF($M8<=0.01,"Settled","Outstanding")) -> Outstanding | O8: Sample data
A9: LN-05 | B9: AES-O-009 | C9: QuickCash Lender | D9: 46178 | E9: 8000 | F9: 0.05 | G9: =IF($D9="","",(TODAY()-$D9)/7) -> 7 | H9: =IF($E9="","",$E9*$F9*$G9) -> 2800 | I9: =IF($E9="","",$E9+$H9) -> 10800 | J9: 0 | K9: 0 | L9: =IF($A9="","",IF($J9="",0,$J9)+IF($K9="",0,$K9/OffRate)) -> 0 | M9: =IF($A9="","",$I9-$L9) -> 10800 | N9: =IF($A9="","",IF($M9<=0.01,"Settled","Outstanding")) -> Outstanding | O9: Sample data
G10: =IF($D10="","",(TODAY()-$D10)/7) | H10: =IF($E10="","",$E10*$F10*$G10) | I10: =IF($E10="","",$E10+$H10) | L10: =IF($A10="","",IF($J10="",0,$J10)+IF($K10="",0,$K10/OffRate)) | M10: =IF($A10="","",$I10-$L10) | N10: =IF($A10="","",IF($M10<=0.01,"Settled","Outstanding"))
G11: =IF($D11="","",(TODAY()-$D11)/7) | H11: =IF($E11="","",$E11*$F11*$G11) | I11: =IF($E11="","",$E11+$H11) | L11: =IF($A11="","",IF($J11="",0,$J11)+IF($K11="",0,$K11/OffRate)) | M11: =IF($A11="","",$I11-$L11) | N11: =IF($A11="","",IF($M11<=0.01,"Settled","Outstanding"))
G12: =IF($D12="","",(TODAY()-$D12)/7) | H12: =IF($E12="","",$E12*$F12*$G12) | I12: =IF($E12="","",$E12+$H12) | L12: =IF($A12="","",IF($J12="",0,$J12)+IF($K12="",0,$K12/OffRate)) | M12: =IF($A12="","",$I12-$L12) | N12: =IF($A12="","",IF($M12<=0.01,"Settled","Outstanding"))
G13: =IF($D13="","",(TODAY()-$D13)/7) | H13: =IF($E13="","",$E13*$F13*$G13) | I13: =IF($E13="","",$E13+$H13) | L13: =IF($A13="","",IF($J13="",0,$J13)+IF($K13="",0,$K13/OffRate)) | M13: =IF($A13="","",$I13-$L13) | N13: =IF($A13="","",IF($M13<=0.01,"Settled","Outstanding"))
G14: =IF($D14="","",(TODAY()-$D14)/7) | H14: =IF($E14="","",$E14*$F14*$G14) | I14: =IF($E14="","",$E14+$H14) | L14: =IF($A14="","",IF($J14="",0,$J14)+IF($K14="",0,$K14/OffRate)) | M14: =IF($A14="","",$I14-$L14) | N14: =IF($A14="","",IF($M14<=0.01,"Settled","Outstanding"))
G15: =IF($D15="","",(TODAY()-$D15)/7) | H15: =IF($E15="","",$E15*$F15*$G15) | I15: =IF($E15="","",$E15+$H15) | L15: =IF($A15="","",IF($J15="",0,$J15)+IF($K15="",0,$K15/OffRate)) | M15: =IF($A15="","",$I15-$L15) | N15: =IF($A15="","",IF($M15<=0.01,"Settled","Outstanding"))
G16: =IF($D16="","",(TODAY()-$D16)/7) | H16: =IF($E16="","",$E16*$F16*$G16) | I16: =IF($E16="","",$E16+$H16) | L16: =IF($A16="","",IF($J16="",0,$J16)+IF($K16="",0,$K16/OffRate)) | M16: =IF($A16="","",$I16-$L16) | N16: =IF($A16="","",IF($M16<=0.01,"Settled","Outstanding"))
G17: =IF($D17="","",(TODAY()-$D17)/7) | H17: =IF($E17="","",$E17*$F17*$G17) | I17: =IF($E17="","",$E17+$H17) | L17: =IF($A17="","",IF($J17="",0,$J17)+IF($K17="",0,$K17/OffRate)) | M17: =IF($A17="","",$I17-$L17) | N17: =IF($A17="","",IF($M17<=0.01,"Settled","Outstanding"))
G18: =IF($D18="","",(TODAY()-$D18)/7) | H18: =IF($E18="","",$E18*$F18*$G18) | I18: =IF($E18="","",$E18+$H18) | L18: =IF($A18="","",IF($J18="",0,$J18)+IF($K18="",0,$K18/OffRate)) | M18: =IF($A18="","",$I18-$L18) | N18: =IF($A18="","",IF($M18<=0.01,"Settled","Outstanding"))
G19: =IF($D19="","",(TODAY()-$D19)/7) | H19: =IF($E19="","",$E19*$F19*$G19) | I19: =IF($E19="","",$E19+$H19) | L19: =IF($A19="","",IF($J19="",0,$J19)+IF($K19="",0,$K19/OffRate)) | M19: =IF($A19="","",$I19-$L19) | N19: =IF($A19="","",IF($M19<=0.01,"Settled","Outstanding"))
G20: =IF($D20="","",(TODAY()-$D20)/7) | H20: =IF($E20="","",$E20*$F20*$G20) | I20: =IF($E20="","",$E20+$H20) | L20: =IF($A20="","",IF($J20="",0,$J20)+IF($K20="",0,$K20/OffRate)) | M20: =IF($A20="","",$I20-$L20) | N20: =IF($A20="","",IF($M20<=0.01,"Settled","Outstanding"))
G21: =IF($D21="","",(TODAY()-$D21)/7) | H21: =IF($E21="","",$E21*$F21*$G21) | I21: =IF($E21="","",$E21+$H21) | L21: =IF($A21="","",IF($J21="",0,$J21)+IF($K21="",0,$K21/OffRate)) | M21: =IF($A21="","",$I21-$L21) | N21: =IF($A21="","",IF($M21<=0.01,"Settled","Outstanding"))
... G44: =IF($D44="","",(TODAY()-$D44)/7) | H44: =IF($E44="","",$E44*$F44*$G44) | I44: =IF($E44="","",$E44+$H44) | L44: =IF($A44="","",IF($J44="",0,$J44)+IF($K44="",0,$K44/OffRate)) | M44: =IF($A44="","",$I44-$L44) | N44: =IF($A44="","",IF($M44<=0.01,"Settled","Outstanding"))

Sheet ContractPayments
A1: CONTRACT PAYMENTS (MONTHLY)
