Workbook

Sheet Paysheet
J1: tax ratio | S1: 6926.5764 | AI1: Rate | AJ1: 6926.5764 | AR1: Rate | AS1: 6926.5764
C2: Exchange rate 6926.5764 | J2: USD/ZWL | P2: Basic | T2: Allowances | W2: ZWL ALLOWANCES | AE2: CILL | AF2: Bonus | AG2: USD/ZWL | AH2: Gross | AK2: Allowable Deductions | AQ2: Taxable Income | AS2: Total Taxable in | AT2: PAYE in | AU2: Tax Credits | AV2: Net PAYE | AW2: PAYE USD | AY2: PAYE ZWL | BA2: Salary After Tax | BC2: Other Deductions | BL2: Net Salary | BO2: Tax Table USD | BU2: ZWL | BX2: USD | CA2: Leave Days
A3: Works # | B3: Netsai | C3: Nhemachena | D3: National 78-171262Y32 | E3: Pay Date | F3: Station | G3: Occupation | H3: Grade | I3: NSSA Number | J3: RATIO | K3: Period | L3: Hours | M3: Rate/hr | N3: UG Shifts | O3: NS Hours | P3: USD NEC | Q3: USD | R3: ZWL Basic | S3: Total | T3: Housing | U3: Underground | V3: Night Shift USD | W3: Food | X3: Airtime | Y3: Overtime @2 | Z3: Overtime @1.5 | AA3: Hours @2 | AB3: Hours @1.5 | AC3: Days sold | AD3: Gratuity | AE3: USD | AF3: USD | AG3: Ratio | AH3: Total | AI3: usd | AJ3: ZWL | AK3: NSSA | AL3: NSSA USD | AM3: NSSA ZWL | AN3: MIPF | AO3: NEC | AP3: Non Taxable Bonus | AQ3: USD | AR3: ZWL | AS3: USD | AT3: USD | AU3: USD | AV3: USD | AW3: PAYE | AX3: AIDS LEVY | AY3: PAYE | AZ3: AIDS LEVY | BA3: USD | BB3: ZWL | BC3: Nyaradzo | BD3: CBZ Life | BE3: Maint ZWL | BF3: Maint USD | BG3: Funeral Assist ZWL | BH3: Loan Repayment ZWL | BI3: Loan Repayment USD | BJ3: Funeral USD | BK3: May Day (USD) | BL3: USD | BM3: ZWL | BN3: 0-100 | BO3: 100.01-300 | BP3: 300.01-1000 | BQ3: 1000.01-2000 | BR3: 2000.01-3000 | BS3: 3000 and Above | BT3: Total | BU3: Bank | BV3: Branch | BW3: Account Number | BX3: Bank | BY3: Branch | BZ3: Account Number | CA3: Opening | CB3: Acrued | CC3: Taken | CD3: Closing
A4: AES-E050 | B4: Clever | C4: Chakabva | D4: 17-934904V07 | E4: 45107 | F4: Unki | G4: Site Manager | H4: 4.13 | I4: 3030113H | J4: =AQ4/AS4 -> 0.30021351 | K4: 5/2023 | L4: 210 | M4: =823.37/208 -> 3.9585096 | N4: 22 | P4: =L4*M4 -> 831.28702 | Q4: =P4*0.3 -> 249.38611 | R4: =P4*0.7*$S$1 -> 4030581.1 | S4: =P4*$S$1 -> 5757973 | T4: =P4*0.25 -> 207.82175 | U4: =M4*N4*8*0.05 -> 34.834885 | V4: =M4*O4*0.1 -> 0 | W4: 10000 | X4: 2000 | Y4: =AA4*M4*2 -> 0 | Z4: =AB4*M4*1.5 -> 0 | AE4: =M4*8*AC4 -> 0 | AG4: =AQ4/AS4 -> 0.30021351 | AH4: =(AI4*$AJ$1)+AJ4 -> 7450752.8 | AI4: =Q4+(T4+U4+V4+Y4+Z4+AE4)*0.3 -> 322.1831 | AJ4: =R4+((+T4+U4+V4+Y4+Z4+AE4)*0.7)*$AJ$1+W4+X4 -> 5219127 | AK4: =IF(S4>518239,0.045*518239,S4*0.045) -> 23320.755 | AL4: =(AK4*0.3)/$AS$1 -> 1.0100555 | AM4: =(AK4*0.7) -> 16324.529 | AO4: =(S4*0.003) -> 17273.919 | AP4: =IF(AF4>320,320,AF4) -> 0 | AQ4: =AI4-AP4-AL4 -> 321.17304 | AR4: =AJ4-AM4-AN4-AO4-BD4 -> 5185528.5 | AS4: =AQ4+(AR4/$AS$1) -> 1069.8154 | AT4: =BT4 -> 235.94462 | AV4: =AT4-AU4 -> 235.94462 | AW4: =AV4*AG4 -> 70.833764 | AX4: =AW4*0.03 -> 2.1250129 | AY4: =(AV4-AW4)*$AS$1 -> 1143653 | AZ4: =AY4*0.03 -> 34309.589 | BA4: =AQ4-AW4-AX4 -> 248.21427 | BB4: =AR4-AY4-AZ4 -> 4007566 | BC4: 31051.59 | BG4: 0 | BL4: =BA4-BK4-BI4-BJ4-BF4 -> 248.21427 | BM4: =BB4-BC4-BE4-BG4-BH4 -> 3976514.4 | BN4: =IF(AS4<100,0,0) -> 0 | BO4: =IF(AS4<70,"",IF(AS4<=300,AS4*0.2-20,)) -> 0 | BP4: =IF(AS4<300.01,"",IF(AS4<=1000,AS4*0.25-35,)) -> 0 | BQ4: =IF(AS4<1000.01,"",IF(AS4<=2000,AS4*0.3-85,)) -> 235.94462 | BR4: =IF(AS4<2000.01,"",IF(AS4<=3000,AS4*0.35-185,)) | BS4: =IF(AS4<3000.01,"",IF(AS4>3000,AS4*0.4-335,)) | BT4: =SUM(BN4:BS4) -> 235.94462 | BU4: FBC | BV4: Gweru | BW4: 2212772367295 | BX4: FBC | BY4: Gweru | BZ4: 1220508908844 | CA4: 11.3 | CB4: 2.5 | CC4: 0 | CD4: =CA4+CB4-CC4 -> 13.8
A5: AES-E052 | B5: Tatenda | C5: Masuku | D5: 55-962276R15 | E5: =E4 -> 45107 | F5: =F4 -> Unki | G5: Builder | H5: 4.7 | I5: 2651177B | J5: =AQ5/AS5 -> 0.3007027 | K5: =K4 -> 5/2023 | L5: 210 | M5: =410.34/208 -> 1.9727885 | N5: 22 | P5: =L5*M5 -> 414.28558 | Q5: =P5*0.3 -> 124.28567 | R5: =P5*0.7*$S$1 -> 2008706.5 | S5: =P5*$S$1 -> 2869580.7 | T5: =P5*0.25 -> 103.57139 | U5: =M5*N5*8*0.05 -> 17.360538 | V5: =M5*O5*0.1 -> 0 | Y5: =AA5*M5*2 -> 0 | Z5: =AB5*M5*1.5 -> 0 | AE5: =M5*8*AC5 -> 0 | AG5: =AQ5/AS5 -> 0.3007027 | AH5: =(AI5*$AJ$1)+AJ5 -> 3707225 | AI5: =Q5+(T5+U5+V5+Y5+Z5+AE5)*0.3 -> 160.56525 | AJ5: =R5+((+T5+U5+V5+Y5+Z5+AE5)*0.7)*$AJ$1+W5+X5 -> 2595057.5 | AK5: =IF(S5>518239,0.045*518239,S5*0.045) -> 23320.755 | AL5: =(AK5*0.3)/$AS$1 -> 1.0100555 | AM5: =(AK5*0.7) -> 16324.529 | AO5: =(S5*0.003) -> 8608.7421 | AP5: =IF(AF5>320,320,AF5) -> 0 | AQ5: =AI5-AP5-AL5 -> 159.5552 | AR5: =AJ5-AM5-AN5-AO5-BD5 -> 2570124.2 | AS5: =AQ5+(AR5/$AS$1) -> 530.6078 | AT5: =BT5 -> 97.65195 | AU5: 0 | AV5: =AT5-AU5 -> 97.65195 | AW5: =AV5*AG5 -> 29.364205 | AX5: =AW5*0.03 -> 0.88092615 | AY5: =(AV5-AW5)*$AS$1 -> 473000.29 | AZ5: =AY5*0.03 -> 14190.009 | BA5: =AQ5-AW5-AX5 -> 129.31007 | BB5: =AR5-AY5-AZ5 -> 2082933.9 | BG5: 0 | BL5: =BA5-BK5-BI5-BJ5-BF5 -> 129.31007 | BM5: =BB5-BC5-BE5-BG5-BH5 -> 2082933.9 | BN5: =IF(AS5<100,0,0) -> 0 | BO5: =IF(AS5<70,"",IF(AS5<=300,AS5*0.2-20,)) -> 0 | BP5: =IF(AS5<300.01,"",IF(AS5<=1000,AS5*0.25-35,)) -> 97.65195 | BQ5: =IF(AS5<1000.01,"",IF(AS5<=2000,AS5*0.3-85,)) | BR5: =IF(AS5<2000.01,"",IF(AS5<=3000,AS5*0.35-185,)) | BS5: =IF(AS5<3000.01,"",IF(AS5>3000,AS5*0.4-335,)) | BT5: =SUM(BN5:BS5) -> 97.65195 | BU5: FBC | BV5: Gweru | BW5: 8658583780750 | BX5: FBC | BY5: Gweru | BZ5: 5753027522713 | CA5: 12.06 | CB5: 2.5 | CC5: 0 | CD5: =CA5+CB5-CC5 -> 14.56
A6: AES-E051 | B6: Kupakwashe | C6: Matongo | D6: 70-912270R61 | E6: =E5 -> 45107 | F6: =F5 -> Unki | G6: Construction Assistant | H6: 4.3 | I6: 7264956Q | J6: =AQ6/AS6 -> 0.30066759 | K6: =K5 -> 5/2023 | L6: 220 | M6: =359.3/208 -> 1.7274038 | N6: 23 | P6: =L6*M6 -> 380.02885 | Q6: =P6*0.3 -> 114.00865 | R6: =P6*0.7*$S$1 -> 1842609.2 | S6: =P6*$S$1 -> 2632298.8 | T6: =P6*0.25 -> 95.007212 | U6: =M6*N6*8*0.05 -> 15.892115 | V6: =M6*O6*0.1 -> 0 | Y6: =AA6*M6*2 -> 0 | Z6: =AB6*M6*1.5 -> 25.911058 | AB6: 10 | AE6: =M6*8*AC6 -> 0 | AG6: =AQ6/AS6 -> 0.30066759 | AH6: =(AI6*$AJ$1)+AJ6 -> 3579926.4 | AI6: =Q6+(T6+U6+V6+Y6+Z6+AE6)*0.3 -> 155.05177 | AJ6: =R6+((+T6+U6+V6+Y6+Z6+AE6)*0.7)*$AJ$1+W6+X6 -> 2505948.5 | AK6: =IF(S6>518239,0.045*518239,S6*0.045) -> 23320.755 | AL6: =(AK6*0.3)/$AS$1 -> 1.0100555 | AM6: =(AK6*0.7) -> 16324.529 | AO6: =S6*0.003 -> 7896.8965 | AP6: =IF(AF6>320,320,AF6) -> 0 | AQ6: =AI6-AP6-AL6 -> 154.04171 | AR6: =AJ6-AM6-AN6-AO6-BD6 -> 2481727.1 | AS6: =AQ6+(AR6/$AS$1) -> 512.33229 | AT6: =BT6 -> 93.083073 | AU6: 0 | AV6: =AT6-AU6 -> 93.083073 | AW6: =AV6*AG6 -> 27.987063 | AX6: =AW6*0.03 -> 0.83961189 | AY6: =(AV6-AW6)*$AS$1 -> 450892.49 | AZ6: =AY6*0.03 -> 13526.775 | BA6: =AQ6-AW6-AX6 -> 125.21504 | BB6: =AR6-AY6-AZ6 -> 2017307.8 | BG6: 0 | BK6: 10 | BL6: =BA6-BK6-BI6-BJ6-BF6 -> 115.21504 | BM6: =BB6-BC6-BE6-BG6-BH6 -> 2017307.8 | BN6: =IF(AS6<100,0,0) -> 0 | BO6: =IF(AS6<70,"",IF(AS6<=300,AS6*0.2-20,)) -> 0 | BP6: =IF(AS6<300.01,"",IF(AS6<=1000,AS6*0.25-35,)) -> 93.083073 | BQ6: =IF(AS6<1000.01,"",IF(AS6<=2000,AS6*0.3-85,)) | BR6: =IF(AS6<2000.01,"",IF(AS6<=3000,AS6*0.35-185,)) | BS6: =IF(AS6<3000.01,"",IF(AS6>3000,AS6*0.4-335,)) | BT6: =SUM(BN6:BS6) -> 93.083073 | BU6: FBC | BV6: Gweru | BW6: 6670509580791 | BX6: FBC | BY6: Gweru | BZ6: 5320100212640 | CA6: 12.3 | CB6: 2.5 | CC6: 0 | CD6: =CA6+CB6-CC6 -> 14.8
A7: AES-E053 | B7: Panashe | C7: Gorejena | D7: 13-392477Q33 | E7: =E6 -> 45107 | F7: =F6 -> Unki | G7: Team Leader | H7: 4.9 | I7: 8835373B | J7: =AQ7/AS7 -> 0.30070221 | K7: =K6 -> 5/2023 | L7: 182 | M7: =542.14/208 -> 2.6064423 | N7: 19 | P7: =L7*M7 -> 474.3725 | Q7: =P7*0.3 -> 142.31175 | R7: =P7*0.7*$S$1 -> 2300044.2 | S7: =P7*$S$1 -> 3285777.4 | T7: =P7*0.25 -> 118.59313 | U7: =M7*N7*8*0.05 -> 19.808962 | V7: =M7*O7*0.1 -> 0 | Y7: =AA7*M7*2 -> 0 | Z7: =AB7*M7*1.5 -> 0 | AE7: =M7*8*AC7 -> 0 | AG7: =AQ7/AS7 -> 0.30070221 | AH7: =(AI7*$AJ$1)+AJ7 -> 4244430 | AI7: =Q7+(T7+U7+V7+Y7+Z7+AE7)*0.3 -> 183.83238 | AJ7: =R7+((+T7+U7+V7+Y7+Z7+AE7)*0.7)*$AJ$1+W7+X7 -> 2971101 | AK7: =IF(S7>518239,0.045*518239,S7*0.045) -> 23320.755 | AL7: =(AK7*0.3)/$AS$1 -> 1.0100555 | AM7: =(AK7*0.7) -> 16324.529 | AO7: =(S7*0.003) -> 9857.3321 | AP7: =IF(AF7>320,320,AF7) -> 0 | AQ7: =AI7-AP7-AL7 -> 182.82232 | AR7: =AJ7-AM7-AN7-AO7-BD7 -> 2944919.1 | AS7: =AQ7+(AR7/$AS$1) -> 607.98462 | AT7: =BT7 -> 116.99615 | AU7: 0 | AV7: =AT7-AU7 -> 116.99615 | AW7: =AV7*AG7 -> 35.181003 | AX7: =AW7*0.03 -> 1.0554301 | AY7: =(AV7-AW7)*$AS$1 -> 566698.9 | AZ7: =AY7*0.03 -> 17000.967 | BA7: =AQ7-AW7-AX7 -> 146.58589 | BB7: =AR7-AY7-AZ7 -> 2361219.3 | BG7: 0 | BL7: =BA7-BK7-BI7-BJ7-BF7 -> 146.58589 | BM7: =BB7-BC7-BE7-BG7-BH7 -> 2361219.3 | BN7: =IF(AS7<100,0,0) -> 0 | BO7: =IF(AS7<70,"",IF(AS7<=300,AS7*0.2-20,)) -> 0 | BP7: =IF(AS7<300.01,"",IF(AS7<=1000,AS7*0.25-35,)) -> 116.99615 | BQ7: =IF(AS7<1000.01,"",IF(AS7<=2000,AS7*0.3-85,)) | BR7: =IF(AS7<2000.01,"",IF(AS7<=3000,AS7*0.35-185,)) | BS7: =IF(AS7<3000.01,"",IF(AS7>3000,AS7*0.4-335,)) | BT7: =SUM(BN7:BS7) -> 116.99615 | BU7: NMB | BV7: Gweru | BW7: 9176546035391 | BX7: FBC | BY7: Gweru | BZ7: 7668659091022 | CA7: 12.3 | CB7: 2.5 | CC7: 3 | CD7: =CA7+CB7-CC7 -> 11.8
A8: AES-E054 | B8: Tapiwa | C8: Shumba | D8: 45-130094R43 | E8: =E7 -> 45107 | F8: =F7 -> Unki | G8: Construction Assistant | H8: 4.3 | I8: 3762152N | J8: =AQ8/AS8 -> 0.3007027 | K8: =K7 -> 5/2023 | L8: 210 | M8: =410.34/208 -> 1.9727885 | N8: 22 | P8: =L8*M8 -> 414.28558 | Q8: =P8*0.3 -> 124.28567 | R8: =P8*0.7*$S$1 -> 2008706.5 | S8: =P8*$S$1 -> 2869580.7 | T8: =P8*0.25 -> 103.57139 | U8: =M8*N8*8*0.05 -> 17.360538 | V8: =M8*O8*0.1 -> 0 | Y8: =AA8*M8*2 -> 0 | Z8: =AB8*M8*1.5 -> 0 | AE8: =M8*8*AC8 -> 0 | AG8: =AQ8/AS8 -> 0.3007027 | AH8: =(AI8*$AJ$1)+AJ8 -> 3707225 | AI8: =Q8+(T8+U8+V8+Y8+Z8+AE8)*0.3 -> 160.56525 | AJ8: =R8+((+T8+U8+V8+Y8+Z8+AE8)*0.7)*$AJ$1+W8+X8 -> 2595057.5 | AK8: =IF(S8>518239,0.045*518239,S8*0.045) -> 23320.755 | AL8: =(AK8*0.3)/$AS$1 -> 1.0100555 | AM8: =(AK8*0.7) -> 16324.529 | AO8: =S8*0.003 -> 8608.7421 | AP8: =IF(AF8>320,320,AF8) -> 0 | AQ8: =AI8-AP8-AL8 -> 159.5552 | AR8: =AJ8-AM8-AN8-AO8-BD8 -> 2570124.2 | AS8: =AQ8+(AR8/$AS$1) -> 530.6078 | AT8: =BT8 -> 97.65195 | AU8: 0 | AV8: =AT8-AU8 -> 97.65195 | AW8: =AV8*AG8 -> 29.364205 | AX8: =AW8*0.03 -> 0.88092615 | AY8: =(AV8-AW8)*$AS$1 -> 473000.29 | AZ8: =AY8*0.03 -> 14190.009 | BA8: =AQ8-AW8-AX8 -> 129.31007 | BB8: =AR8-AY8-AZ8 -> 2082933.9 | BG8: 0 | BL8: =BA8-BK8-BI8-BJ8-BF8 -> 129.31007 | BM8: =BB8-BC8-BE8-BG8-BH8 -> 2082933.9 | BN8: =IF(AS8<100,0,0) -> 0 | BO8: =IF(AS8<70,"",IF(AS8<=300,AS8*0.2-20,)) -> 0 | BP8: =IF(AS8<300.01,"",IF(AS8<=1000,AS8*0.25-35,)) -> 97.65195 | BQ8: =IF(AS8<1000.01,"",IF(AS8<=2000,AS8*0.3-85,)) | BR8: =IF(AS8<2000.01,"",IF(AS8<=3000,AS8*0.35-185,)) | BS8: =IF(AS8<3000.01,"",IF(AS8>3000,AS8*0.4-335,)) | BT8: =SUM(BN8:BS8) -> 97.65195 | BU8: FBC | BV8: Gweru | BW8: 9577830686343 | BX8: FBC | BY8: Gweru | BZ8: 7241498528903 | CA8: 11.52 | CB8: 2.5 | CC8: 5 | CD8: =CA8+CB8-CC8 -> 9.02
A9: AES-E057 | B9: Energy | C9: Mudenda | D9: 35-456871J78 | E9: =E8 -> 45107 | F9: =F8 -> Unki | G9: Ventilation Officer | H9: 4.9 | I9: 7728339B | J9: =AQ9/AS9 -> 0.30072254 | K9: =K8 -> 5/2023 | L9: 208 | M9: =542.14/208 -> 2.6064423 | N9: 0 | O9: 10 | P9: =L9*M9 -> 542.14 | Q9: =P9*0.3 -> 162.642 | R9: =P9*0.7*$S$1 -> 2628621.9 | S9: =P9*$S$1 -> 3755174.1 | T9: =P9*0.25 -> 135.535 | U9: =M9*N9*8*0.05 -> 0 | V9: =M9*O9*0.1 -> 2.6064423 | Y9: =AA9*M9*2 -> 0 | Z9: =AB9*M9*1.5 -> 0 | AE9: =M9*8*AC9 -> 0 | AG9: =AQ9/AS9 -> 0.30072254 | AH9: =(AI9*$AJ$1)+AJ9 -> 4712021.4 | AI9: =Q9+(T9+U9+V9+Y9+Z9+AE9)*0.3 -> 204.08443 | AJ9: =R9+((+T9+U9+V9+Y9+Z9+AE9)*0.7)*$AJ$1+W9+X9 -> 3298415 | AK9: =IF(S9>518239,0.045*518239,S9*0.045) -> 23320.755 | AL9: =(AK9*0.3)/$AS$1 -> 1.0100555 | AM9: =(AK9*0.7) -> 16324.529 | AO9: =S9*0.003 -> 11265.522 | AP9: =IF(AF9>320,320,AF9) -> 0 | AQ9: =AI9-AP9-AL9 -> 203.07438 | AR9: =AJ9-AM9-AN9-AO9-BD9 -> 3270824.9 | AS9: =AQ9+(AR9/$AS$1) -> 675.28817 | AT9: =BT9 -> 133.82204 | AU9: 0 | AV9: =AT9-AU9 -> 133.82204 | AW9: =AV9*AG9 -> 40.243305 | AX9: =AW9*0.03 -> 1.2072992 | AY9: =(AV9-AW9)*$AS$1 -> 648180.27 | AZ9: =AY9*0.03 -> 19445.408 | BA9: =AQ9-AW9-AX9 -> 161.62377 | BB9: =AR9-AY9-AZ9 -> 2603199.2 | BD9: 0 | BG9: 0 | BL9: =BA9-BK9-BI9-BJ9-BF9 -> 161.62377 | BM9: =BB9-BC9-BE9-BG9-BH9 -> 2603199.2 | BN9: =IF(AS9<100,0,0) -> 0 | BO9: =IF(AS9<70,"",IF(AS9<=300,AS9*0.2-20,)) -> 0 | BP9: =IF(AS9<300.01,"",IF(AS9<=1000,AS9*0.25-35,)) -> 133.82204 | BQ9: =IF(AS9<1000.01,"",IF(AS9<=2000,AS9*0.3-85,)) | BR9: =IF(AS9<2000.01,"",IF(AS9<=3000,AS9*0.35-185,)) | BS9: =IF(AS9<3000.01,"",IF(AS9>3000,AS9*0.4-335,)) | BT9: =SUM(BN9:BS9) -> 133.82204 | BU9: FBC | BV9: Gweru | BW9: 4362736323263 | BX9: FBC | BY9: Gweru | BZ9: 5243795393319 | CA9: 12.49 | CB9: 2.5 | CC9: 0 | CD9: =CA9+CB9-CC9 -> 14.99
A10: AES-E055 | B10: Perfect | C10: Mhererwa | D10: 54-612311T32 | E10: =E9 -> 45107 | F10: =F9 -> Unki | G10: UV Operator | H10: 4.7 | I10: TBA | J10: =AQ10/AS10 -> 0.3007027 | K10: =K9 -> 5/2023 | L10: 210 | M10: =410.34/208 -> 1.9727885 | N10: 22 | P10: =L10*M10 -> 414.28558 | Q10: =P10*0.3 -> 124.28567 | R10: =P10*0.7*$S$1 -> 2008706.5 | S10: =P10*$S$1 -> 2869580.7 | T10: =P10*0.25 -> 103.57139 | U10: =M10*N10*8*0.05 -> 17.360538 | V10: =M10*O10*0.1 -> 0 | Y10: =AA10*M10*2 -> 0 | Z10: =AB10*M10*1.5 -> 0 | AE10: =M10*8*AC10 -> 0 | AG10: =AQ10/AS10 -> 0.3007027 | AH10: =(AI10*$AJ$1)+AJ10 -> 3707225 | AI10: =Q10+(T10+U10+V10+Y10+Z10+AE10)*0.3 -> 160.56525 | AJ10: =R10+((+T10+U10+V10+Y10+Z10+AE10)*0.7)*$AJ$1+W10+X10 -> 2595057.5 | AK10: =IF(S10>518239,0.045*518239,S10*0.045) -> 23320.755 | AL10: =(AK10*0.3)/$AS$1 -> 1.0100555 | AM10: =(AK10*0.7) -> 16324.529 | AO10: =S10*0.003 -> 8608.7421 | AP10: =IF(AF10>320,320,AF10) -> 0 | AQ10: =AI10-AP10-AL10 -> 159.5552 | AR10: =AJ10-AM10-AN10-AO10-BD10 -> 2570124.2 | AS10: =AQ10+(AR10/$AS$1) -> 530.6078 | AT10: =BT10 -> 97.65195 | AU10: 0 | AV10: =AT10-AU10 -> 97.65195 | AW10: =AV10*AG10 -> 29.364205 | AX10: =AW10*0.03 -> 0.88092615 | AY10: =(AV10-AW10)*$AS$1 -> 473000.29 | AZ10: =AY10*0.03 -> 14190.009 | BA10: =AQ10-AW10-AX10 -> 129.31007 | BB10: =AR10-AY10-AZ10 -> 2082933.9 | BD10: 0 | BG10: 0 | BL10: =BA10-BK10-BI10-BJ10-BF10 -> 129.31007 | BM10: =BB10-BC10-BE10-BG10-BH10 -> 2082933.9 | BN10: =IF(AS10<100,0,0) -> 0 | BO10: =IF(AS10<70,"",IF(AS10<=300,AS10*0.2-20,)) -> 0 | BP10: =IF(AS10<300.01,"",IF(AS10<=1000,AS10*0.25-35,)) -> 97.65195 | BQ10: =IF(AS10<1000.01,"",IF(AS10<=2000,AS10*0.3-85,)) | BR10: =IF(AS10<2000.01,"",IF(AS10<=3000,AS10*0.35-185,)) | BS10: =IF(AS10<3000.01,"",IF(AS10>3000,AS10*0.4-335,)) | BT10: =SUM(BN10:BS10) -> 97.65195 | BU10: ZB | BV10: Shurugwi | BW10: 9378152371743 | BX10: FBC | BY10: Gweru | BZ10: 8883373049733 | CA10: 12.26 | CB10: 2.5 | CC10: 6 | CD10: =CA10+CB10-CC10 -> 8.76
A11: AES-E056 | B11: Tanyaradzwa | C11: Ndoro | D11: 04-197573K30 | E11: =E10 -> 45107 | F11: =F10 -> Unki | G11: Construction Assistant | H11: 4.3 | I11: TBA | J11: =AQ11/AS11 -> 0.3007027 | K11: =K10 -> 5/2023 | L11: 210 | M11: =410.34/208 -> 1.9727885 | N11: 22 | P11: =L11*M11 -> 414.28558 | Q11: =P11*0.3 -> 124.28567 | R11: =P11*0.7*$S$1 -> 2008706.5 | S11: =P11*$S$1 -> 2869580.7 | T11: =P11*0.25 -> 103.57139 | U11: =M11*N11*8*0.05 -> 17.360538 | V11: =M11*O11*0.1 -> 0 | Y11: =AA11*M11*2 -> 0 | Z11: =AB11*M11*1.5 -> 0 | AE11: =M11*8*AC11 -> 0 | AG11: =AQ11/AS11 -> 0.3007027 | AH11: =(AI11*$AJ$1)+AJ11 -> 3707225 | AI11: =Q11+(T11+U11+V11+Y11+Z11+AE11)*0.3 -> 160.56525 | AJ11: =R11+((+T11+U11+V11+Y11+Z11+AE11)*0.7)*$AJ$1+W11+X11 -> 2595057.5 | AK11: =IF(S11>518239,0.045*518239,S11*0.045) -> 23320.755 | AL11: =(AK11*0.3)/$AS$1 -> 1.0100555 | AM11: =(AK11*0.7) -> 16324.529 | AO11: =S11*0.003 -> 8608.7421 | AP11: =IF(AF11>320,320,AF11) -> 0 | AQ11: =AI11-AP11-AL11 -> 159.5552 | AR11: =AJ11-AM11-AN11-AO11-BD11 -> 2570124.2 | AS11: =AQ11+(AR11/$AS$1) -> 530.6078 | AT11: =BT11 -> 97.65195 | AU11: 0 | AV11: =AT11-AU11 -> 97.65195 | AW11: =AV11*AG11 -> 29.364205 | AX11: =AW11*0.03 -> 0.88092615 | AY11: =(AV11-AW11)*$AS$1 -> 473000.29 | AZ11: =AY11*0.03 -> 14190.009 | BA11: =AQ11-AW11-AX11 -> 129.31007 | BB11: =AR11-AY11-AZ11 -> 2082933.9 | BD11: 0 | BG11: 0 | BL11: =BA11-BK11-BI11-BJ11-BF11 -> 129.31007 | BM11: =BB11-BC11-BE11-BG11-BH11 -> 2082933.9 | BN11: =IF(AS11<100,0,0) -> 0 | BO11: =IF(AS11<70,"",IF(AS11<=300,AS11*0.2-20,)) -> 0 | BP11: =IF(AS11<300.01,"",IF(AS11<=1000,AS11*0.25-35,)) -> 97.65195 | BQ11: =IF(AS11<1000.01,"",IF(AS11<=2000,AS11*0.3-85,)) | BR11: =IF(AS11<2000.01,"",IF(AS11<=3000,AS11*0.35-185,)) | BS11: =IF(AS11<3000.01,"",IF(AS11>3000,AS11*0.4-335,)) | BT11: =SUM(BN11:BS11) -> 97.65195 | BU11: ZB | BV11: Shurugwi | BW11: 6386933976899 | BX11: FBC | BY11: Gweru | BZ11: 9325231550423 | CA11: 11.67 | CB11: 2.5 | CC11: 0 | CD11: =CA11+CB11-CC11 -> 14.17
A12: AES-E059 | B12: Perfect | C12: Chinouriri | D12: 72-656711M56 | E12: =E11 -> 45107 | F12: =F11 -> Unki | G12: Boilermaker | H12: 4.9 | I12: 3219824V | J12: =AQ12/AS12 -> 0.30070162 | K12: =K11 -> 5/2023 | L12: 210 | M12: =542.14/208 -> 2.6064423 | N12: 22 | P12: =L12*M12 -> 547.35288 | Q12: =P12*0.3 -> 164.20587 | R12: =P12*0.7*$S$1 -> 2653897.1 | S12: =P12*$S$1 -> 3791281.6 | T12: =P12*0.25 -> 136.83822 | U12: =M12*N12*8*0.05 -> 22.936692 | V12: =M12*O12*0.1 -> 0 | Y12: =AA12*M12*2 -> 0 | Z12: =AB12*M12*1.5 -> 0 | AE12: =M12*8*AC12 -> 0 | AG12: =AQ12/AS12 -> 0.30070162 | AH12: =(AI12*$AJ$1)+AJ12 -> 4897974.7 | AI12: =Q12+(T12+U12+V12+Y12+Z12+AE12)*0.3 -> 212.13834 | AJ12: =R12+((+T12+U12+V12+Y12+Z12+AE12)*0.7)*$AJ$1+W12+X12 -> 3428582.3 | AK12: =IF(S12>518239,0.045*518239,S12*0.045) -> 23320.755 | AL12: =(AK12*0.3)/$AS$1 -> 1.0100555 | AM12: =(AK12*0.7) -> 16324.529 | AO12: =S12*0.003 -> 11373.845 | AP12: =IF(AF12>320,320,AF12) -> 0 | AQ12: =AI12-AP12-AL12 -> 211.12828 | AR12: =AJ12-AM12-AN12-AO12-BD12 -> 3400883.9 | AS12: =AQ12+(AR12/$AS$1) -> 702.11889 | AT12: =BT12 -> 140.52972 | AU12: 0 | AV12: =AT12-AU12 -> 140.52972 | AW12: =AV12*AG12 -> 42.257514 | AX12: =AW12*0.03 -> 1.2677254 | AY12: =(AV12-AW12)*$AS$1 -> 680689.95 | AZ12: =AY12*0.03 -> 20420.699 | BA12: =AQ12-AW12-AX12 -> 167.60304 | BB12: =AR12-AY12-AZ12 -> 2699773.3 | BD12: 0 | BL12: =BA12-BK12-BI12-BJ12-BF12 -> 167.60304 | BM12: =BB12-BC12-BE12-BG12-BH12 -> 2699773.3 | BN12: =IF(AS12<100,0,0) -> 0 | BO12: =IF(AS12<70,"",IF(AS12<=300,AS12*0.2-20,)) -> 0 | BP12: =IF(AS12<300.01,"",IF(AS12<=1000,AS12*0.25-35,)) -> 140.52972 | BQ12: =IF(AS12<1000.01,"",IF(AS12<=2000,AS12*0.3-85,)) | BR12: =IF(AS12<2000.01,"",IF(AS12<=3000,AS12*0.35-185,)) | BS12: =IF(AS12<3000.01,"",IF(AS12>3000,AS12*0.4-335,)) | BT12: =SUM(BN12:BS12) -> 140.52972 | BU12: ZB | BV12: Gweru | BW12: 6817749619277 | BX12: FBC | BY12: Gweru | BZ12: 5765067552342 | CA12: 12.26 | CB12: 2.5 | CC12: 0 | CD12: =CA12+CB12-CC12 -> 14.76
A13: AES-E058 | B13: Wisdom | C13: Mavhunga | D13: 41-363615H17 | E13: =E12 -> 45107 | F13: =F12 -> Unki | G13: Construction Assistant | H13: 4.3 | I13: 1036161N | J13: =AQ13/AS13 -> 0.3007027 | K13: =K12 -> 5/2023 | L13: 210 | M13: =410.34/208 -> 1.9727885 | N13: 22 | P13: =L13*M13 -> 414.28558 | Q13: =P13*0.3 -> 124.28567 | R13: =P13*0.7*$S$1 -> 2008706.5 | S13: =P13*$S$1 -> 2869580.7 | T13: =P13*0.25 -> 103.57139 | U13: =M13*N13*8*0.05 -> 17.360538 | V13: =M13*O13*0.1 -> 0 | Y13: =AA13*M13*2 -> 0 | Z13: =AB13*M13*1.5 -> 0 | AE13: =M13*8*AC13 -> 0 | AG13: =AQ13/AS13 -> 0.3007027 | AH13: =(AI13*$AJ$1)+AJ13 -> 3707225 | AI13: =Q13+(T13+U13+V13+Y13+Z13+AE13)*0.3 -> 160.56525 | AJ13: =R13+((+T13+U13+V13+Y13+Z13+AE13)*0.7)*$AJ$1+W13+X13 -> 2595057.5 | AK13: =IF(S13>518239,0.045*518239,S13*0.045) -> 23320.755 | AL13: =(AK13*0.3)/$AS$1 -> 1.0100555 | AM13: =(AK13*0.7) -> 16324.529 | AO13: =S13*0.003 -> 8608.7421 | AP13: =IF(AF13>320,320,AF13) -> 0 | AQ13: =AI13-AP13-AL13 -> 159.5552 | AR13: =AJ13-AM13-AN13-AO13-BD13 -> 2570124.2 | AS13: =AQ13+(AR13/$AS$1) -> 530.6078 | AT13: =BT13 -> 97.65195 | AU13: 0 | AV13: =AT13-AU13 -> 97.65195 | AW13: =AV13*AG13 -> 29.364205 | AX13: =AW13*0.03 -> 0.88092615 | AY13: =(AV13-AW13)*$AS$1 -> 473000.29 | AZ13: =AY13*0.03 -> 14190.009 | BA13: =AQ13-AW13-AX13 -> 129.31007 | BB13: =AR13-AY13-AZ13 -> 2082933.9 | BD13: 0 | BL13: =BA13-BK13-BI13-BJ13-BF13 -> 129.31007 | BM13: =BB13-BC13-BE13-BG13-BH13 -> 2082933.9 | BN13: =IF(AS13<100,0,0) -> 0 | BO13: =IF(AS13<70,"",IF(AS13<=300,AS13*0.2-20,)) -> 0 | BP13: =IF(AS13<300.01,"",IF(AS13<=1000,AS13*0.25-35,)) -> 97.65195 | BQ13: =IF(AS13<1000.01,"",IF(AS13<=2000,AS13*0.3-85,)) | BR13: =IF(AS13<2000.01,"",IF(AS13<=3000,AS13*0.35-185,)) | BS13: =IF(AS13<3000.01,"",IF(AS13>3000,AS13*0.4-335,)) | BT13: =SUM(BN13:BS13) -> 97.65195 | BU13: ZB | BV13: Shurugwi | BW13: 4387532121887 | BX13: FBC | BY13: Gweru | BZ13: 3101594275846 | CA13: 11.48 | CB13: 2.5 | CC13: 1 | CD13: =CA13+CB13-CC13 -> 12.98
A14: AES-E060 | B14: Makanaka | C14: Dziva | D14: 70-899213Z25 | E14: =E13 -> 45107 | F14: =F13 -> Unki | G14: Jack Hammer Operator | H14: 4.7 | I14: TBA | J14: =AQ14/AS14 -> 0.3007027 | K14: =K13 -> 5/2023 | L14: 210 | M14: =410.34/208 -> 1.9727885 | N14: 22 | P14: =L14*M14 -> 414.28558 | Q14: =P14*0.3 -> 124.28567 | R14: =P14*0.7*$S$1 -> 2008706.5 | S14: =P14*$S$1 -> 2869580.7 | T14: =P14*0.25 -> 103.57139 | U14: =M14*N14*8*0.05 -> 17.360538 | V14: =M14*O14*0.1 -> 0 | Y14: =AA14*M14*2 -> 0 | Z14: =AB14*M14*1.5 -> 0 | AE14: =M14*8*AC14 -> 0 | AG14: =AQ14/AS14 -> 0.3007027 | AH14: =(AI14*$AJ$1)+AJ14 -> 3707225 | AI14: =Q14+(T14+U14+V14+Y14+Z14+AE14)*0.3 -> 160.56525 | AJ14: =R14+((+T14+U14+V14+Y14+Z14+AE14)*0.7)*$AJ$1+W14+X14 -> 2595057.5 | AK14: =IF(S14>518239,0.045*518239,S14*0.045) -> 23320.755 | AL14: =(AK14*0.3)/$AS$1 -> 1.0100555 | AM14: =(AK14*0.7) -> 16324.529 | AO14: =S14*0.003 -> 8608.7421 | AP14: =IF(AF14>320,320,AF14) -> 0 | AQ14: =AI14-AP14-AL14 -> 159.5552 | AR14: =AJ14-AM14-AN14-AO14-BD14 -> 2570124.2 | AS14: =AQ14+(AR14/$AS$1) -> 530.6078 | AT14: =BT14 -> 97.65195 | AU14: 0 | AV14: =AT14-AU14 -> 97.65195 | AW14: =AV14*AG14 -> 29.364205 | AX14: =AW14*0.03 -> 0.88092615 | AY14: =(AV14-AW14)*$AS$1 -> 473000.29 | AZ14: =AY14*0.03 -> 14190.009 | BA14: =AQ14-AW14-AX14 -> 129.31007 | BB14: =AR14-AY14-AZ14 -> 2082933.9 | BD14: 0 | BL14: =BA14-BK14-BI14-BJ14-BF14 -> 129.31007 | BM14: =BB14-BC14-BE14-BG14-BH14 -> 2082933.9 | BN14: =IF(AS14<100,0,0) -> 0 | BO14: =IF(AS14<70,"",IF(AS14<=300,AS14*0.2-20,)) -> 0 | BP14: =IF(AS14<300.01,"",IF(AS14<=1000,AS14*0.25-35,)) -> 97.65195 | BQ14: =IF(AS14<1000.01,"",IF(AS14<=2000,AS14*0.3-85,)) | BR14: =IF(AS14<2000.01,"",IF(AS14<=3000,AS14*0.35-185,)) | BS14: =IF(AS14<3000.01,"",IF(AS14>3000,AS14*0.4-335,)) | BT14: =SUM(BN14:BS14) -> 97.65195 | BU14: FBC | BV14: Gweru BS | BW14: 4806163686472 | BX14: FBC | BY14: Headoffice | BZ14: 9520092430792 | CA14: 12.18 | CB14: 2.5 | CC14: 0 | CD14: =CA14+CB14-CC14 -> 14.68
C56: Totals | P56: =SUM(P4:P55) -> 5260.8947 | Q56: =SUM(Q4:Q55) -> 1578.2684 | R56: =SUM(R4:R55) -> 25507992 | S56: =SUM(S4:S55) -> 36439989 | T56: =SUM(T4:T55) -> 1315.2237 | U56: =SUM(U4:U55) -> 197.63588 | V56: =SUM(V4:V55) -> 2.6064423 | W56: =SUM(W4:W55) -> 10000 | ... BE56: =SUM(BE4:BE55) -> 0 | BG56: =SUM(BG4:BG55) -> 0 | BJ56: =SUM(BJ4:BJ55) -> 0 | BK56: =SUM(BK4:BK55) -> 10 | BL56: =SUM(BL4:BL55) -> 1615.1024 | BM56: =SUM(BM4:BM55) -> 26155617 | BN56: =SUM(BN4:BN55) -> 0 | BO56: =SUM(BO4:BO55) -> 0 | BP56: =SUM(BP4:BP55) -> 1070.3427 | BQ56: =SUM(BQ4:BQ55) -> 235.94462 | ... BT56: =SUM(BT4:BT55) -> 1306.2873 | CA56: =SUM(CA4:CA55) -> 131.82 | CB56: =SUM(CB4:CB55) -> 27.5 | CC56: =SUM(CC4:CC55) -> 15 | CD56: =SUM(CD4:CD55) -> 144.32

Sheet Payslip 2
A1: AIRFLOW ENVIRONMENTAL SOLUTIONS PRIVATE LIMITED PAYSLIP | M1: Rate | N1: 6926.5764
A2: Employee Details | D2: Earnings Details | E2: Units | F2: Earning Amounts | I2: Deduction Details | J2: Deduction Amounts | M2: CA | N2: 73 | O2: =CONCATENATE(M2,N2) -> CA73
A3: =VLOOKUP(B4,Paysheet!$A$4:$CD$55,COLUMN(Paysheet!B5),FALSE()) -> #N/A | B3: =VLOOKUP(B4,Paysheet!$A$4:$CD$55,COLUMN(Paysheet!C5),FALSE()) -> #N/A | F3: USD | G3: ZWL | J3: USD | K3: ZWL | M3: CA | N3: 76 | O3: =CONCATENATE(M3,N3) -> CA76
A4: Employee NO | B4: =O2 -> CA73 | D4: Basic Pay | E4: =VLOOKUP(B4,Paysheet!$A$4:$CD$55,COLUMN(Paysheet!L6),FALSE()) -> #N/A | F4: =VLOOKUP(B4,Paysheet!$A$4:$CD$55,COLUMN(Paysheet!Q6),FALSE()) -> #N/A | G4: =VLOOKUP(B4,Paysheet!$A$4:$CD$55,COLUMN(Paysheet!R6),FALSE()) -> #N/A | I4: PAYE | J4: =VLOOKUP(B4,Paysheet!$A$4:$CD$55,COLUMN(Paysheet!AW6),FALSE()) -> #N/A | K4: =VLOOKUP(B4,Paysheet!$A$4:$CD$55,COLUMN(Paysheet!AY6),FALSE()) -> #N/A | M4: CA | N4: 0 | O4: =CONCATENATE(M4,N4) -> CA0
A5: Period | B5: =VLOOKUP(B4,Paysheet!$A$4:$CD$55,COLUMN(Paysheet!K7),FALSE()) -> #N/A | D5: Housing Allowance | F5: =VLOOKUP(B4,Paysheet!$A$4:$CD$55,COLUMN(Paysheet!T7),FALSE())*0.3 -> #N/A | G5: =VLOOKUP(B4,Paysheet!$A$4:$CD$55,COLUMN(Paysheet!T7),FALSE())*0.7*N1 -> #N/A | I5: AIDS LEVY | J5: =VLOOKUP(B4,Paysheet!$A$4:$CD$55,COLUMN(Paysheet!AX7),FALSE()) -> #N/A | K5: =VLOOKUP(B4,Paysheet!$A$4:$CD$55,COLUMN(Paysheet!AZ7),FALSE()) -> #N/A
A6: Nat ID | B6: =VLOOKUP(B4,Paysheet!$A$4:$CD$55,COLUMN(Paysheet!D8),FALSE()) -> #N/A | D6: Overtime 1.5 | F6: =VLOOKUP(B4,Paysheet!$A$4:$CD$55,COLUMN(Paysheet!Z8),FALSE())*0.3 -> #N/A | I6: NSSA | J6: =VLOOKUP(B4,Paysheet!$A$4:$CD$55,COLUMN(Paysheet!AL8),FALSE()) -> #N/A | K6: =VLOOKUP(B4,Paysheet!$A$4:$CD$55,COLUMN(Paysheet!AM8),FALSE()) -> #N/A
A7: Pay Method | B7: Transfer | D7: Overtime 2.0 | F7: =VLOOKUP(B4,Paysheet!$A$4:$CD$55,COLUMN(Paysheet!Y9),FALSE()) -> #N/A | I7: NEC | K7: =VLOOKUP(B4,Paysheet!$A$4:$CD$55,COLUMN(Paysheet!AO9),FALSE()) -> #N/A
A8: Grade | B8: =VLOOKUP(B4,Paysheet!$A$4:$CD$55,COLUMN(Paysheet!H10),FALSE()) -> #N/A | D8: Loan/Advance | I8: Repayment | J8: =VLOOKUP(B4,Paysheet!$A$4:$CD$55,COLUMN(Paysheet!BI10),FALSE()) -> #N/A
A9: Occupation | B9: =VLOOKUP(B4,Paysheet!$A$4:$CD$55,COLUMN(Paysheet!G11),FALSE()) -> #N/A | D9: C.I.L.O.L | I9: Maintenance | J9: =VLOOKUP(B4,Paysheet!$A$4:$CD$55,COLUMN(Paysheet!BF11),FALSE()) -> #N/A | K9: =VLOOKUP(B4,Paysheet!$A$4:$CD$55,COLUMN(Paysheet!BE11),FALSE()) -> #N/A
A10: Leave Days | B10: =VLOOKUP(B4,Paysheet!$A$4:$CD$55,COLUMN(Paysheet!CD12),FALSE()) -> #N/A | D10: Food Allowance | G10: =VLOOKUP(B4,Paysheet!$A$4:$CD$55,COLUMN(Paysheet!W12),FALSE()) -> #N/A | I10: Nyaradzo | K10: =VLOOKUP(B4,Paysheet!$A$4:$CD$55,COLUMN(Paysheet!BC12),FALSE()) -> #N/A
A11: NSSA No | B11: =VLOOKUP(B4,Paysheet!$A$4:$CD$55,COLUMN(Paysheet!I13),FALSE()) -> #N/A | D11: Airtime Allowance | G11: =VLOOKUP(B4,Paysheet!$A$4:$CD$55,COLUMN(Paysheet!X13),FALSE()) -> #N/A | I11: MIPF | K11: =VLOOKUP(B4,Paysheet!$A$4:$CD$55,COLUMN(Paysheet!AN13),FALSE()) -> #N/A | M11: Checking
A12: Station | B12: =VLOOKUP(B4,Paysheet!$A$4:$CD$55,COLUMN(Paysheet!F14),FALSE()) -> #N/A | D12: Underground Allowance | F12: =VLOOKUP(B4,Paysheet!$A$4:$CD$55,COLUMN(Paysheet!U14),FALSE())*0.3 -> #N/A | G12: =VLOOKUP(B4,Paysheet!$A$4:$CD$55,COLUMN(Paysheet!U14),FALSE())*0.7*N1 -> #N/A | I12: CBZ Fund | K12: =VLOOKUP(B4,Paysheet!$A$4:$CD$55,COLUMN(Paysheet!BD14),FALSE()) -> #N/A | M12: usd | N12: =F15-J15 -> #N/A
A13: Pay Date | B13: =VLOOKUP(B4,Paysheet!$A$4:$CD$55,COLUMN(Paysheet!E15),FALSE()) -> #N/A | D13: Night Shift Allowance | F13: =VLOOKUP(B4,Paysheet!$A$4:$CD$55,COLUMN(Paysheet!V15),FALSE())*0.3 -> #N/A | G13: =VLOOKUP(B4,Paysheet!$A$4:$CD$55,COLUMN(Paysheet!V15),FALSE())*0.7*N1 -> #N/A | I13: May Day | J13: =VLOOKUP(B4,Paysheet!$A$4:$CD$55,COLUMN(Paysheet!BK15),FALSE()) -> #N/A | M13: zwl | N13: =G15-K15 -> #N/A
D15: Gross | F15: =SUM(F4:F14) -> #N/A | G15: =SUM(G4:G14) -> #N/A | I15: Total Deductions | J15: =SUM(J4:J14) -> #N/A | K15: =SUM(K4:K14) -> #N/A
A17: ZWL Banked | B17: =VLOOKUP(B4,Paysheet!$A$4:$CD$55,COLUMN(Paysheet!BU19),FALSE()) -> #N/A | D17: =VLOOKUP(B4,Paysheet!$A$4:$CD$55,COLUMN(Paysheet!BW19),FALSE()) -> #N/A | F17: Tax Credit | I17: NET PAY | J17: ZWL | K17: =VLOOKUP(B4,Paysheet!$A$4:$CD$55,COLUMN(Paysheet!BM6),FALSE()) -> #N/A | N17: =K17-N13 -> #N/A
A18: USD Banked | B18: =VLOOKUP(B4,Paysheet!$A$4:$CD$55,COLUMN(Paysheet!BX20),FALSE()) -> #N/A | D18: =VLOOKUP(B4,Paysheet!$A$4:$CD$55,COLUMN(Paysheet!BZ20),FALSE()) -> #N/A | F18: =VLOOKUP(B4,Paysheet!$A$4:$CD$55,COLUMN(Paysheet!AU19),FALSE()) -> #N/A | J18: USD | K18: =VLOOKUP(B4,Paysheet!$A$4:$CD$55,COLUMN(Paysheet!BL6),FALSE()) -> #N/A
A21: AIRFLOW ENVIRONMENTAL SOLUTIONS PRIVATE LIMITED PAYSLIP
A22: Employee Details | D22: Earnings Details | E22: Units | F22: Earning Amounts | I22: Deduction Details | J22: Deduction Amounts
A23: =VLOOKUP(B24,Paysheet!$A$4:$CD$55,COLUMN(Paysheet!B25),FALSE()) -> #N/A | B23: =VLOOKUP(B24,Paysheet!$A$4:$CD$55,COLUMN(Paysheet!C25),FALSE()) -> #N/A | F23: USD | G23: ZWL | J23: USD | K23: ZWL
A24: Employee NO | B24: =O3 -> CA76 | D24: Basic Pay | E24: =VLOOKUP(B24,Paysheet!$A$4:$CD$55,COLUMN(Paysheet!L26),FALSE()) -> #N/A | F24: =VLOOKUP(B24,Paysheet!$A$4:$CD$55,COLUMN(Paysheet!Q26),FALSE()) -> #N/A | G24: =VLOOKUP(B24,Paysheet!$A$4:$CD$55,COLUMN(Paysheet!R26),FALSE()) -> #N/A | I24: PAYE | J24: =VLOOKUP(B24,Paysheet!$A$4:$CD$55,COLUMN(Paysheet!AW26),FALSE()) -> #N/A | K24: =VLOOKUP(B24,Paysheet!$A$4:$CD$55,COLUMN(Paysheet!AY26),FALSE()) -> #N/A
A25: Period | B25: =VLOOKUP(B24,Paysheet!$A$4:$CD$55,COLUMN(Paysheet!K27),FALSE()) -> #N/A | D25: Housing Allowance | F25: =VLOOKUP(B24,Paysheet!$A$4:$CD$55,COLUMN(Paysheet!T27),FALSE())*0.3 -> #N/A | G25: =VLOOKUP(B24,Paysheet!$A$4:$CD$55,COLUMN(Paysheet!T27),FALSE())*0.7*N1 -> #N/A | I25: AIDS LEVY | J25: =VLOOKUP(B24,Paysheet!$A$4:$CD$55,COLUMN(Paysheet!AX27),FALSE()) -> #N/A | K25: =VLOOKUP(B24,Paysheet!$A$4:$CD$55,COLUMN(Paysheet!AZ27),FALSE()) -> #N/A
A26: Nat ID | B26: =VLOOKUP(B24,Paysheet!$A$4:$CD$55,COLUMN(Paysheet!D28),FALSE()) -> #N/A | D26: Overtime 1.5 | F26: =VLOOKUP(B24,Paysheet!$A$4:$CD$55,COLUMN(Paysheet!Z28),FALSE())*0.3 -> #N/A | I26: NSSA | J26: =VLOOKUP(B24,Paysheet!$A$4:$CD$55,COLUMN(Paysheet!AL28),FALSE()) -> #N/A | K26: =VLOOKUP(B24,Paysheet!$A$4:$CD$55,COLUMN(Paysheet!AM28),FALSE()) -> #N/A
A27: Pay Method | B27: Transfer | D27: Overtime 2.0 | F27: =VLOOKUP(B24,Paysheet!$A$4:$CD$55,COLUMN(Paysheet!Y29),FALSE()) -> #N/A | I27: NEC | K27: =VLOOKUP(B24,Paysheet!$A$4:$CD$55,COLUMN(Paysheet!AO29),FALSE()) -> #N/A
A28: Grade | B28: =VLOOKUP(B24,Paysheet!$A$4:$CD$55,COLUMN(Paysheet!H30),FALSE()) -> #N/A | D28: Loan/Advance | I28: Repayment | J28: =VLOOKUP(B24,Paysheet!$A$4:$CD$55,COLUMN(Paysheet!BI30),FALSE()) -> #N/A
A29: Occupation | B29: =VLOOKUP(B24,Paysheet!$A$4:$CD$55,COLUMN(Paysheet!G31),FALSE()) -> #N/A | D29: C.I.L.O.L | I29: Maintenance | J29: =VLOOKUP(B24,Paysheet!$A$4:$CD$55,COLUMN(Paysheet!BF31),FALSE()) -> #N/A | K29: =VLOOKUP(B24,Paysheet!$A$4:$CD$55,COLUMN(Paysheet!BE31),FALSE()) -> #N/A
A30: Leave Days | B30: =VLOOKUP(B24,Paysheet!$A$4:$CD$55,COLUMN(Paysheet!CD32),FALSE()) -> #N/A | D30: Food Allowance | G30: =VLOOKUP(B24,Paysheet!$A$4:$CD$55,COLUMN(Paysheet!W32),FALSE()) -> #N/A | I30: Nyaradzo | K30: =VLOOKUP(B24,Paysheet!$A$4:$CD$55,COLUMN(Paysheet!BC32),FALSE()) -> #N/A
A31: NSSA No | B31: =VLOOKUP(B24,Paysheet!$A$4:$CD$55,COLUMN(Paysheet!I33),FALSE()) -> #N/A | D31: Airtime Allowance | G31: =VLOOKUP(B24,Paysheet!$A$4:$CD$55,COLUMN(Paysheet!X33),FALSE()) -> #N/A | I31: MIPF | K31: =VLOOKUP(B24,Paysheet!$A$4:$CD$55,COLUMN(Paysheet!AN33),FALSE()) -> #N/A | M31: Checking
A32: Station | B32: =VLOOKUP(B24,Paysheet!$A$4:$CD$55,COLUMN(Paysheet!F34),FALSE()) -> #N/A | D32: Underground Allowance | F32: =VLOOKUP(B24,Paysheet!$A$4:$CD$55,COLUMN(Paysheet!U14),FALSE())*0.3 -> #N/A | G32: =VLOOKUP(B24,Paysheet!$A$4:$CD$55,COLUMN(Paysheet!U14),FALSE())*0.7*N1 -> #N/A | I32: CBZ Fund | K32: =VLOOKUP(B24,Paysheet!$A$4:$CD$55,COLUMN(Paysheet!BD34),FALSE()) -> #N/A | M32: usd | N32: =F35-J35 -> #N/A
A33: Pay Date | B33: =VLOOKUP(B24,Paysheet!$A$4:$CD$55,COLUMN(Paysheet!E35),FALSE()) -> #N/A | D33: Night Shift Allowance | F33: =VLOOKUP(B24,Paysheet!$A$4:$CD$55,COLUMN(Paysheet!V15),FALSE())*0.3 -> #N/A | G33: =VLOOKUP(B24,Paysheet!$A$4:$CD$55,COLUMN(Paysheet!V15),FALSE())*0.7*N1 -> #N/A | I33: May Day | J33: =VLOOKUP(B24,Paysheet!$A$4:$CD$55,COLUMN(Paysheet!BK35),FALSE()) -> #N/A | M33: zwl | N33: =G35-K35 -> #N/A
D35: Gross | F35: =SUM(F24:F34) -> #N/A | G35: =SUM(G24:G34) -> #N/A | I35: Total Deductions | J35: =SUM(J24:J34) -> #N/A | K35: =SUM(K24:K34) -> #N/A
A37: ZWL Banked | B37: =VLOOKUP(B24,Paysheet!$A$4:$CD$55,COLUMN(Paysheet!BU39),FALSE()) -> #N/A | D37: =VLOOKUP(B24,Paysheet!$A$4:$CD$55,COLUMN(Paysheet!BW39),FALSE()) -> #N/A | F37: Tax Credit | I37: NET PAY | J37: ZWL | K37: =VLOOKUP(B24,Paysheet!$A$4:$CD$55,COLUMN(Paysheet!BM26),FALSE()) -> #N/A
A38: USD Banked | B38: =VLOOKUP(B24,Paysheet!$A$4:$CD$55,COLUMN(Paysheet!BX40),FALSE()) -> #N/A | D38: =VLOOKUP(B24,Paysheet!$A$4:$CD$55,COLUMN(Paysheet!BZ40),FALSE()) -> #N/A | F38: =VLOOKUP(B24,Paysheet!$A$4:$CD$55,COLUMN(Paysheet!AU39),FALSE()) -> #N/A | J38: USD | K38: =VLOOKUP(B24,Paysheet!$A$4:$CD$55,COLUMN(Paysheet!BL26),FALSE()) -> #N/A | N38: =K37-N33 -> #N/A
A41: AIRFLOW ENVIRONMENTAL SOLUTIONS PRIVATE LIMITED PAYSLIP
A42: Employee Details | D42: Earnings Details | E42: Units | F42: Earning Amounts | I42: Deduction Details | J42: Deduction Amounts
A43: =VLOOKUP(B44,Paysheet!$A$4:$CD$55,COLUMN(Paysheet!B45),FALSE()) -> #N/A | B43: =VLOOKUP(B44,Paysheet!$A$4:$CD$55,COLUMN(Paysheet!C45),FALSE()) -> #N/A | F43: USD | G43: ZWL | J43: USD | K43: ZWL
A44: Employee NO | B44: =O4 -> CA0 | D44: Basic Pay | E44: =VLOOKUP(B44,Paysheet!$A$4:$CD$55,COLUMN(Paysheet!L46),FALSE()) -> #N/A | F44: =VLOOKUP(B44,Paysheet!$A$4:$CD$55,COLUMN(Paysheet!Q46),FALSE()) -> #N/A | G44: =VLOOKUP(B44,Paysheet!$A$4:$CD$55,COLUMN(Paysheet!R46),FALSE()) -> #N/A | I44: PAYE | J44: =VLOOKUP(B44,Paysheet!$A$4:$CD$55,COLUMN(Paysheet!AW46),FALSE()) -> #N/A | K44: =VLOOKUP(B44,Paysheet!$A$4:$CD$55,COLUMN(Paysheet!AY46),FALSE()) -> #N/A
A45: Period | B45: =VLOOKUP(B44,Paysheet!$A$4:$CD$55,COLUMN(Paysheet!K47),FALSE()) -> #N/A | D45: Housing Allowance | F45: =VLOOKUP(B44,Paysheet!$A$4:$CD$55,COLUMN(Paysheet!T47),FALSE())*0.3 -> #N/A | G45: =VLOOKUP(B44,Paysheet!$A$4:$CD$55,COLUMN(Paysheet!T47),FALSE())*0.7*N1 -> #N/A | I45: AIDS LEVY | J45: =VLOOKUP(B44,Paysheet!$A$4:$CD$55,COLUMN(Paysheet!AX47),FALSE()) -> #N/A | K45: =VLOOKUP(B44,Paysheet!$A$4:$CD$55,COLUMN(Paysheet!AZ47),FALSE()) -> #N/A
A46: Nat ID | B46: =VLOOKUP(B44,Paysheet!$A$4:$CD$55,COLUMN(Paysheet!D48),FALSE()) -> #N/A | D46: Overtime 1.5 | F46: =VLOOKUP(B44,Paysheet!$A$4:$CD$55,COLUMN(Paysheet!Z48),FALSE())*0.3 -> #N/A | G46: =VLOOKUP(B44,Paysheet!$A$4:$CD$55,COLUMN(Paysheet!Z48),FALSE())*0.7*N1 -> #N/A | I46: NSSA | J46: =VLOOKUP(B44,Paysheet!$A$4:$CD$55,COLUMN(Paysheet!AL48),FALSE()) -> #N/A | K46: =VLOOKUP(B44,Paysheet!$A$4:$CD$55,COLUMN(Paysheet!AM48),FALSE()) -> #N/A
A47: Pay Method | B47: Transfer | D47: Overtime 2.0 | F47: =VLOOKUP(B44,Paysheet!$A$4:$CD$55,COLUMN(Paysheet!Y49),FALSE())*0.3 -> #N/A | G47: =VLOOKUP(B44,Paysheet!$A$4:$CD$55,COLUMN(Paysheet!Y49),FALSE())*0.3 -> #N/A | I47: NEC | K47: =VLOOKUP(B44,Paysheet!$A$4:$CD$55,COLUMN(Paysheet!AO49),FALSE()) -> #N/A
A48: Grade | B48: =VLOOKUP(B44,Paysheet!$A$4:$CD$55,COLUMN(Paysheet!H50),FALSE()) -> #N/A | D48: Loan/Advance | I48: Repayment | J48: =VLOOKUP(B44,Paysheet!$A$4:$CD$55,COLUMN(Paysheet!BI50),FALSE()) -> #N/A
...

Sheet Bank Schedule
B1: Airflow Environmental Solutions
B2: Unki Bank Schedule for the Month of May 2023 | M2: Back Pay | O2: Totals | Q2: USD | R2: zwl
C3: Netsai | D3: Nhemachena | E3: Bank | F3: Branch | G3: Account Number | H3: Amount | I3: Bank | J3: Branch | K3: Account Number | L3: Amount | M3: USD | N3: ZWL | O3: USD | P3: ZWL
A4: 1 | B4: =Paysheet!A4 -> AES-E050 | C4: =Paysheet!B4 -> Clever | D4: =Paysheet!C4 -> Chakabva | E4: =Paysheet!BU4 -> FBC | F4: =Paysheet!BV4 -> Gweru | G4: =Paysheet!BW4 -> 2212772367295 | H4: =Paysheet!BM4 -> 3976514.4 | I4: =Paysheet!BX4 -> FBC | J4: =Paysheet!BY4 -> Gweru | K4: =Paysheet!BZ4 -> 1220508908844 | L4: =Paysheet!BL4 -> 248.21427 | M4: 175.73 | N4: 687057.09 | O4: =L4+M4 -> 423.94427 | P4: =H4+N4 -> 4663571.5 | Q4: =437.78-O4 -> 13.835735 | R4: =1518321.1-P4 -> -3145250.4
A5: 2 | B5: =Paysheet!A5 -> AES-E052 | C5: =Paysheet!B5 -> Tatenda | D5: =Paysheet!C5 -> Masuku | E5: =Paysheet!BU5 -> FBC | F5: =Paysheet!BV5 -> Gweru | G5: =Paysheet!BW5 -> 8658583780750 | H5: =Paysheet!BM5 -> 2082933.9 | I5: =Paysheet!BX5 -> FBC | J5: =Paysheet!BY5 -> Gweru | K5: =Paysheet!BZ5 -> 5753027522713 | L5: =Paysheet!BL5 -> 129.31007 | M5: 80.56 | N5: 323181.65 | O5: =L5+M5 -> 209.87007 | P5: =H5+N5 -> 2406115.6 | Q5: =211.24-O5 -> 1.3699337 | R5: =764848.8-P5 -> -1641266.8
A6: 3 | B6: =Paysheet!A6 -> AES-E051 | C6: =Paysheet!B6 -> Kupakwashe | D6: =Paysheet!C6 -> Matongo | E6: =Paysheet!BU6 -> FBC | F6: =Paysheet!BV6 -> Gweru | G6: =Paysheet!BW6 -> 6670509580791 | H6: =Paysheet!BM6 -> 2017307.8 | I6: =Paysheet!BX6 -> FBC | J6: =Paysheet!BY6 -> Gweru | K6: =Paysheet!BZ6 -> 5320100212640 | L6: =Paysheet!BL6 -> 115.21504 | M6: 73.43 | N6: 292266.66 | O6: =L6+M6 -> 188.64504 | P6: =H6+N6 -> 2309574.5 | Q6: =172.64-O6 -> -16.005039 | R6: =672416-85-P6 -> -1637243.5
A7: 4 | B7: =Paysheet!A7 -> AES-E053 | C7: =Paysheet!B7 -> Panashe | D7: =Paysheet!C7 -> Gorejena | E7: =Paysheet!BU7 -> NMB | F7: =Paysheet!BV7 -> Gweru | G7: =Paysheet!BW7 -> 9176546035391 | H7: =Paysheet!BM7 -> 2361219.3 | I7: =Paysheet!BX7 -> FBC | J7: =Paysheet!BY7 -> Gweru | K7: =Paysheet!BZ7 -> 7668659091022 | L7: =Paysheet!BL7 -> 146.58589 | M7: 108.44 | N7: 429459.23 | O7: =L7+M7 -> 255.02589 | P7: =H7+N7 -> 2790678.5 | Q7: =282.06-O7 -> 27.034112 | R7: =672416.85-P7 -> -2118261.6
A8: 5 | B8: =Paysheet!A8 -> AES-E054 | C8: =Paysheet!B8 -> Tapiwa | D8: =Paysheet!C8 -> Shumba | E8: =Paysheet!BU8 -> FBC | F8: =Paysheet!BV8 -> Gweru | G8: =Paysheet!BW8 -> 9577830686343 | H8: =Paysheet!BM8 -> 2082933.9 | I8: =Paysheet!BX8 -> FBC | J8: =Paysheet!BY8 -> Gweru | K8: =Paysheet!BZ8 -> 7241498528903 | L8: =Paysheet!BL8 -> 129.31007 | M8: 73.43 | N8: 292266.66 | O8: =L8+M8 -> 202.74007 | P8: =H8+N8 -> 2375200.6 | Q8: =207.06-O8 -> 4.3199337 | R8: =1005465.12-P8 -> -1369735.5
A9: 6 | B9: =Paysheet!A9 -> AES-E057 | C9: =Paysheet!B9 -> Energy | D9: =Paysheet!C9 -> Mudenda | E9: =Paysheet!BU9 -> FBC | F9: =Paysheet!BV9 -> Gweru | G9: =Paysheet!BW9 -> 4362736323263 | H9: =Paysheet!BM9 -> 2603199.2 | I9: =Paysheet!BX9 -> FBC | J9: =Paysheet!BY9 -> Gweru | K9: =Paysheet!BZ9 -> 5243795393319 | L9: =Paysheet!BL9 -> 161.62377 | M9: 94.92 | N9: 418269.45 | O9: =L9+M9 -> 256.54377 | P9: =H9+N9 -> 3021468.7
A10: 7 | B10: =Paysheet!A10 -> AES-E055 | C10: =Paysheet!B10 -> Perfect | D10: =Paysheet!C10 -> Mhererwa | E10: =Paysheet!BU10 -> ZB | F10: =Paysheet!BV10 -> Shurugwi | G10: =Paysheet!BW10 -> 9378152371743 | H10: =Paysheet!BM10 -> 2082933.9 | I10: =Paysheet!BX10 -> FBC | J10: =Paysheet!BY10 -> Gweru | K10: =Paysheet!BZ10 -> 8883373049733 | L10: =Paysheet!BL10 -> 129.31007 | M10: 80.56 | N10: 323181.65 | O10: =L10+M10 -> 209.87007 | P10: =H10+N10 -> 2406115.6 | Q10: =221.24-O10 -> 11.369934 | R10: =764848.8-P10 -> -1641266.8
A11: 8 | B11: =Paysheet!A11 -> AES-E056 | C11: =Paysheet!B11 -> Tanyaradzwa | D11: =Paysheet!C11 -> Ndoro | E11: =Paysheet!BU11 -> ZB | F11: =Paysheet!BV11 -> Shurugwi | G11: =Paysheet!BW11 -> 6386933976899 | H11: =Paysheet!BM11 -> 2082933.9 | I11: =Paysheet!BX11 -> FBC | J11: =Paysheet!BY11 -> Gweru | K11: =Paysheet!BZ11 -> 9325231550423 | L11: =Paysheet!BL11 -> 129.31007 | M11: 65.36 | N11: 268616.88 | O11: =L11+M11 -> 194.67007 | P11: =H11+N11 -> 2351550.8 | Q11: =202.24-O11 -> 7.5699337 | R11: =699963.89-P11 -> -1651586.9
A12: 9 | B12: =Paysheet!A12 -> AES-E059 | C12: =Paysheet!B12 -> Perfect | D12: =Paysheet!C12 -> Chinouriri | E12: =Paysheet!BU12 -> ZB | F12: =Paysheet!BV12 -> Gweru | G12: =Paysheet!BW12 -> 6817749619277 | H12: =Paysheet!BM12 -> 2699773.3 | I12: =Paysheet!BX12 -> FBC | J12: =Paysheet!BY12 -> Gweru | K12: =Paysheet!BZ12 -> 5765067552342 | L12: =Paysheet!BL12 -> 167.60304 | M12: 107.94 | N12: 427012.64 | O12: =L12+M12 -> 275.54304 | P12: =H12+N12 -> 3126785.9 | Q12: =282.91-O12 -> 7.3669559 | R12: =974743.85-P12 -> -2152042.1
A13: 10 | B13: =Paysheet!A13 -> AES-E058 | C13: =Paysheet!B13 -> Wisdom | D13: =Paysheet!C13 -> Mavhunga | E13: =Paysheet!BU13 -> ZB | F13: =Paysheet!BV13 -> Shurugwi | G13: =Paysheet!BW13 -> 4387532121887 | H13: =Paysheet!BM13 -> 2082933.9 | I13: =Paysheet!BX13 -> FBC | J13: =Paysheet!BY13 -> Gweru | K13: =Paysheet!BZ13 -> 3101594275846 | L13: =Paysheet!BL13 -> 129.31007 | M13: 73.2 | N13: 290702.3 | O13: =L13+M13 -> 202.51007 | P13: =H13+N13 -> 2373636.2 | Q13: =206.83-O13 -> 4.3199337 | R13: =711439.9-P13 -> -1662196.3
A14: 11 | B14: =Paysheet!A14 -> AES-E060 | C14: =Paysheet!B14 -> Makanaka | D14: =Paysheet!C14 -> Dziva | E14: =Paysheet!BU14 -> FBC | F14: =Paysheet!BV14 -> Gweru BS | G14: =Paysheet!BW14 -> 4806163686472 | H14: =Paysheet!BM14 -> 2082933.9 | I14: =Paysheet!BX14 -> FBC | J14: =Paysheet!BY14 -> Headoffice | K14: =Paysheet!BZ14 -> 9520092430792 | L14: =Paysheet!BL14 -> 129.31007 | M14: 84.46 | N14: 278259.66 | O14: =L14+M14 -> 213.77007 | P14: =H14+N14 -> 2361193.6 | Q14: =222.29-O14 -> 8.5199337 | R14: =761071.8-P14 -> -1600121.8
A15: 12 | B15: =Paysheet!A15 -> 0 | C15: =Paysheet!B15 -> 0 | D15: =Paysheet!C15 -> 0 | E15: =Paysheet!BU15 -> 0 | F15: =Paysheet!BV15 -> 0 | G15: =Paysheet!BW15 -> 0 | H15: =Paysheet!BM15 -> 0 | I15: =Paysheet!BX15 -> 0 | J15: =Paysheet!BY15 -> 0 | K15: =Paysheet!BZ15 -> 0 | L15: =Paysheet!BL15 -> 0
A16: 13 | B16: =Paysheet!A16 -> 0 | C16: =Paysheet!B16 -> 0 | D16: =Paysheet!C16 -> 0 | E16: =Paysheet!BU16 -> 0 | F16: =Paysheet!BV16 -> 0 | G16: =Paysheet!BW16 -> 0 | H16: =Paysheet!BM16 -> 0 | I16: =Paysheet!BX16 -> 0 | J16: =Paysheet!BY16 -> 0 | K16: =Paysheet!BZ16 -> 0 | L16: =Paysheet!BL16 -> 0
A17: 14 | B17: =Paysheet!A17 -> 0 | C17: =Paysheet!B17 -> 0 | D17: =Paysheet!C17 -> 0 | E17: =Paysheet!BU17 -> 0 | F17: =Paysheet!BV17 -> 0 | G17: =Paysheet!BW17 -> 0 | H17: =Paysheet!BM17 -> 0 | I17: =Paysheet!BX17 -> 0 | J17: =Paysheet!BY17 -> 0 | K17: =Paysheet!BZ17 -> 0 | L17: =Paysheet!BL17 -> 0
A18: 15 | B18: =Paysheet!A18 -> 0 | C18: =Paysheet!B18 -> 0 | D18: =Paysheet!C18 -> 0 | E18: =Paysheet!BU18 -> 0 | F18: =Paysheet!BV18 -> 0 | G18: =Paysheet!BW18 -> 0 | H18: =Paysheet!BM18 -> 0 | I18: =Paysheet!BX18 -> 0 | J18: =Paysheet!BY18 -> 0 | K18: =Paysheet!BZ18 -> 0 | L18: =Paysheet!BL18 -> 0
A19: 16 | B19: =Paysheet!A19 -> 0 | C19: =Paysheet!B19 -> 0 | D19: =Paysheet!C19 -> 0 | E19: =Paysheet!BU19 -> 0 | F19: =Paysheet!BV19 -> 0 | G19: =Paysheet!BW19 -> 0 | H19: =Paysheet!BM19 -> 0 | I19: =Paysheet!BX19 -> 0 | J19: =Paysheet!BY19 -> 0 | K19: =Paysheet!BZ19 -> 0 | L19: =Paysheet!BL19 -> 0
H20: =SUM(H4:H19) -> 26155617 | L20: =SUM(L4:L19) -> 1615.1024 | M20: =SUM(M4:M19) -> 1018.03 | N20: =SUM(N4:N19) -> 4030273.9 | O20: =SUM(O4:O14) -> 2633.1324 | P20: =SUM(P4:P14) -> 30185891

Sheet NSSA
B3: Netsai | C3: Nhemachena | D3: Employee Contribution | E3: Employer Contribution | F3: Total
A4: =Paysheet!A4 -> AES-E050 | B4: =Paysheet!B4 -> Clever | C4: =Paysheet!C4 -> Chakabva | D4: =Paysheet!AK4 -> 23320.755 | E4: =D4 -> 23320.755 | F4: =SUM(D4:E4) -> 46641.51
A5: =Paysheet!A5 -> AES-E052 | B5: =Paysheet!B5 -> Tatenda | C5: =Paysheet!C5 -> Masuku | D5: =Paysheet!AK5 -> 23320.755 | E5: =D5 -> 23320.755 | F5: =SUM(D5:E5) -> 46641.51
A6: =Paysheet!A6 -> AES-E051 | B6: =Paysheet!B6 -> Kupakwashe | C6: =Paysheet!C6 -> Matongo | D6: =Paysheet!AK6 -> 23320.755 | E6: =D6 -> 23320.755 | F6: =SUM(D6:E6) -> 46641.51
A7: =Paysheet!A7 -> AES-E053 | B7: =Paysheet!B7 -> Panashe | C7: =Paysheet!C7 -> Gorejena | D7: =Paysheet!AK7 -> 23320.755 | E7: =D7 -> 23320.755 | F7: =SUM(D7:E7) -> 46641.51
A8: =Paysheet!A8 -> AES-E054 | B8: =Paysheet!B8 -> Tapiwa | C8: =Paysheet!C8 -> Shumba | D8: =Paysheet!AK8 -> 23320.755 | E8: =D8 -> 23320.755 | F8: =SUM(D8:E8) -> 46641.51
A9: =Paysheet!A9 -> AES-E057 | B9: =Paysheet!B9 -> Energy | C9: =Paysheet!C9 -> Mudenda | D9: =Paysheet!AK9 -> 23320.755 | E9: =D9 -> 23320.755 | F9: =SUM(D9:E9) -> 46641.51
A10: =Paysheet!A10 -> AES-E055 | B10: =Paysheet!B10 -> Perfect | C10: =Paysheet!C10 -> Mhererwa | D10: =Paysheet!AK10 -> 23320.755 | E10: =D10 -> 23320.755 | F10: =SUM(D10:E10) -> 46641.51
A11: =Paysheet!A11 -> AES-E056 | B11: =Paysheet!B11 -> Tanyaradzwa | C11: =Paysheet!C11 -> Ndoro | D11: =Paysheet!AK11 -> 23320.755 | E11: =D11 -> 23320.755 | F11: =SUM(D11:E11) -> 46641.51
A12: =Paysheet!A12 -> AES-E059 | B12: =Paysheet!B12 -> Perfect | C12: =Paysheet!C12 -> Chinouriri | D12: =Paysheet!AK12 -> 23320.755 | E12: =D12 -> 23320.755 | F12: =SUM(D12:E12) -> 46641.51
A13: =Paysheet!A13 -> AES-E058 | B13: =Paysheet!B13 -> Wisdom | C13: =Paysheet!C13 -> Mavhunga | D13: =Paysheet!AK13 -> 23320.755 | E13: =D13 -> 23320.755 | F13: =SUM(D13:E13) -> 46641.51
A14: =Paysheet!A14 -> AES-E060 | B14: =Paysheet!B14 -> Makanaka | C14: =Paysheet!C14 -> Dziva | D14: =Paysheet!AK14 -> 23320.755 | E14: =D14 -> 23320.755 | F14: =SUM(D14:E14) -> 46641.51
A15: =Paysheet!A15 -> 0 | B15: =Paysheet!B15 -> 0 | C15: =Paysheet!C15 -> 0 | D15: =Paysheet!AK15 -> 0 | E15: =D15 -> 0 | F15: =SUM(D15:E15) -> 0
... A55: =Paysheet!A55 -> 0 | B55: =Paysheet!B55 -> 0 | C55: =Paysheet!C55 -> 0 | D55: =Paysheet!AK55 -> 0 | E55: =D55 -> 0 | F55: =SUM(D55:E55) -> 0
A56: =Paysheet!A56 -> 0 | B56: =Paysheet!B56 -> 0 | E56: =D56 -> 0
A57: =Paysheet!A57 -> 0 | B57: =Paysheet!B57 -> 0 | C57: =Paysheet!C57 -> 0 | D57: =Paysheet!AK57 -> 0 | E57: =D57 -> 0
A58: =Paysheet!A58 -> 0 | B58: =Paysheet!B58 -> 0 | C58: =Paysheet!C58 -> 0 | D58: =Paysheet!AK58 -> 0 | E58: =D58 -> 0
A59: =Paysheet!A59 -> 0 | B59: =Paysheet!B59 -> 0 | C59: =Paysheet!C59 -> 0 | D59: =Paysheet!AK59 -> 0 | E59: =D59 -> 0
A60: =Paysheet!A60 -> 0 | B60: =Paysheet!B60 -> 0 | C60: =Paysheet!C60 -> 0 | D60: =Paysheet!AK60 -> 0 | E60: =D60 -> 0
D61: =SUM(D4:D60) -> 256528.3 | E61: =D61 -> 256528.3 | F61: =SUM(F4:F60) -> 513056.61
E62: Total | F62: =F61 -> 513056.61
E63: WCIF | F63: =F62*0.0177 -> 9081.102
E64: Payable | F64: =F62+F63 -> 522137.71

Sheet PAYE
A1: Details | D1: USD | G1: ZWL
B2: Netsai | C2: Nhemachena | D2: PAYE | E2: AIDS LEVY | F2: Total | G2: PAYE | H2: AIDS LEVY | I2: Total
A3: =Paysheet!A4 -> AES-E050 | B3: =Paysheet!B4 -> Clever | C3: =Paysheet!C4 -> Chakabva | D3: =Paysheet!AW4 -> 70.833764 | E3: =Paysheet!AX4 -> 2.1250129 | F3: =D3+E3 -> 72.958777 | G3: =Paysheet!AY4 -> 1143653 | H3: =Paysheet!AZ4 -> 34309.589 | I3: =G3+H3 -> 1177962.6
A4: =Paysheet!A5 -> AES-E052 | B4: =Paysheet!B5 -> Tatenda | C4: =Paysheet!C5 -> Masuku | D4: =Paysheet!AW5 -> 29.364205 | E4: =Paysheet!AX5 -> 0.88092615 | F4: =D4+E4 -> 30.245131 | G4: =Paysheet!AY5 -> 473000.29 | H4: =Paysheet!AZ5 -> 14190.009 | I4: =G4+H4 -> 487190.29
A5: =Paysheet!A6 -> AES-E051 | B5: =Paysheet!B6 -> Kupakwashe | C5: =Paysheet!C6 -> Matongo | D5: =Paysheet!AW6 -> 27.987063 | E5: =Paysheet!AX6 -> 0.83961189 | F5: =D5+E5 -> 28.826675 | G5: =Paysheet!AY6 -> 450892.49 | H5: =Paysheet!AZ6 -> 13526.775 | I5: =G5+H5 -> 464419.26
A6: =Paysheet!A7 -> AES-E053 | B6: =Paysheet!B7 -> Panashe | C6: =Paysheet!C7 -> Gorejena | D6: =Paysheet!AW7 -> 35.181003 | E6: =Paysheet!AX7 -> 1.0554301 | F6: =D6+E6 -> 36.236433 | G6: =Paysheet!AY7 -> 566698.9 | H6: =Paysheet!AZ7 -> 17000.967 | I6: =G6+H6 -> 583699.87
A7: =Paysheet!A8 -> AES-E054 | B7: =Paysheet!B8 -> Tapiwa | C7: =Paysheet!C8 -> Shumba | D7: =Paysheet!AW8 -> 29.364205 | E7: =Paysheet!AX8 -> 0.88092615 | F7: =D7+E7 -> 30.245131 | G7: =Paysheet!AY8 -> 473000.29 | H7: =Paysheet!AZ8 -> 14190.009 | I7: =G7+H7 -> 487190.29
A8: =Paysheet!A9 -> AES-E057 | B8: =Paysheet!B9 -> Energy | C8: =Paysheet!C9 -> Mudenda | D8: =Paysheet!AW9 -> 40.243305 | E8: =Paysheet!AX9 -> 1.2072992 | F8: =D8+E8 -> 41.450604 | G8: =Paysheet!AY9 -> 648180.27 | H8: =Paysheet!AZ9 -> 19445.408 | I8: =G8+H8 -> 667625.68
A9: =Paysheet!A10 -> AES-E055 | B9: =Paysheet!B10 -> Perfect | C9: =Paysheet!C10 -> Mhererwa | D9: =Paysheet!AW10 -> 29.364205 | E9: =Paysheet!AX10 -> 0.88092615 | F9: =D9+E9 -> 30.245131 | G9: =Paysheet!AY10 -> 473000.29 | H9: =Paysheet!AZ10 -> 14190.009 | I9: =G9+H9 -> 487190.29
A10: =Paysheet!A11 -> AES-E056 | B10: =Paysheet!B11 -> Tanyaradzwa | C10: =Paysheet!C11 -> Ndoro | D10: =Paysheet!AW11 -> 29.364205 | E10: =Paysheet!AX11 -> 0.88092615 | F10: =D10+E10 -> 30.245131 | G10: =Paysheet!AY11 -> 473000.29 | H10: =Paysheet!AZ11 -> 14190.009 | I10: =G10+H10 -> 487190.29
A11: =Paysheet!A12 -> AES-E059 | B11: =Paysheet!B12 -> Perfect | C11: =Paysheet!C12 -> Chinouriri | D11: =Paysheet!AW12 -> 42.257514 | E11: =Paysheet!AX12 -> 1.2677254 | F11: =D11+E11 -> 43.52524 | G11: =Paysheet!AY12 -> 680689.95 | H11: =Paysheet!AZ12 -> 20420.699 | I11: =G11+H11 -> 701110.65
A12: =Paysheet!A13 -> AES-E058 | B12: =Paysheet!B13 -> Wisdom | C12: =Paysheet!C13 -> Mavhunga | D12: =Paysheet!AW13 -> 29.364205 | E12: =Paysheet!AX13 -> 0.88092615 | F12: =D12+E12 -> 30.245131 | G12: =Paysheet!AY13 -> 473000.29 | H12: =Paysheet!AZ13 -> 14190.009 | I12: =G12+H12 -> 487190.29
A13: =Paysheet!A14 -> AES-E060 | B13: =Paysheet!B14 -> Makanaka | C13: =Paysheet!C14 -> Dziva | D13: =Paysheet!AW14 -> 29.364205 | E13: =Paysheet!AX14 -> 0.88092615 | F13: =D13+E13 -> 30.245131 | G13: =Paysheet!AY14 -> 473000.29 | H13: =Paysheet!AZ14 -> 14190.009 | I13: =G13+H13 -> 487190.29
A14: =Paysheet!A15 -> 0 | B14: =Paysheet!B15 -> 0 | C14: =Paysheet!C15 -> 0 | D14: =Paysheet!AW15 -> 0 | E14: =Paysheet!AX15 -> 0 | F14: =D14+E14 -> 0 | G14: =Paysheet!AY15 -> 0 | H14: =Paysheet!AZ15 -> 0 | I14: =G14+H14 -> 0
... A54: =Paysheet!A55 -> 0 | B54: =Paysheet!B55 -> 0 | C54: =Paysheet!C55 -> 0 | D54: =Paysheet!AW55 -> 0 | E54: =Paysheet!AX55 -> 0 | F54: =D54+E54 -> 0 | G54: =Paysheet!AY55 -> 0 | H54: =Paysheet!AZ55 -> 0 | I54: =G54+H54 -> 0
A55: =Paysheet!A56 -> 0 | B55: =Paysheet!B56 -> 0 | I55: =G55+H55 -> 0
A56: =Paysheet!A57 -> 0 | B56: =Paysheet!B57 -> 0 | C56: =Paysheet!C57 -> 0 | D56: =Paysheet!AW57 -> 0 | E56: =Paysheet!AX57 -> 0 | F56: =D56+E56 -> 0 | G56: =Paysheet!AY57 -> 0 | H56: =Paysheet!AZ57 -> 0 | I56: =G56+H56 -> 0
A57: =Paysheet!A58 -> 0 | B57: =Paysheet!B58 -> 0 | C57: =Paysheet!C58 -> 0 | D57: =Paysheet!AW58 -> 0 | E57: =Paysheet!AX58 -> 0 | F57: =D57+E57 -> 0 | G57: =Paysheet!AY58 -> 0 | H57: =Paysheet!AZ58 -> 0 | I57: =G57+H57 -> 0
A58: =Paysheet!A59 -> 0 | B58: =Paysheet!B59 -> 0 | C58: =Paysheet!C59 -> 0 | D58: =Paysheet!AW59 -> 0 | E58: =Paysheet!AX59 -> 0 | F58: =D58+E58 -> 0 | G58: =Paysheet!AY59 -> 0 | H58: =Paysheet!AZ59 -> 0 | I58: =G58+H58 -> 0
A59: =Paysheet!A60 -> 0 | B59: =Paysheet!B60 -> 0 | C59: =Paysheet!C60 -> 0 | D59: =Paysheet!AW60 -> 0 | E59: =Paysheet!AX60 -> 0 | F59: =D59+E59 -> 0 | G59: =Paysheet!AY60 -> 0 | H59: =Paysheet!AZ60 -> 0 | I59: =G59+H59 -> 0
A60: =Paysheet!A61 -> 0 | B60: =Paysheet!B61 -> 0 | C60: =Paysheet!C61 -> 0 | D60: =Paysheet!AW61 -> 0 | E60: =Paysheet!AX61 -> 0 | F60: =D60+E60 -> 0 | G60: =Paysheet!AY61 -> 0 | H60: =Paysheet!AZ61 -> 0 | I60: =G60+H60 -> 0
A61: =Paysheet!A62 -> 0 | B61: =Paysheet!B62 -> 0 | C61: =Paysheet!C62 -> 0 | D61: =Paysheet!AW62 -> 0 | E61: =Paysheet!AX62 -> 0 | F61: =D61+E61 -> 0 | G61: =Paysheet!AY62 -> 0 | H61: =Paysheet!AZ62 -> 0 | I61: =G61+H61 -> 0
A62: =Paysheet!A63 -> 0 | B62: =Paysheet!B63 -> 0 | C62: =Paysheet!C63 -> 0 | D62: =Paysheet!AW63 -> 0 | E62: =Paysheet!AX63 -> 0 | F62: =D62+E62 -> 0 | G62: =Paysheet!AY63 -> 0 | H62: =Paysheet!AZ63 -> 0 | I62: =G62+H62 -> 0
A63: =Paysheet!A64 -> 0 | B63: =Paysheet!B64 -> 0 | C63: =Paysheet!C64 -> 0 | D63: =Paysheet!AW64 -> 0 | E63: =Paysheet!AX64 -> 0 | F63: =D63+E63 -> 0 | G63: =Paysheet!AY64 -> 0 | H63: =Paysheet!AZ64 -> 0 | I63: =G63+H63 -> 0
A64: =Paysheet!A65 -> 0 | B64: =Paysheet!B65 -> 0 | C64: =Paysheet!C65 -> 0 | D64: =Paysheet!AW65 -> 0 | E64: =Paysheet!AX65 -> 0 | F64: =D64+E64 -> 0 | G64: =Paysheet!AY65 -> 0 | H64: =Paysheet!AZ65 -> 0 | I64: =G64+H64 -> 0
A65: =Paysheet!A66 -> 0 | B65: =Paysheet!B66 -> 0 | C65: =Paysheet!C66 -> 0 | D65: =Paysheet!AW66 -> 0 | E65: =Paysheet!AX66 -> 0 | F65: =D65+E65 -> 0 | G65: =Paysheet!AY66 -> 0 | H65: =Paysheet!AZ66 -> 0 | I65: =G65+H65 -> 0
C66: Total | D66: =SUM(D3:D65) -> 392.68788 | E66: =SUM(E3:E65) -> 11.780636 | F66: =SUM(F3:F65) -> 404.46852 | G66: =SUM(G3:G65) -> 6328116.3 | H66: =SUM(H3:H65) -> 189843.49 | I66: =SUM(I3:I65) -> 6517959.8

Sheet Nyaradzo 

Sheet Zimdef
C1: Zimdef Schedule May 2023
D2: Gross | F2: Rate | G2: 1404.8039
A3: Works # | B3: Netsai | C3: Nhemachena | D3: USD | E3: ZWL | F3: NSSA | G3: USD CONVERTED | H3: TOTAL | I3: ZIMDEF
A4: AES-E050 | B4: Clever | C4: Chakabva | D4: =Paysheet!AI4 -> 322.1831 | E4: =Paysheet!AJ4 -> 5219127 | F4: =NSSA!E4 -> 23320.755 | G4: =D4*$G$2 -> 452604.07 | H4: =E4+F4+G4 -> 5695051.8 | I4: =H4*0.01 -> 56950.518
A5: AES-E052 | B5: Tatenda | C5: Masuku | D5: =Paysheet!AI5 -> 160.56525 | E5: =Paysheet!AJ5 -> 2595057.5 | F5: =NSSA!E5 -> 23320.755 | G5: =D5*$G$2 -> 225562.69 | H5: =E5+F5+G5 -> 2843940.9 | I5: =H5*0.01 -> 28439.409
A6: AES-E051 | B6: Kupakwashe | C6: Matongo | D6: =Paysheet!AI6 -> 155.05177 | E6: =Paysheet!AJ6 -> 2505948.5 | F6: =NSSA!E6 -> 23320.755 | G6: =D6*$G$2 -> 217817.33 | H6: =E6+F6+G6 -> 2747086.6 | I6: =H6*0.01 -> 27470.866
A7: AES-E053 | B7: Panashe | C7: Gorejena | D7: =Paysheet!AI7 -> 183.83238 | E7: =Paysheet!AJ7 -> 2971101 | F7: =NSSA!E7 -> 23320.755 | G7: =D7*$G$2 -> 258248.44 | H7: =E7+F7+G7 -> 3252670.2 | I7: =H7*0.01 -> 32526.702
A8: AES-E054 | B8: Tapiwa | C8: Shumba | D8: =Paysheet!AI8 -> 160.56525 | E8: =Paysheet!AJ8 -> 2595057.5 | F8: =NSSA!E8 -> 23320.755 | G8: =D8*$G$2 -> 225562.69 | H8: =E8+F8+G8 -> 2843940.9 | I8: =H8*0.01 -> 28439.409
A9: AES-E057 | B9: Energy | C9: Mudenda | D9: =Paysheet!AI9 -> 204.08443 | E9: =Paysheet!AJ9 -> 3298415 | F9: =NSSA!E9 -> 23320.755 | G9: =D9*$G$2 -> 286698.61 | H9: =E9+F9+G9 -> 3608434.3 | I9: =H9*0.01 -> 36084.343
A10: AES-E055 | B10: Perfect | C10: Mhererwa | D10: =Paysheet!AI10 -> 160.56525 | E10: =Paysheet!AJ10 -> 2595057.5 | F10: =NSSA!E10 -> 23320.755 | G10: =D10*$G$2 -> 225562.69 | H10: =E10+F10+G10 -> 2843940.9 | I10: =H10*0.01 -> 28439.409
A11: AES-E056 | B11: Tanyaradzwa | C11: Ndoro | D11: =Paysheet!AI11 -> 160.56525 | E11: =Paysheet!AJ11 -> 2595057.5 | F11: =NSSA!E11 -> 23320.755 | G11: =D11*$G$2 -> 225562.69 | H11: =E11+F11+G11 -> 2843940.9 | I11: =H11*0.01 -> 28439.409
A12: AES-E059 | B12: Perfect | C12: Chinouriri | D12: =Paysheet!AI12 -> 212.13834 | E12: =Paysheet!AJ12 -> 3428582.3 | F12: =NSSA!E12 -> 23320.755 | G12: =D12*$G$2 -> 298012.77 | H12: =E12+F12+G12 -> 3749915.8 | I12: =H12*0.01 -> 37499.158
A13: AES-E058 | B13: Wisdom | C13: Mavhunga | D13: =Paysheet!AI13 -> 160.56525 | E13: =Paysheet!AJ13 -> 2595057.5 | F13: =NSSA!E13 -> 23320.755 | G13: =D13*$G$2 -> 225562.69 | H13: =E13+F13+G13 -> 2843940.9 | I13: =H13*0.01 -> 28439.409
A14: AES-E060 | B14: Makanaka | C14: Dziva | D14: =Paysheet!AI14 -> 160.56525 | E14: =Paysheet!AJ14 -> 2595057.5 | F14: =NSSA!E14 -> 23320.755 | G14: =D14*$G$2 -> 225562.69 | H14: =E14+F14+G14 -> 2843940.9 | I14: =H14*0.01 -> 28439.409
D15: =SUM(D4:D14) -> 2040.6815 | E15: =SUM(E4:E14) -> 32993519 | F15: =SUM(F4:F14) -> 256528.3 | G15: =SUM(G4:G14) -> 2866757.4 | H15: =SUM(H4:H14) -> 36116804 | I15: =SUM(I4:I14) -> 361168.04
